Workbook
Name QTemp: 'Link List'!$B$1:$M$23

Sheet Link List
A1: No | B1: Kode provinsi | C1: Kode Kabupaten | D1: Ruas | E1: Sffx | F1: Nama Ruas | G1: Status | H1: Fungsi | I1: Panjang Ruas SK Gub (km) | J1: Panjang Ruas Survei (km) | K1: Titik Awal Ruas - Patok KM | L1: Titik Awal Ruas - Offset (m) | M1: Link Access Status
A2: 1 | B2: 18 | C2: 00 | D2: 036 | F2: SUKAMARA - KURIPAN | G2: P | H2: K2 | I2: 21.777 | J2: 21.777 | K2: 0 | L2: 0 | M2: P
A3: =+A2+1 -> 2 | B3: 18 | C3: 00 | D3: 044 | F3: SP TELUK KILUAN - SP. UMBAR | G3: P | H3: K2 | I3: 25.157 | J3: 25.157 | K3: 0 | L3: 0 | M3: P
A4: =+A3+1 -> 3 | B4: 18 | C4: 00 | D4: 045 | F4: SP. UMBAR - PUTIH DOH | G4: P | H4: K2 | I4: 23.83 | J4: 23.83 | K4: 0 | L4: 0 | M4: P
A5: =+A4+1 -> 4 | B5: 18 | C5: 00 | D5: 046 | F5: PUTIH DOH - KURIPAN | G5: P | H5: K2 | I5: 11.736 | J5: 11.736 | K5: 0 | L5: 0 | M5: P
A6: =+A5+1 -> 5 | B6: 18 | C6: 00 | D6: 047 | F6: KURIPAN - SP. KOTA AGUNG | G6: P | H6: K2 | I6: 21.468 | J6: 21.468 | K6: 0 | L6: 0 | M6: N
A7: =+A6+1 -> 6 | B7: 18 | C7: 00 | D7: 048 | F7: PEKON BALAK - SUOH | G7: P | H7: K2 | I7: 33.628 | J7: 33.628 | K7: 0 | L7: 0 | M7: N
A8: =+A7+1 -> 7 | B8: 18 | C8: 00 | D8: 049 | F8: SUOH - SP. BLOK 9 | G8: P | H8: K2 | I8: 30.447 | J8: 30.447 | K8: 0 | L8: 0 | M8: P
A9: =+A8+1 -> 8 | B9: 18 | C9: 00 | D9: 050 | F9: SP. BLOK 9 - SANGGI | G9: P | H9: K2 | I9: 20.873 | J9: 20.873 | K9: 0 | L9: 0 | M9: N
A10: =+A9+1 -> 9 | B10: 18 | C10: 00 | D10: 051 | E10: 11K | F10: JALAN RADEN INTAN (LIWA) | G10: P | H10: K2 | I10: 5.179 | J10: 5.179 | K10: 0 | L10: 0 | M10: N
A11: =+A10+1 -> 10 | B11: 18 | C11: 00 | D11: 052 | F11: LIWA - BTS. SUMATERA SELATAN | G11: P | H11: K2 | I11: 19.109 | J11: 19.109 | K11: 0 | L11: 0 | M11: P
A12: =+A11+1 -> 11 | B12: 18 | C12: 00 | D12: 053 | E12: 11K | F12: JALAN ADAM MALIK (KRUI) | G12: P | H12: K2 | I12: 1.812 | J12: 1.812 | K12: 0 | L12: 0 | M12: N
A13: =+A12+1 -> 12 | B13: 18 | C13: 00 | D13: 054 | F13: KRUI - PEKON SERAI | G13: P | H13: K2 | I13: 1.81 | J13: 1.81 | K13: 0 | L13: 0 | M13: N
A14: =+A13+1 -> 13 | B14: 18 | C14: 00 | D14: 055 | F14: KOTAJAWA - KAMPUNG BARU | G14: P | H14: K2 | I14: 8.374 | J14: 8.374 | K14: 0 | L14: 0 | M14: N
A15: =+A14+1 -> 14 | B15: 18 | C15: 00 | D15: 056 | F15: TALANG PADANG - NGARIP | G15: P | H15: K2 | I15: 35.862 | J15: 35.862 | K15: 0 | L15: 0 | M15: N
A16: =+A15+1 -> 15 | B16: 18 | C16: 00 | D16: 057 | F16: NGARIP - ULU SEMONG | G16: P | H16: K2 | I16: 21.5 | J16: 21.5 | K16: 0 | L16: 0 | M16: P
A17: =+A16+1 -> 16 | B17: 18 | C17: 00 | D17: 058 | F17: ULU SEMONG - SP. TRIMULYO | G17: P | H17: K2 | I17: 9.66 | J17: 9.66 | K17: 0 | L17: 0 | M17: P
A18: =+A17+1 -> 17 | B18: 18 | C18: 00 | D18: 059 | F18: SP. TRIMULYO - BUNGIN - SP. TUGU SARI | G18: P | H18: K2 | I18: 24.574 | J18: 24.574 | K18: 0 | L18: 0 | M18: N
A19: =+A18+1 -> 18 | B19: 18 | C19: 00 | D19: 060 | F19: TEKAD - BATUTEGI | G19: P | H19: K2 | I19: 4.8 | J19: 4.8 | K19: 0 | L19: 0 | M19: P
A20: =+A19+1 -> 19 | B20: 18 | C20: 00 | D20: 064 | F20: BANDAR SAKTI - SP. DAYA MURNI | G20: P | H20: K2 | I20: 10.099 | J20: 10.099 | K20: 0 | L20: 0 | M20: P
A21: =+A20+1 -> 20 | B21: 18 | C21: 00 | D21: 065 | F21: SP. DAYA MURNI - GUNUNG BATIN | G21: P | H21: K2 | I21: 12.389 | J21: 12.389 | K21: 0 | L21: 0 | M21: N
A22: =+A21+1 -> 21 | B22: 18 | C22: 00 | D22: 068 | F22: SP. TUJOK - PANARAGAN JAYA | G22: P | H22: K2 | I22: 25.813 | J22: 25.813 | K22: 0 | L22: 0 | M22: P
A23: =+A22+1 -> 22 | B23: 18 | C23: 00 | D23: 069 | F23: PANARAGAN JAYA - SP. PANARAGAN | G23: P | H23: K2 | I23: 4.104 | J23: 4.104 | K23: 0 | L23: 0 | M23: P
A24: =+A23+1 -> 23 | B24: 18 | C24: 00 | D24: 085 | E24: 11K | F24: JALAN RAYA GUNUNG SAKTI (MENGGALA) | G24: P | H24: K2 | I24: 1.865 | J24: 1.865 | K24: 0 | L24: 0 | M24: N
A25: =+A24+1 -> 24 | B25: 18 | C25: 00 | D25: 086 | F25: BUJUNG TENUK - PENUMANGAN | G25: P | H25: K2 | I25: 12.432 | J25: 12.432 | K25: 0 | L25: 0 | M25: P
A26: =+A25+1 -> 25 | B26: 18 | C26: 00 | D26: 087 | F26: PENUMANGAN - TEGAL MUKTI | G26: P | H26: K2 | I26: 15.839 | J26: 15.839 | K26: 0 | L26: 0 | M26: P
A27: =+A26+1 -> 26 | B27: 18 | C27: 00 | D27: 090 | F27: ADIJAYA - TULUNG RANDU | G27: P | H27: K2 | I27: 38.13 | J27: 38.13 | K27: 0 | L27: 0 | M27: P
A28: =+A27+1 -> 27 | B28: 18 | C28: 00 | D28: 091 | F28: PENUMANGAN - UNIT VI | G28: P | H28: K2 | I28: 23.562 | J28: 23.562 | K28: 0 | L28: 0 | M28: P
A29: =+A28+1 -> 28 | B29: 18 | C29: 00 | D29: 092 | F29: SP. UNIT VIII - GEDONG AJI | G29: P | H29: K2 | I29: 22.05 | J29: 22.05 | K29: 0 | L29: 0 | M29: N
A30: =+A29+1 -> 29 | B30: 18 | C30: 00 | D30: 093 | F30: GEDONG AJI - UMBUL MESIR | G30: P | H30: K2 | I30: 31.5 | J30: 31.5 | K30: 0 | L30: 0 | M30: P
A31: =+A30+1 -> 30 | B31: 18 | C31: 00 | D31: 094 | F31: SP. PEMATANG - BRABASAN | G31: P | H31: K2 | I31: 11.602 | J31: 11.602 | K31: 0 | L31: 0 | M31: N
A32: =+A31+1 -> 31 | B32: 18 | C32: 00 | D32: 095 | F32: BRABASAN - WIRALAGA | G32: P | H32: K2 | I32: 29.443 | J32: 29.443 | K32: 0 | L32: 0 | M32: P

Sheet 1. Rekap Back Up Aspal
C2: PEMERINTAH PROVINSI LAMPUNG
C3: DINAS BINA MARGA DAN BINA KONSTRUKSI
B6: REKAPITULASI BACK - UP DATA SURVEY KONDISI JALAN (ASPAL)
B9: NO. RUAS | E9: : | F9: ='Link List'!D3 -> 044
B12: NAMA RUAS | E12: : | F12: ='Link List'!F3 -> SP TELUK KILUAN - SP. UMBAR
B15: PANJANG RUAS | E15: : | F15: ='Link List'!I3 -> 25.157
C18: STA | F18: NILAI TTI | G18: KONDISI | H18: TIPE KERUSAKAN KONDISI JALAN ASPAL | T18: KET
C19: DARI (M) | D19: KE (M) | E19: LEBAR | H19: BLEEDING | I19: AGREGAT LEPAS | J19: DISINTEGRASI | K19: RETAK TURUN | L19: TAMBALAN | M19: RETAK LAIN | N19: JENIS RETAK | O19: LUBANG | P19: TIPE LUBANG | Q19: ALUR | R19: RUSAK TEPI (KIRI) | S19: RUSAK TEPI (KANAN)
B20: 1 | H20: 2 | I20: 3 | J20: 4 | K20: 5 | L20: 6 | M20: 7 | O20: 8 | Q20: 9 | R20: 10 Ki | S20: 10 Ka | T20: 12
C21: =NOTE!J22 -> 21780 | D21: 21800 | E21: 4.5 | F21: =(100/((D21-C21)*E21))*((H21*0.5)+(I21*0.5)+(J21*4)+(K21*4)+(L21*1)+(M21*2)+(O21*1.5)+(Q21*1)+(R21*1)+(S21*1)) -> 22.222222 | G21: =IF(F21<=25,"B",IF(F21<=75,"S",IF(F21<=100,"RR","RB"))) -> B | H21: ='1. Back Up Aspal'!J28 -> 0 | I21: ='1. Back Up Aspal'!M28 -> 0 | J21: ='1. Back Up Aspal'!P28 -> 0 | K21: ='1. Back Up Aspal'!S28 -> 0 | L21: ='1. Back Up Aspal'!V28 -> 0 | M21: ='1. Back Up Aspal'!Y28 -> 10 | N21: ='1. Back Up Aspal'!Z28 -> 2 | O21: ='1. Back Up Aspal'!AC28 -> 0 | P21: ='1. Back Up Aspal'!AD28 -> 2 | Q21: ='1. Back Up Aspal'!AG28 -> 0 | R21: ='1. Back Up Aspal'!AJ28 -> 0 | S21: ='1. Back Up Aspal'!AM28 -> 0
C22: =D21 -> 21800 | D22: =C22+100 -> 21900 | E22: 4.5 | F22: =(100/((D22-C22)*E22))*((H22*0.5)+(I22*0.5)+(J22*4)+(K22*4)+(L22*1)+(M22*2)+(O22*1.5)+(Q22*1)+(R22*1)+(S22*1)) -> 0 | G22: =IF(F22<=25,"B",IF(F22<=75,"S",IF(F22<=100,"RR","RB"))) -> B | H22: ='1. Back Up Aspal'!J36 -> 0 | I22: ='1. Back Up Aspal'!M36 -> 0 | J22: ='1. Back Up Aspal'!P36 -> 0 | K22: ='1. Back Up Aspal'!S36 -> 0 | L22: ='1. Back Up Aspal'!V36 -> 0 | M22: ='1. Back Up Aspal'!Y36 -> 0 | N22: ='1. Back Up Aspal'!Z36 -> 2 | O22: ='1. Back Up Aspal'!AC36 -> 0 | P22: ='1. Back Up Aspal'!AD36 -> 2 | Q22: ='1. Back Up Aspal'!AG36 -> 0 | R22: ='1. Back Up Aspal'!AJ36 -> 0 | S22: ='1. Back Up Aspal'!AM36 -> 0
C23: =D22 -> 21900 | D23: =C23+100 -> 22000 | E23: 4.5 | F23: =(100/((D23-C23)*E23))*((H23*0.5)+(I23*0.5)+(J23*4)+(K23*4)+(L23*1)+(M23*2)+(O23*1.5)+(Q23*1)+(R23*1)+(S23*1)) -> 0 | G23: =IF(F23<=25,"B",IF(F23<=75,"S",IF(F23<=100,"RR","RB"))) -> B | H23: ='1. Back Up Aspal'!J44 -> 0 | I23: ='1. Back Up Aspal'!M44 -> 0 | J23: ='1. Back Up Aspal'!P44 -> 0 | K23: ='1. Back Up Aspal'!S44 -> 0 | L23: ='1. Back Up Aspal'!V44 -> 0 | M23: ='1. Back Up Aspal'!Y44 -> 0 | N23: ='1. Back Up Aspal'!Z44 -> 2 | O23: ='1. Back Up Aspal'!AC44 -> 0 | P23: ='1. Back Up Aspal'!AD44 -> 2 | Q23: ='1. Back Up Aspal'!AG44 -> 0 | R23: ='1. Back Up Aspal'!AJ44 -> 0 | S23: ='1. Back Up Aspal'!AM44 -> 0
C24: =D23 -> 22000 | D24: =C24+100 -> 22100 | E24: 4.5 | F24: =(100/((D24-C24)*E24))*((H24*0.5)+(I24*0.5)+(J24*4)+(K24*4)+(L24*1)+(M24*2)+(O24*1.5)+(Q24*1)+(R24*1)+(S24*1)) -> 0 | G24: =IF(F24<=25,"B",IF(F24<=75,"S",IF(F24<=100,"RR","RB"))) -> B | H24: ='1. Back Up Aspal'!J52 -> 0 | I24: ='1. Back Up Aspal'!M52 -> 0 | J24: ='1. Back Up Aspal'!P52 -> 0 | K24: ='1. Back Up Aspal'!S52 -> 0 | L24: ='1. Back Up Aspal'!V52 -> 0 | M24: ='1. Back Up Aspal'!Y52 -> 0 | N24: ='1. Back Up Aspal'!Z52 -> 2 | O24: ='1. Back Up Aspal'!AC52 -> 0 | P24: ='1. Back Up Aspal'!AD52 -> 2 | Q24: ='1. Back Up Aspal'!AG52 -> 0 | R24: ='1. Back Up Aspal'!AJ52 -> 0 | S24: ='1. Back Up Aspal'!AM52 -> 0
C25: =D24 -> 22100 | D25: =NOTE!L22 -> 22150 | E25: 4.5 | F25: =(100/((D25-C25)*E25))*((H25*0.5)+(I25*0.5)+(J25*4)+(K25*4)+(L25*1)+(M25*2)+(O25*1.5)+(Q25*1)+(R25*1)+(S25*1)) -> 0 | G25: =IF(F25<=25,"B",IF(F25<=75,"S",IF(F25<=100,"RR","RB"))) -> B | H25: ='1. Back Up Aspal'!J60 -> 0 | I25: ='1. Back Up Aspal'!M60 -> 0 | J25: ='1. Back Up Aspal'!P60 -> 0 | K25: ='1. Back Up Aspal'!S60 -> 0 | L25: ='1. Back Up Aspal'!V60 -> 0 | M25: ='1. Back Up Aspal'!Y60 -> 0 | N25: ='1. Back Up Aspal'!Z60 -> 2 | O25: ='1. Back Up Aspal'!AC60 -> 0 | P25: ='1. Back Up Aspal'!AD60 -> 2 | Q25: ='1. Back Up Aspal'!AG60 -> 0 | R25: ='1. Back Up Aspal'!AJ60 -> 0 | S25: ='1. Back Up Aspal'!AM60 -> 0
C26: =NOTE!J24 -> 22350 | D26: =C26+50 -> 22400 | E26: 4.5 | F26: =(100/((D26-C26)*E26))*((H26*0.5)+(I26*0.5)+(J26*4)+(K26*4)+(L26*1)+(M26*2)+(O26*1.5)+(Q26*1)+(R26*1)+(S26*1)) -> 0 | G26: =IF(F26<=25,"B",IF(F26<=75,"S",IF(F26<=100,"RR","RB"))) -> B | H26: ='1. Back Up Aspal'!J68 -> 0 | I26: ='1. Back Up Aspal'!M68 -> 0 | J26: ='1. Back Up Aspal'!P68 -> 0 | K26: ='1. Back Up Aspal'!S68 -> 0 | L26: ='1. Back Up Aspal'!V68 -> 0 | M26: ='1. Back Up Aspal'!Y68 -> 0 | N26: ='1. Back Up Aspal'!Z68 -> 2 | O26: ='1. Back Up Aspal'!AC68 -> 0 | P26: ='1. Back Up Aspal'!AD68 -> 2 | Q26: ='1. Back Up Aspal'!AG68 -> 0 | R26: ='1. Back Up Aspal'!AJ68 -> 0 | S26: ='1. Back Up Aspal'!AM68 -> 0
C27: =D26 -> 22400 | D27: =C27+100 -> 22500 | E27: 4.5 | F27: =(100/((D27-C27)*E27))*((H27*0.5)+(I27*0.5)+(J27*4)+(K27*4)+(L27*1)+(M27*2)+(O27*1.5)+(Q27*1)+(R27*1)+(S27*1)) -> 0 | G27: =IF(F27<=25,"B",IF(F27<=75,"S",IF(F27<=100,"RR","RB"))) -> B | H27: ='1. Back Up Aspal'!J76 -> 0 | I27: ='1. Back Up Aspal'!M76 -> 0 | J27: ='1. Back Up Aspal'!P76 -> 0 | K27: ='1. Back Up Aspal'!S76 -> 0 | L27: ='1. Back Up Aspal'!V76 -> 0 | M27: ='1. Back Up Aspal'!Y76 -> 0 | N27: ='1. Back Up Aspal'!Z76 -> 2 | O27: ='1. Back Up Aspal'!AC76 -> 0 | P27: ='1. Back Up Aspal'!AD76 -> 2 | Q27: ='1. Back Up Aspal'!AG76 -> 0 | R27: ='1. Back Up Aspal'!AJ76 -> 0 | S27: ='1. Back Up Aspal'!AM76 -> 0
C28: =D27 -> 22500 | D28: =NOTE!L24 -> 22600 | E28: 4.5 | F28: =(100/((D28-C28)*E28))*((H28*0.5)+(I28*0.5)+(J28*4)+(K28*4)+(L28*1)+(M28*2)+(O28*1.5)+(Q28*1)+(R28*1)+(S28*1)) -> 25 | G28: =IF(F28<=25,"B",IF(F28<=75,"S",IF(F28<=100,"RR","RB"))) -> B | H28: ='1. Back Up Aspal'!J84 -> 0 | I28: ='1. Back Up Aspal'!M84 -> 225 | J28: ='1. Back Up Aspal'!P84 -> 0 | K28: ='1. Back Up Aspal'!S84 -> 0 | L28: ='1. Back Up Aspal'!V84 -> 0 | M28: ='1. Back Up Aspal'!Y84 -> 0 | N28: ='1. Back Up Aspal'!Z84 -> 2 | O28: ='1. Back Up Aspal'!AC84 -> 0 | P28: ='1. Back Up Aspal'!AD84 -> 2 | Q28: ='1. Back Up Aspal'!AG84 -> 0 | R28: ='1. Back Up Aspal'!AJ84 -> 0 | S28: ='1. Back Up Aspal'!AM84 -> 0
C29: =NOTE!J26 -> 24000 | D29: 24100 | E29: 4.5 | F29: =(100/((D29-C29)*E29))*((H29*0.5)+(I29*0.5)+(J29*4)+(K29*4)+(L29*1)+(M29*2)+(O29*1.5)+(Q29*1)+(R29*1)+(S29*1)) -> 25 | G29: =IF(F29<=25,"B",IF(F29<=75,"S",IF(F29<=100,"RR","RB"))) -> B | H29: ='1. Back Up Aspal'!J92 -> 0 | I29: ='1. Back Up Aspal'!M92 -> 225 | J29: ='1. Back Up Aspal'!P92 -> 0 | K29: ='1. Back Up Aspal'!S92 -> 0 | L29: ='1. Back Up Aspal'!V92 -> 0 | M29: ='1. Back Up Aspal'!Y92 -> 0 | N29: ='1. Back Up Aspal'!Z92 -> 2 | O29: ='1. Back Up Aspal'!AC92 -> 0 | P29: ='1. Back Up Aspal'!AD92 -> 2 | Q29: ='1. Back Up Aspal'!AG92 -> 0 | R29: ='1. Back Up Aspal'!AJ92 -> 0 | S29: ='1. Back Up Aspal'!AM92 -> 0
C30: =D29 -> 24100 | D30: =C30+100 -> 24200 | E30: 4.5 | F30: =(100/((D30-C30)*E30))*((H30*0.5)+(I30*0.5)+(J30*4)+(K30*4)+(L30*1)+(M30*2)+(O30*1.5)+(Q30*1)+(R30*1)+(S30*1)) -> 55.555556 | G30: =IF(F30<=25,"B",IF(F30<=75,"S",IF(F30<=100,"RR","RB"))) -> S | H30: ='1. Back Up Aspal'!J100 -> 0 | I30: ='1. Back Up Aspal'!M100 -> 500 | J30: ='1. Back Up Aspal'!P100 -> 0 | K30: ='1. Back Up Aspal'!S100 -> 0 | L30: ='1. Back Up Aspal'!V100 -> 0 | M30: ='1. Back Up Aspal'!Y100 -> 0 | N30: ='1. Back Up Aspal'!Z100 -> 2 | O30: ='1. Back Up Aspal'!AC100 -> 0 | P30: ='1. Back Up Aspal'!AD100 -> 2 | Q30: ='1. Back Up Aspal'!AG100 -> 0 | R30: ='1. Back Up Aspal'!AJ100 -> 0 | S30: ='1. Back Up Aspal'!AM100 -> 0
C31: =D30 -> 24200 | D31: =C31+100 -> 24300 | E31: 4.5 | F31: =(100/((D31-C31)*E31))*((H31*0.5)+(I31*0.5)+(J31*4)+(K31*4)+(L31*1)+(M31*2)+(O31*1.5)+(Q31*1)+(R31*1)+(S31*1)) -> 38.888889 | G31: =IF(F31<=25,"B",IF(F31<=75,"S",IF(F31<=100,"RR","RB"))) -> S | H31: ='1. Back Up Aspal'!J108 -> 0 | I31: ='1. Back Up Aspal'!M108 -> 350 | J31: ='1. Back Up Aspal'!P108 -> 0 | K31: ='1. Back Up Aspal'!S108 -> 0 | L31: ='1. Back Up Aspal'!V108 -> 0 | M31: ='1. Back Up Aspal'!Y108 -> 0 | N31: ='1. Back Up Aspal'!Z108 -> 2 | O31: ='1. Back Up Aspal'!AC108 -> 0 | P31: ='1. Back Up Aspal'!AD108 -> 2 | Q31: ='1. Back Up Aspal'!AG108 -> 0 | R31: ='1. Back Up Aspal'!AJ108 -> 0 | S31: ='1. Back Up Aspal'!AM108 -> 0
C32: =D31 -> 24300 | D32: =C32+100 -> 24400 | E32: 4.5 | F32: =(100/((D32-C32)*E32))*((H32*0.5)+(I32*0.5)+(J32*4)+(K32*4)+(L32*1)+(M32*2)+(O32*1.5)+(Q32*1)+(R32*1)+(S32*1)) -> 33.333333 | G32: =IF(F32<=25,"B",IF(F32<=75,"S",IF(F32<=100,"RR","RB"))) -> S | H32: ='1. Back Up Aspal'!J116 -> 0 | I32: ='1. Back Up Aspal'!M116 -> 300 | J32: ='1. Back Up Aspal'!P116 -> 0 | K32: ='1. Back Up Aspal'!S116 -> 0 | L32: ='1. Back Up Aspal'!V116 -> 0 | M32: ='1. Back Up Aspal'!Y116 -> 0 | N32: ='1. Back Up Aspal'!Z116 -> 2 | O32: ='1. Back Up Aspal'!AC116 -> 0 | P32: ='1. Back Up Aspal'!AD116 -> 2 | Q32: ='1. Back Up Aspal'!AG116 -> 0 | R32: ='1. Back Up Aspal'!AJ116 -> 0 | S32: ='1. Back Up Aspal'!AM116 -> 0
C33: =D32 -> 24400 | D33: =C33+100 -> 24500 | E33: 4.5 | F33: =(100/((D33-C33)*E33))*((H33*0.5)+(I33*0.5)+(J33*4)+(K33*4)+(L33*1)+(M33*2)+(O33*1.5)+(Q33*1)+(R33*1)+(S33*1)) -> 50 | G33: =IF(F33<=25,"B",IF(F33<=75,"S",IF(F33<=100,"RR","RB"))) -> S | H33: ='1. Back Up Aspal'!J124 -> 0 | I33: ='1. Back Up Aspal'!M124 -> 450 | J33: ='1. Back Up Aspal'!P124 -> 0 | K33: ='1. Back Up Aspal'!S124 -> 0 | L33: ='1. Back Up Aspal'!V124 -> 0 | M33: ='1. Back Up Aspal'!Y124 -> 0 | N33: ='1. Back Up Aspal'!Z124 -> 2 | O33: ='1. Back Up Aspal'!AC124 -> 0 | P33: ='1. Back Up Aspal'!AD124 -> 2 | Q33: ='1. Back Up Aspal'!AG124 -> 0 | R33: ='1. Back Up Aspal'!AJ124 -> 0 | S33: ='1. Back Up Aspal'!AM124 -> 0
C34: =D33 -> 24500 | D34: =C34+100 -> 24600 | E34: 4.5 | F34: =(100/((D34-C34)*E34))*((H34*0.5)+(I34*0.5)+(J34*4)+(K34*4)+(L34*1)+(M34*2)+(O34*1.5)+(Q34*1)+(R34*1)+(S34*1)) -> 400 | G34: =IF(F34<=25,"B",IF(F34<=75,"S",IF(F34<=100,"RR","RB"))) -> RB | H34: ='1. Back Up Aspal'!J132 -> 0 | I34: ='1. Back Up Aspal'!M132 -> 0 | J34: ='1. Back Up Aspal'!P132 -> 450 | K34: ='1. Back Up Aspal'!S132 -> 0 | L34: ='1. Back Up Aspal'!V132 -> 0 | M34: ='1. Back Up Aspal'!Y132 -> 0 | N34: ='1. Back Up Aspal'!Z132 -> 2 | O34: ='1. Back Up Aspal'!AC132 -> 0 | P34: ='1. Back Up Aspal'!AD132 -> 2 | Q34: ='1. Back Up Aspal'!AG132 -> 0 | R34: ='1. Back Up Aspal'!AJ132 -> 0 | S34: ='1. Back Up Aspal'!AM132 -> 0
C35: =D34 -> 24600 | D35: =C35+100 -> 24700 | E35: 4.5 | F35: =(100/((D35-C35)*E35))*((H35*0.5)+(I35*0.5)+(J35*4)+(K35*4)+(L35*1)+(M35*2)+(O35*1.5)+(Q35*1)+(R35*1)+(S35*1)) -> 400 | G35: =IF(F35<=25,"B",IF(F35<=75,"S",IF(F35<=100,"RR","RB"))) -> RB | H35: ='1. Back Up Aspal'!J140 -> 0 | I35: ='1. Back Up Aspal'!M140 -> 0 | J35: ='1. Back Up Aspal'!P140 -> 450 | K35: ='1. Back Up Aspal'!S140 -> 0 | L35: ='1. Back Up Aspal'!V140 -> 0 | M35: ='1. Back Up Aspal'!Y140 -> 0 | N35: ='1. Back Up Aspal'!Z140 -> 2 | O35: ='1. Back Up Aspal'!AC140 -> 0 | P35: ='1. Back Up Aspal'!AD140 -> 2 | Q35: ='1. Back Up Aspal'!AG140 -> 0 | R35: ='1. Back Up Aspal'!AJ140 -> 0 | S35: ='1. Back Up Aspal'!AM140 -> 0
C36: =D35 -> 24700 | D36: =C36+100 -> 24800 | E36: 4.5 | F36: =(100/((D36-C36)*E36))*((H36*0.5)+(I36*0.5)+(J36*4)+(K36*4)+(L36*1)+(M36*2)+(O36*1.5)+(Q36*1)+(R36*1)+(S36*1)) -> 400 | G36: =IF(F36<=25,"B",IF(F36<=75,"S",IF(F36<=100,"RR","RB"))) -> RB | H36: ='1. Back Up Aspal'!J148 -> 0 | I36: ='1. Back Up Aspal'!M148 -> 0 | J36: ='1. Back Up Aspal'!P148 -> 450 | K36: ='1. Back Up Aspal'!S148 -> 0 | L36: ='1. Back Up Aspal'!V148 -> 0 | M36: ='1. Back Up Aspal'!Y148 -> 0 | N36: ='1. Back Up Aspal'!Z148 -> 2 | O36: ='1. Back Up Aspal'!AC148 -> 0 | P36: ='1. Back Up Aspal'!AD148 -> 2 | Q36: ='1. Back Up Aspal'!AG148 -> 0 | R36: ='1. Back Up Aspal'!AJ148 -> 0 | S36: ='1. Back Up Aspal'!AM148 -> 0
C37: =D36 -> 24800 | D37: =C37+100 -> 24900 | E37: 4.5 | F37: =(100/((D37-C37)*E37))*((H37*0.5)+(I37*0.5)+(J37*4)+(K37*4)+(L37*1)+(M37*2)+(O37*1.5)+(Q37*1)+(R37*1)+(S37*1)) -> 400 | G37: =IF(F37<=25,"B",IF(F37<=75,"S",IF(F37<=100,"RR","RB"))) -> RB | H37: ='1. Back Up Aspal'!J156 -> 0 | I37: ='1. Back Up Aspal'!M156 -> 0 | J37: ='1. Back Up Aspal'!P156 -> 450 | K37: ='1. Back Up Aspal'!S156 -> 0 | L37: ='1. Back Up Aspal'!V156 -> 0 | M37: ='1. Back Up Aspal'!Y156 -> 0 | N37: ='1. Back Up Aspal'!Z156 -> 2 | O37: ='1. Back Up Aspal'!AC156 -> 0 | P37: ='1. Back Up Aspal'!AD156 -> 2 | Q37: ='1. Back Up Aspal'!AG156 -> 0 | R37: ='1. Back Up Aspal'!AJ156 -> 0 | S37: ='1. Back Up Aspal'!AM156 -> 0
C38: =D37 -> 24900 | D38: =C38+100 -> 25000 | E38: 4.5 | F38: =(100/((D38-C38)*E38))*((H38*0.5)+(I38*0.5)+(J38*4)+(K38*4)+(L38*1)+(M38*2)+(O38*1.5)+(Q38*1)+(R38*1)+(S38*1)) -> 400 | G38: =IF(F38<=25,"B",IF(F38<=75,"S",IF(F38<=100,"RR","RB"))) -> RB | H38: ='1. Back Up Aspal'!J164 -> 0 | I38: ='1. Back Up Aspal'!M164 -> 0 | J38: ='1. Back Up Aspal'!P164 -> 450 | K38: ='1. Back Up Aspal'!S164 -> 0 | L38: ='1. Back Up Aspal'!V164 -> 0 | M38: ='1. Back Up Aspal'!Y164 -> 0 | N38: ='1. Back Up Aspal'!Z164 -> 2 | O38: ='1. Back Up Aspal'!AC164 -> 0 | P38: ='1. Back Up Aspal'!AD164 -> 2 | Q38: ='1. Back Up Aspal'!AG164 -> 0 | R38: ='1. Back Up Aspal'!AJ164 -> 0 | S38: ='1. Back Up Aspal'!AM164 -> 0
C39: =D38 -> 25000 | D39: =C39+100 -> 25100 | E39: 4.5 | F39: =(100/((D39-C39)*E39))*((H39*0.5)+(I39*0.5)+(J39*4)+(K39*4)+(L39*1)+(M39*2)+(O39*1.5)+(Q39*1)+(R39*1)+(S39*1)) -> 400 | G39: =IF(F39<=25,"B",IF(F39<=75,"S",IF(F39<=100,"RR","RB"))) -> RB | H39: ='1. Back Up Aspal'!J172 -> 0 | I39: ='1. Back Up Aspal'!M172 -> 0 | J39: ='1. Back Up Aspal'!P172 -> 450 | K39: ='1. Back Up Aspal'!S172 -> 0 | L39: ='1. Back Up Aspal'!V172 -> 0 | M39: ='1. Back Up Aspal'!Y172 -> 0 | N39: ='1. Back Up Aspal'!Z172 -> 2 | O39: ='1. Back Up Aspal'!AC172 -> 0 | P39: ='1. Back Up Aspal'!AD172 -> 2 | Q39: ='1. Back Up Aspal'!AG172 -> 0 | R39: ='1. Back Up Aspal'!AJ172 -> 0 | S39: ='1. Back Up Aspal'!AM172 -> 0
C40: =D39 -> 25100 | D40: 25157 | E40: 4.5 | F40: =(100/((D40-C40)*E40))*((H40*0.5)+(I40*0.5)+(J40*4)+(K40*4)+(L40*1)+(M40*2)+(O40*1.5)+(Q40*1)+(R40*1)+(S40*1)) -> 400 | G40: =IF(F40<=25,"B",IF(F40<=75,"S",IF(F40<=100,"RR","RB"))) -> RB | H40: ='1. Back Up Aspal'!J180 -> 0 | I40: ='1. Back Up Aspal'!M180 -> 0 | J40: ='1. Back Up Aspal'!P180 -> 256.5 | K40: ='1. Back Up Aspal'!S180 -> 0 | L40: ='1. Back Up Aspal'!V180 -> 0 | M40: ='1. Back Up Aspal'!Y180 -> 0 | N40: ='1. Back Up Aspal'!Z180 -> 2 | O40: ='1. Back Up Aspal'!AC180 -> 0 | P40: ='1. Back Up Aspal'!AD180 -> 2 | Q40: ='1. Back Up Aspal'!AG180 -> 0 | R40: ='1. Back Up Aspal'!AJ180 -> 0 | S40: ='1. Back Up Aspal'!AM180 -> 0
B100: LEGENDA :
B102: I. PERKERASAN ASPAL | H102: RETAK LAIN
B103: 1. | C103: Ketidakrataan atau IRI (m/km) | H103: 1
B104: 2. | C104: Kegemukan / Blending (m2) | H104: 2
B105: 3. | C105: Agregat Lepas / Ravelling (m2) | H105: 3
B106: 4. | C106: Disintegrasi (m2) | H106: 4
B107: 5. | C107: Retak turun dan Penurunan (m2)
B108: 6. | C108: Tambalan / Patching (m2) | H108: RATA RATA LEBAR RETAK
B109: 7. | C109: Retak Lain / (Melintang, Bercabang n Buaya) (m2) | H109: 1
B110: 8. | C110: Lubang / Potholes (m2) | H110: 2
B111: 9. | C111: Alur / Jejak Roda / Rutting (m2) | H111: 3
...

Sheet 1. Back Up Aspal
C2: PEMERINTAH PROVINSI LAMPUNG
C3: DINAS BINA MARGA DAN BINA KONSTRUKSI
B6: BACK - UP DATA SURVEY KONDISI JALAN (ASPAL)
B9: NO. RUAS | E9: : | F9: ='Link List'!D3 -> 044
B12: NAMA RUAS | E12: : | F12: ='Link List'!F3 -> SP TELUK KILUAN - SP. UMBAR
B15: PANJANG RUAS | E15: : | F15: ='Link List'!I3 -> 25.157
C18: STA | F18: NILAI TTI | G18: KONDISI | H18: TIPE KERUSAKAN KONDISI JALAN ASPAL | AN18: KET
C19: DARI (M) | D19: KE (M) | E19: LEBAR | H19: P | I19: L | J19: BLEEDING | K19: P | L19: L | M19: AGREGAT LEPAS | N19: P | O19: L | P19: DISINTEGRASI | Q19: P | R19: L | S19: RETAK TURUN | T19: P | U19: L | V19: TAMBALAN | W19: P | X19: L | Y19: RETAK LAIN | Z19: JENIS RETAK | AA19: P | AB19: L | AC19: LUBANG | AD19: TIPE LUBANG | AE19: P | AF19: L | AG19: ALUR | AH19: P | AI19: L | AJ19: RUSAK TEPI (KIRI) | AK19: P | AL19: L | AM19: RUSAK TEPI (KANAN)
B20: 1 | H20: 2 | K20: 3 | N20: 4 | Q20: 5 | W20: 7 | AA20: 8 | AE20: 9 | AH20: 10 | AK20: 11 | AN20: 12
C21: ='1. Rekap Back Up Aspal'!C21 -> 21780 | D21: ='1. Rekap Back Up Aspal'!D21 -> 21800 | E21: ='1. Rekap Back Up Aspal'!E21 -> 4.5 | F21: =(100/((D21-C21)*E21))*((J28*0.5)+(M28*0.5)+(P28*4)+(S28*4)+(V28*1)+(Y28*2)+(AC28*1.5)+(AG28*1)+(AJ28*1)+(AM28*1)) -> 22.222222 | G21: =IF(F21<=25,"B",IF(F21<=75,"S",IF(F21<=100,"RR","RB"))) -> B | H21: 0 | I21: 0 | J21: =H21*I21 -> 0 | K21: 0 | L21: 0 | M21: =K21*L21 -> 0 | N21: 0 | O21: 0 | P21: =N21*O21 -> 0 | Q21: 0 | R21: 0 | S21: =Q21*R21 -> 0 | T21: 0 | U21: 0 | V21: =T21*U21 -> 0 | W21: 5 | X21: 2 | Y21: =W21*X21 -> 10 | Z21: 3 | AA21: 0 | AB21: 0 | AC21: =AA21*AB21 -> 0 | AD21: 1 | AE21: 0 | AF21: 0 | AG21: =AE21*AF21 -> 0 | AH21: 0 | AI21: 0 | AJ21: =AH21*AI21 -> 0 | AK21: 0 | AL21: 0 | AM21: =AK21*AL21 -> 0
H22: 0 | I22: 0 | J22: =H22*I22 -> 0 | K22: 0 | L22: 0 | M22: =K22*L22 -> 0 | N22: 0 | O22: 0 | P22: =N22*O22 -> 0 | Q22: 0 | R22: 0 | S22: =Q22*R22 -> 0 | T22: 0 | U22: 0 | V22: =T22*U22 -> 0 | W22: 0 | X22: 0 | Y22: =W22*X22 -> 0 | Z22: 3 | AA22: 0 | AB22: 0 | AC22: =AA22*AB22 -> 0 | AD22: 1 | AE22: 0 | AF22: 0 | AG22: =AE22*AF22 -> 0 | AH22: 0 | AI22: 0 | AJ22: =AH22*AI22 -> 0 | AK22: 0 | AL22: 0 | AM22: =AK22*AL22 -> 0
H23: 0 | I23: 0 | J23: =H23*I23 -> 0 | K23: 0 | L23: 0 | M23: =K23*L23 -> 0 | N23: 0 | O23: 0 | P23: =N23*O23 -> 0 | Q23: 0 | R23: 0 | S23: =Q23*R23 -> 0 | T23: 0 | U23: 0 | V23: =T23*U23 -> 0 | W23: 0 | X23: 0 | Y23: =W23*X23 -> 0 | Z23: 1 | AA23: 0 | AB23: 0 | AC23: =AA23*AB23 -> 0 | AD23: 1 | AE23: 0 | AF23: 0 | AG23: =AE23*AF23 -> 0 | AH23: 0 | AI23: 0 | AJ23: =AH23*AI23 -> 0 | AK23: 0 | AL23: 0 | AM23: =AK23*AL23 -> 0
H24: 0 | I24: 0 | J24: =H24*I24 -> 0 | K24: 0 | L24: 0 | M24: =K24*L24 -> 0 | N24: 0 | O24: 0 | P24: =N24*O24 -> 0 | Q24: 0 | R24: 0 | S24: =Q24*R24 -> 0 | T24: 0 | U24: 0 | V24: =T24*U24 -> 0 | W24: 0 | X24: 0 | Y24: =W24*X24 -> 0 | Z24: 1 | AA24: 0 | AB24: 0 | AC24: =AA24*AB24 -> 0 | AD24: 1 | AE24: 0 | AF24: 0 | AG24: =AE24*AF24 -> 0 | AH24: 0 | AI24: 0 | AJ24: =AH24*AI24 -> 0 | AK24: 0 | AL24: 0 | AM24: =AK24*AL24 -> 0
H25: 0 | I25: 0 | J25: =H25*I25 -> 0 | K25: 0 | L25: 0 | M25: =K25*L25 -> 0 | N25: 0 | O25: 0 | P25: =N25*O25 -> 0 | Q25: 0 | R25: 0 | S25: =Q25*R25 -> 0 | T25: 0 | U25: 0 | V25: =T25*U25 -> 0 | W25: 0 | X25: 0 | Y25: =W25*X25 -> 0 | Z25: 1 | AA25: 0 | AB25: 0 | AC25: =AA25*AB25 -> 0 | AD25: 1 | AE25: 0 | AF25: 0 | AG25: =AE25*AF25 -> 0 | AH25: 0 | AI25: 0 | AJ25: =AH25*AI25 -> 0 | AK25: 0 | AL25: 0 | AM25: =AK25*AL25 -> 0
H26: 0 | I26: 0 | J26: =H26*I26 -> 0 | K26: 0 | L26: 0 | M26: =K26*L26 -> 0 | N26: 0 | O26: 0 | P26: =N26*O26 -> 0 | Q26: 0 | R26: 0 | S26: =Q26*R26 -> 0 | T26: 0 | U26: 0 | V26: =T26*U26 -> 0 | W26: 0 | X26: 0 | Y26: =W26*X26 -> 0 | Z26: 1 | AA26: 0 | AB26: 0 | AC26: =AA26*AB26 -> 0 | AD26: 1 | AE26: 0 | AF26: 0 | AG26: =AE26*AF26 -> 0 | AH26: 0 | AI26: 0 | AJ26: =AH26*AI26 -> 0 | AK26: 0 | AL26: 0 | AM26: =AK26*AL26 -> 0
H27: 0 | I27: 0 | J27: =H27*I27 -> 0 | K27: 0 | L27: 0 | M27: =K27*L27 -> 0 | N27: 0 | O27: 0 | P27: =N27*O27 -> 0 | Q27: 0 | R27: 0 | S27: =Q27*R27 -> 0 | T27: 0 | U27: 0 | V27: =T27*U27 -> 0 | W27: 0 | X27: 0 | Y27: =W27*X27 -> 0 | Z27: 1 | AA27: 0 | AB27: 0 | AC27: =AA27*AB27 -> 0 | AD27: 1 | AE27: 0 | AF27: 0 | AG27: =AE27*AF27 -> 0 | AH27: 0 | AI27: 0 | AJ27: =AH27*AI27 -> 0 | AK27: 0 | AL27: 0 | AM27: =AK27*AL27 -> 0
H28: Total | J28: =SUM(J21:J27) -> 0 | K28: Total | M28: =SUM(M21:M27) -> 0 | N28: Total | P28: =SUM(P21:P27) -> 0 | Q28: Total | S28: =SUM(S21:S27) -> 0 | T28: Total | V28: =SUM(V21:V27) -> 0 | W28: Total | Y28: =SUM(Y21:Y27) -> 10 | Z28: 2 | AA28: Total | AC28: =SUM(AC21:AC27) -> 0 | AD28: 2 | AE28: Total | AG28: =SUM(AG21:AG27) -> 0 | AH28: Total | AJ28: =SUM(AJ21:AJ27) -> 0 | AK28: Total | AM28: =SUM(AM21:AM27) -> 0
C29: ='1. Rekap Back Up Aspal'!C22 -> 21800 | D29: ='1. Rekap Back Up Aspal'!D22 -> 21900 | E29: ='1. Rekap Back Up Aspal'!E22 -> 4.5 | F29: =(100/((D29-C29)*E29))*((J36*0.5)+(M36*0.5)+(P36*4)+(S36*4)+(V36*1)+(Y36*2)+(AC36*1.5)+(AG36*1)+(AJ36*1)+(AM36*1)) -> 0 | G29: =IF(F29<=25,"B",IF(F29<=75,"S",IF(F29<=100,"RR","RB"))) -> B | H29: 0 | I29: 0 | J29: =H29*I29 -> 0 | K29: 0 | L29: 0 | M29: =K29*L29 -> 0 | N29: 0 | O29: 4 | P29: =N29*O29 -> 0 | Q29: 0 | R29: 0 | S29: =Q29*R29 -> 0 | T29: 0 | U29: 0 | V29: =T29*U29 -> 0 | W29: 0 | X29: 0 | Y29: =W29*X29 -> 0 | Z29: 2 | AA29: 0 | AB29: 0 | AC29: =AA29*AB29 -> 0 | AD29: 1 | AE29: 0 | AF29: 0 | AG29: =AE29*AF29 -> 0 | AH29: 0 | AI29: 0 | AJ29: =AH29*AI29 -> 0 | AK29: 0 | AL29: 0 | AM29: =AK29*AL29 -> 0
H30: 0 | I30: 0 | J30: =H30*I30 -> 0 | K30: 0 | L30: 0 | M30: =K30*L30 -> 0 | N30: 0 | O30: 0 | P30: =N30*O30 -> 0 | Q30: 0 | R30: 0 | S30: =Q30*R30 -> 0 | T30: 0 | U30: 0 | V30: =T30*U30 -> 0 | W30: 0 | X30: 0 | Y30: =W30*X30 -> 0 | Z30: 3 | AA30: 0 | AB30: 0 | AC30: =AA30*AB30 -> 0 | AD30: 1 | AE30: 0 | AF30: 0 | AG30: =AE30*AF30 -> 0 | AH30: 0 | AI30: 0 | AJ30: =AH30*AI30 -> 0 | AK30: 0 | AL30: 0 | AM30: =AK30*AL30 -> 0
H31: 0 | I31: 0 | J31: =H31*I31 -> 0 | K31: 0 | L31: 0 | M31: =K31*L31 -> 0 | N31: 0 | O31: 0 | P31: =N31*O31 -> 0 | Q31: 0 | R31: 0 | S31: =Q31*R31 -> 0 | T31: 0 | U31: 0 | V31: =T31*U31 -> 0 | W31: 0 | X31: 0 | Y31: =W31*X31 -> 0 | Z31: 1 | AA31: 0 | AB31: 0 | AC31: =AA31*AB31 -> 0 | AD31: 1 | AE31: 0 | AF31: 0 | AG31: =AE31*AF31 -> 0 | AH31: 0 | AI31: 0 | AJ31: =AH31*AI31 -> 0 | AK31: 0 | AL31: 0 | AM31: =AK31*AL31 -> 0
H32: 0 | I32: 0 | J32: =H32*I32 -> 0 | K32: 0 | L32: 0 | M32: =K32*L32 -> 0 | N32: 0 | O32: 0 | P32: =N32*O32 -> 0 | Q32: 0 | R32: 0 | S32: =Q32*R32 -> 0 | T32: 0 | U32: 0 | V32: =T32*U32 -> 0 | W32: 0 | X32: 0 | Y32: =W32*X32 -> 0 | Z32: 1 | AA32: 0 | AB32: 0 | AC32: =AA32*AB32 -> 0 | AD32: 1 | AE32: 0 | AF32: 0 | AG32: =AE32*AF32 -> 0 | AH32: 0 | AI32: 0 | AJ32: =AH32*AI32 -> 0 | AK32: 0 | AL32: 0 | AM32: =AK32*AL32 -> 0
H33: 0 | I33: 0 | J33: =H33*I33 -> 0 | K33: 0 | L33: 0 | M33: =K33*L33 -> 0 | N33: 0 | O33: 0 | P33: =N33*O33 -> 0 | Q33: 0 | R33: 0 | S33: =Q33*R33 -> 0 | T33: 0 | U33: 0 | V33: =T33*U33 -> 0 | W33: 0 | X33: 0 | Y33: =W33*X33 -> 0 | Z33: 1 | AA33: 0 | AB33: 0 | AC33: =AA33*AB33 -> 0 | AD33: 1 | AE33: 0 | AF33: 0 | AG33: =AE33*AF33 -> 0 | AH33: 0 | AI33: 0 | AJ33: =AH33*AI33 -> 0 | AK33: 0 | AL33: 0 | AM33: =AK33*AL33 -> 0
H34: 0 | I34: 0 | J34: =H34*I34 -> 0 | K34: 0 | L34: 0 | M34: =K34*L34 -> 0 | N34: 0 | O34: 0 | P34: =N34*O34 -> 0 | Q34: 0 | R34: 0 | S34: =Q34*R34 -> 0 | T34: 0 | U34: 0 | V34: =T34*U34 -> 0 | W34: 0 | X34: 0 | Y34: =W34*X34 -> 0 | Z34: 1 | AA34: 0 | AB34: 0 | AC34: =AA34*AB34 -> 0 | AD34: 1 | AE34: 0 | AF34: 0 | AG34: =AE34*AF34 -> 0 | AH34: 0 | AI34: 0 | AJ34: =AH34*AI34 -> 0 | AK34: 0 | AL34: 0 | AM34: =AK34*AL34 -> 0
H35: 0 | I35: 0 | J35: =H35*I35 -> 0 | K35: 0 | L35: 0 | M35: =K35*L35 -> 0 | N35: 0 | O35: 0 | P35: =N35*O35 -> 0 | Q35: 0 | R35: 0 | S35: =Q35*R35 -> 0 | T35: 0 | U35: 0 | V35: =T35*U35 -> 0 | W35: 0 | X35: 0 | Y35: =W35*X35 -> 0 | Z35: 1 | AA35: 0 | AB35: 0 | AC35: =AA35*AB35 -> 0 | AD35: 1 | AE35: 0 | AF35: 0 | AG35: =AE35*AF35 -> 0 | AH35: 0 | AI35: 0 | AJ35: =AH35*AI35 -> 0 | AK35: 0 | AL35: 0 | AM35: =AK35*AL35 -> 0
H36: Total | J36: =SUM(J29:J35) -> 0 | K36: Total | M36: =SUM(M29:M35) -> 0 | N36: Total | P36: =SUM(P29:P35) -> 0 | Q36: Total | S36: =SUM(S29:S35) -> 0 | T36: Total | V36: =SUM(V29:V35) -> 0 | W36: Total | Y36: =SUM(Y29:Y35) -> 0 | Z36: 2 | AA36: Total | AC36: =SUM(AC29:AC35) -> 0 | AD36: 2 | AE36: Total | AG36: =SUM(AG29:AG35) -> 0 | AH36: Total | AJ36: =SUM(AJ29:AJ35) -> 0 | AK36: Total | AM36: =SUM(AM29:AM35) -> 0
C37: ='1. Rekap Back Up Aspal'!C23 -> 21900 | D37: ='1. Rekap Back Up Aspal'!D23 -> 22000 | E37: ='1. Rekap Back Up Aspal'!E23 -> 4.5 | F37: =(100/((D37-C37)*E37))*((J44*0.5)+(M44*0.5)+(P44*4)+(S44*4)+(V44*1)+(Y44*2)+(AC44*1.5)+(AG44*1)+(AJ44*1)+(AM44*1)) -> 0 | G37: =IF(F37<=25,"B",IF(F37<=75,"S",IF(F37<=100,"RR","RB"))) -> B | H37: 0 | I37: 0 | J37: =H37*I37 -> 0 | K37: 0 | L37: 0 | M37: =K37*L37 -> 0 | N37: 0 | O37: 4 | P37: =N37*O37 -> 0 | Q37: 0 | R37: 0 | S37: =Q37*R37 -> 0 | T37: 0 | U37: 0 | V37: =T37*U37 -> 0 | W37: 0 | X37: 0 | Y37: =W37*X37 -> 0 | Z37: 2 | AA37: 0 | AB37: 0 | AC37: =AA37*AB37 -> 0 | AD37: 1 | AE37: 0 | AF37: 0 | AG37: =AE37*AF37 -> 0 | AH37: 0 | AI37: 0 | AJ37: =AH37*AI37 -> 0 | AK37: 0 | AL37: 0 | AM37: =AK37*AL37 -> 0
H38: 0 | I38: 0 | J38: =H38*I38 -> 0 | K38: 0 | L38: 0 | M38: =K38*L38 -> 0 | N38: 0 | O38: 0 | P38: =N38*O38 -> 0 | Q38: 0 | R38: 0 | S38: =Q38*R38 -> 0 | T38: 0 | U38: 0 | V38: =T38*U38 -> 0 | W38: 0 | X38: 0 | Y38: =W38*X38 -> 0 | Z38: 3 | AA38: 0 | AB38: 0 | AC38: =AA38*AB38 -> 0 | AD38: 1 | AE38: 0 | AF38: 0 | AG38: =AE38*AF38 -> 0 | AH38: 0 | AI38: 0 | AJ38: =AH38*AI38 -> 0 | AK38: 0 | AL38: 0 | AM38: =AK38*AL38 -> 0
H39: 0 | I39: 0 | J39: =H39*I39 -> 0 | K39: 0 | L39: 0 | M39: =K39*L39 -> 0 | N39: 0 | O39: 0 | P39: =N39*O39 -> 0 | Q39: 0 | R39: 0 | S39: =Q39*R39 -> 0 | T39: 0 | U39: 0 | V39: =T39*U39 -> 0 | W39: 0 | X39: 0 | Y39: =W39*X39 -> 0 | Z39: 1 | AA39: 0 | AB39: 0 | AC39: =AA39*AB39 -> 0 | AD39: 1 | AE39: 0 | AF39: 0 | AG39: =AE39*AF39 -> 0 | AH39: 0 | AI39: 0 | AJ39: =AH39*AI39 -> 0 | AK39: 0 | AL39: 0 | AM39: =AK39*AL39 -> 0
H40: 0 | I40: 0 | J40: =H40*I40 -> 0 | K40: 0 | L40: 0 | M40: =K40*L40 -> 0 | N40: 0 | O40: 0 | P40: =N40*O40 -> 0 | Q40: 0 | R40: 0 | S40: =Q40*R40 -> 0 | T40: 0 | U40: 0 | V40: =T40*U40 -> 0 | W40: 0 | X40: 0 | Y40: =W40*X40 -> 0 | Z40: 1 | AA40: 0 | AB40: 0 | AC40: =AA40*AB40 -> 0 | AD40: 1 | AE40: 0 | AF40: 0 | AG40: =AE40*AF40 -> 0 | AH40: 0 | AI40: 0 | AJ40: =AH40*AI40 -> 0 | AK40: 0 | AL40: 0 | AM40: =AK40*AL40 -> 0
H41: 0 | I41: 0 | J41: =H41*I41 -> 0 | K41: 0 | L41: 0 | M41: =K41*L41 -> 0 | N41: 0 | O41: 0 | P41: =N41*O41 -> 0 | Q41: 0 | R41: 0 | S41: =Q41*R41 -> 0 | T41: 0 | U41: 0 | V41: =T41*U41 -> 0 | W41: 0 | X41: 0 | Y41: =W41*X41 -> 0 | Z41: 1 | AA41: 0 | AB41: 0 | AC41: =AA41*AB41 -> 0 | AD41: 1 | AE41: 0 | AF41: 0 | AG41: =AE41*AF41 -> 0 | AH41: 0 | AI41: 0 | AJ41: =AH41*AI41 -> 0 | AK41: 0 | AL41: 0 | AM41: =AK41*AL41 -> 0
H42: 0 | I42: 0 | J42: =H42*I42 -> 0 | K42: 0 | L42: 0 | M42: =K42*L42 -> 0 | N42: 0 | O42: 0 | P42: =N42*O42 -> 0 | Q42: 0 | R42: 0 | S42: =Q42*R42 -> 0 | T42: 0 | U42: 0 | V42: =T42*U42 -> 0 | W42: 0 | X42: 0 | Y42: =W42*X42 -> 0 | Z42: 1 | AA42: 0 | AB42: 0 | AC42: =AA42*AB42 -> 0 | AD42: 1 | AE42: 0 | AF42: 0 | AG42: =AE42*AF42 -> 0 | AH42: 0 | AI42: 0 | AJ42: =AH42*AI42 -> 0 | AK42: 0 | AL42: 0 | AM42: =AK42*AL42 -> 0
H43: 0 | I43: 0 | J43: =H43*I43 -> 0 | K43: 0 | L43: 0 | M43: =K43*L43 -> 0 | N43: 0 | O43: 0 | P43: =N43*O43 -> 0 | Q43: 0 | R43: 0 | S43: =Q43*R43 -> 0 | T43: 0 | U43: 0 | V43: =T43*U43 -> 0 | W43: 0 | X43: 0 | Y43: =W43*X43 -> 0 | Z43: 1 | AA43: 0 | AB43: 0 | AC43: =AA43*AB43 -> 0 | AD43: 1 | AE43: 0 | AF43: 0 | AG43: =AE43*AF43 -> 0 | AH43: 0 | AI43: 0 | AJ43: =AH43*AI43 -> 0 | AK43: 0 | AL43: 0 | AM43: =AK43*AL43 -> 0
H44: Total | J44: =SUM(J37:J43) -> 0 | K44: Total | M44: =SUM(M37:M43) -> 0 | N44: Total | P44: =SUM(P37:P43) -> 0 | Q44: Total | S44: =SUM(S37:S43) -> 0 | T44: Total | V44: =SUM(V37:V43) -> 0 | W44: Total | Y44: =SUM(Y37:Y43) -> 0 | Z44: 2 | AA44: Total | AC44: =SUM(AC37:AC43) -> 0 | AD44: 2 | AE44: Total | AG44: =SUM(AG37:AG43) -> 0 | AH44: Total | AJ44: =SUM(AJ37:AJ43) -> 0 | AK44: Total | AM44: =SUM(AM37:AM43) -> 0
C45: ='1. Rekap Back Up Aspal'!C24 -> 22000 | D45: ='1. Rekap Back Up Aspal'!D24 -> 22100 | E45: ='1. Rekap Back Up Aspal'!E24 -> 4.5 | F45: =(100/((D45-C45)*E45))*((J52*0.5)+(M52*0.5)+(P52*4)+(S52*4)+(V52*1)+(Y52*2)+(AC52*1.5)+(AG52*1)+(AJ52*1)+(AM52*1)) -> 0 | G45: =IF(F45<=25,"B",IF(F45<=75,"S",IF(F45<=100,"RR","RB"))) -> B | H45: 0 | I45: 0 | J45: =H45*I45 -> 0 | K45: 0 | L45: 0 | M45: =K45*L45 -> 0 | N45: 0 | O45: 4 | P45: =N45*O45 -> 0 | Q45: 0 | R45: 0 | S45: =Q45*R45 -> 0 | T45: 0 | U45: 0 | V45: =T45*U45 -> 0 | W45: 0 | X45: 0 | Y45: =W45*X45 -> 0 | Z45: 2 | AA45: 0 | AB45: 0 | AC45: =AA45*AB45 -> 0 | AD45: 1 | AE45: 0 | AF45: 0 | AG45: =AE45*AF45 -> 0 | AH45: 0 | AI45: 0 | AJ45: =AH45*AI45 -> 0 | AK45: 0 | AL45: 0 | AM45: =AK45*AL45 -> 0
H46: 0 | I46: 0 | J46: =H46*I46 -> 0 | K46: 0 | L46: 0 | M46: =K46*L46 -> 0 | N46: 0 | O46: 0 | P46: =N46*O46 -> 0 | Q46: 0 | R46: 0 | S46: =Q46*R46 -> 0 | T46: 0 | U46: 0 | V46: =T46*U46 -> 0 | W46: 0 | X46: 0 | Y46: =W46*X46 -> 0 | Z46: 3 | AA46: 0 | AB46: 0 | AC46: =AA46*AB46 -> 0 | AD46: 1 | AE46: 0 | AF46: 0 | AG46: =AE46*AF46 -> 0 | AH46: 0 | AI46: 0 | AJ46: =AH46*AI46 -> 0 | AK46: 0 | AL46: 0 | AM46: =AK46*AL46 -> 0
H47: 0 | I47: 0 | J47: =H47*I47 -> 0 | K47: 0 | L47: 0 | M47: =K47*L47 -> 0 | N47: 0 | O47: 0 | P47: =N47*O47 -> 0 | Q47: 0 | R47: 0 | S47: =Q47*R47 -> 0 | T47: 0 | U47: 0 | V47: =T47*U47 -> 0 | W47: 0 | X47: 0 | Y47: =W47*X47 -> 0 | Z47: 1 | AA47: 0 | AB47: 0 | AC47: =AA47*AB47 -> 0 | AD47: 1 | AE47: 0 | AF47: 0 | AG47: =AE47*AF47 -> 0 | AH47: 0 | AI47: 0 | AJ47: =AH47*AI47 -> 0 | AK47: 0 | AL47: 0 | AM47: =AK47*AL47 -> 0
H48: 0 | I48: 0 | J48: =H48*I48 -> 0 | K48: 0 | L48: 0 | M48: =K48*L48 -> 0 | N48: 0 | O48: 0 | P48: =N48*O48 -> 0 | Q48: 0 | R48: 0 | S48: =Q48*R48 -> 0 | T48: 0 | U48: 0 | V48: =T48*U48 -> 0 | W48: 0 | X48: 0 | Y48: =W48*X48 -> 0 | Z48: 1 | AA48: 0 | AB48: 0 | AC48: =AA48*AB48 -> 0 | AD48: 1 | AE48: 0 | AF48: 0 | AG48: =AE48*AF48 -> 0 | AH48: 0 | AI48: 0 | AJ48: =AH48*AI48 -> 0 | AK48: 0 | AL48: 0 | AM48: =AK48*AL48 -> 0
H49: 0 | I49: 0 | J49: =H49*I49 -> 0 | K49: 0 | L49: 0 | M49: =K49*L49 -> 0 | N49: 0 | O49: 0 | P49: =N49*O49 -> 0 | Q49: 0 | R49: 0 | S49: =Q49*R49 -> 0 | T49: 0 | U49: 0 | V49: =T49*U49 -> 0 | W49: 0 | X49: 0 | Y49: =W49*X49 -> 0 | Z49: 1 | AA49: 0 | AB49: 0 | AC49: =AA49*AB49 -> 0 | AD49: 1 | AE49: 0 | AF49: 0 | AG49: =AE49*AF49 -> 0 | AH49: 0 | AI49: 0 | AJ49: =AH49*AI49 -> 0 | AK49: 0 | AL49: 0 | AM49: =AK49*AL49 -> 0
H50: 0 | I50: 0 | J50: =H50*I50 -> 0 | K50: 0 | L50: 0 | M50: =K50*L50 -> 0 | N50: 0 | O50: 0 | P50: =N50*O50 -> 0 | Q50: 0 | R50: 0 | S50: =Q50*R50 -> 0 | T50: 0 | U50: 0 | V50: =T50*U50 -> 0 | W50: 0 | X50: 0 | Y50: =W50*X50 -> 0 | Z50: 1 | AA50: 0 | AB50: 0 | AC50: =AA50*AB50 -> 0 | AD50: 1 | AE50: 0 | AF50: 0 | AG50: =AE50*AF50 -> 0 | AH50: 0 | AI50: 0 | AJ50: =AH50*AI50 -> 0 | AK50: 0 | AL50: 0 | AM50: =AK50*AL50 -> 0
H51: 0 | I51: 0 | J51: =H51*I51 -> 0 | K51: 0 | L51: 0 | M51: =K51*L51 -> 0 | N51: 0 | O51: 0 | P51: =N51*O51 -> 0 | Q51: 0 | R51: 0 | S51: =Q51*R51 -> 0 | T51: 0 | U51: 0 | V51: =T51*U51 -> 0 | W51: 0 | X51: 0 | Y51: =W51*X51 -> 0 | Z51: 1 | AA51: 0 | AB51: 0 | AC51: =AA51*AB51 -> 0 | AD51: 1 | AE51: 0 | AF51: 0 | AG51: =AE51*AF51 -> 0 | AH51: 0 | AI51: 0 | AJ51: =AH51*AI51 -> 0 | AK51: 0 | AL51: 0 | AM51: =AK51*AL51 -> 0
...

Sheet 2. Rekap Back Up Beton
C2: PEMERINTAH PROVINSI LAMPUNG
C3: DINAS BINA MARGA DAN BINA KONSTRUKSI
B6: BACK - UP DATA SURVEY KONDISI JALAN (BETON)
B9: NO. RUAS | E9: : | F9: ='Link List'!D3 -> 044
B12: NAMA RUAS | E12: : | F12: ='Link List'!F3 -> SP TELUK KILUAN - SP. UMBAR
B15: PANJANG RUAS | E15: : | F15: ='Link List'!I3 -> 25.157
C18: STA | F18: NILAI TTI | G18: KONDISI | H18: TIPE KERUSAKAN KONDISI JALAN BETON | N18: KET
C19: DARI (M) | D19: KE (M) | E19: LEBAR | H19: BETON RETAK | I19: PECAH/ GOMPAL | J19: STRUKTUR RETAK | K19: PATAHAN/ PENURUNAN | L19: JUMLAH PUMPING | M19: JUMLAH PECAH SUDUT
B20: 1 | N20: 8
C21: 0 | D21: 100 | E21: 5 | F21: =(100/((D21-C21)*E21))*((H21*0.5)+(I21*1)+(J21*2)+(K21*20)+(L21*15)+(M21*1.5)) -> 0 | G21: =IF(F21<=25,"B",IF(F21<=75,"S",IF(F21<=100,"RR","RB"))) -> B | H21: ='2. Back Up Beton'!J28 -> 0 | I21: ='2. Back Up Beton'!M28 -> 0 | J21: ='2. Back Up Beton'!P28 -> 0 | K21: ='2. Back Up Beton'!S28 -> 0 | L21: ='2. Back Up Beton'!V28 -> 0 | M21: ='2. Back Up Beton'!Y28 -> 0
C22: =D21 -> 100 | D22: =C22+100 -> 200 | E22: 5 | F22: =(100/((D22-C22)*E22))*((H22*0.5)+(I22*1)+(J22*2)+(K22*20)+(L22*15)+(M22*1.5)) -> 0 | G22: =IF(F22<=25,"B",IF(F22<=75,"S",IF(F22<=100,"RR","RB"))) -> B | H22: ='2. Back Up Beton'!J36 -> 0 | I22: ='2. Back Up Beton'!M36 -> 0 | J22: ='2. Back Up Beton'!P36 -> 0 | K22: ='2. Back Up Beton'!S36 -> 0 | L22: ='2. Back Up Beton'!V36 -> 0 | M22: ='2. Back Up Beton'!Y36 -> 0
C23: =D22 -> 200 | D23: =C23+100 -> 300 | E23: 5 | F23: =(100/((D23-C23)*E23))*((H23*0.5)+(I23*1)+(J23*2)+(K23*20)+(L23*15)+(M23*1.5)) -> 4 | G23: =IF(F23<=25,"B",IF(F23<=75,"S",IF(F23<=100,"RR","RB"))) -> B | H23: ='2. Back Up Beton'!J44 -> 0 | I23: ='2. Back Up Beton'!M44 -> 0 | J23: ='2. Back Up Beton'!P44 -> 0 | K23: ='2. Back Up Beton'!S44 -> 1 | L23: ='2. Back Up Beton'!V44 -> 0 | M23: ='2. Back Up Beton'!Y44 -> 0
C24: =D23 -> 300 | D24: =C24+100 -> 400 | E24: 5 | F24: =(100/((D24-C24)*E24))*((H24*0.5)+(I24*1)+(J24*2)+(K24*20)+(L24*15)+(M24*1.5)) -> 0 | G24: =IF(F24<=25,"B",IF(F24<=75,"S",IF(F24<=100,"RR","RB"))) -> B | H24: ='2. Back Up Beton'!J52 -> 0 | I24: ='2. Back Up Beton'!M52 -> 0 | J24: ='2. Back Up Beton'!P52 -> 0 | K24: ='2. Back Up Beton'!S52 -> 0 | L24: ='2. Back Up Beton'!V52 -> 0 | M24: ='2. Back Up Beton'!Y52 -> 0
C25: =D24 -> 400 | D25: =C25+100 -> 500 | E25: 5 | F25: =(100/((D25-C25)*E25))*((H25*0.5)+(I25*1)+(J25*2)+(K25*20)+(L25*15)+(M25*1.5)) -> 1.3 | G25: =IF(F25<=25,"B",IF(F25<=75,"S",IF(F25<=100,"RR","RB"))) -> B | H25: ='2. Back Up Beton'!J60 -> 5 | I25: ='2. Back Up Beton'!M60 -> 0 | J25: ='2. Back Up Beton'!P60 -> 2 | K25: ='2. Back Up Beton'!S60 -> 0 | L25: ='2. Back Up Beton'!V60 -> 0 | M25: ='2. Back Up Beton'!Y60 -> 0
C26: =D25 -> 500 | D26: =C26+100 -> 600 | E26: 5 | F26: =(100/((D26-C26)*E26))*((H26*0.5)+(I26*1)+(J26*2)+(K26*20)+(L26*15)+(M26*1.5)) -> 0 | G26: =IF(F26<=25,"B",IF(F26<=75,"S",IF(F26<=100,"RR","RB"))) -> B | H26: ='2. Back Up Beton'!J68 -> 0 | I26: ='2. Back Up Beton'!M68 -> 0 | J26: ='2. Back Up Beton'!P68 -> 0 | K26: ='2. Back Up Beton'!S68 -> 0 | L26: ='2. Back Up Beton'!V68 -> 0 | M26: ='2. Back Up Beton'!Y68 -> 0
C27: =D26 -> 600 | D27: =C27+100 -> 700 | E27: 5 | F27: =(100/((D27-C27)*E27))*((H27*0.5)+(I27*1)+(J27*2)+(K27*20)+(L27*15)+(M27*1.5)) -> 0 | G27: =IF(F27<=25,"B",IF(F27<=75,"S",IF(F27<=100,"RR","RB"))) -> B | H27: ='2. Back Up Beton'!J76 -> 0 | I27: ='2. Back Up Beton'!M76 -> 0 | J27: ='2. Back Up Beton'!P76 -> 0 | K27: ='2. Back Up Beton'!S76 -> 0 | L27: ='2. Back Up Beton'!V76 -> 0 | M27: ='2. Back Up Beton'!Y76 -> 0
C28: =D27 -> 700 | D28: =C28+100 -> 800 | E28: 5 | F28: =(100/((D28-C28)*E28))*((H28*0.5)+(I28*1)+(J28*2)+(K28*20)+(L28*15)+(M28*1.5)) -> 0 | G28: =IF(F28<=25,"B",IF(F28<=75,"S",IF(F28<=100,"RR","RB"))) -> B | H28: ='2. Back Up Beton'!J84 -> 0 | I28: ='2. Back Up Beton'!M84 -> 0 | J28: ='2. Back Up Beton'!P84 -> 0 | K28: ='2. Back Up Beton'!S84 -> 0 | L28: ='2. Back Up Beton'!V84 -> 0 | M28: ='2. Back Up Beton'!Y84 -> 0
C29: =D28 -> 800 | D29: =C29+100 -> 900 | E29: 6 | F29: =(100/((D29-C29)*E29))*((H29*0.5)+(I29*1)+(J29*2)+(K29*20)+(L29*15)+(M29*1.5)) -> 0 | G29: =IF(F29<=25,"B",IF(F29<=75,"S",IF(F29<=100,"RR","RB"))) -> B | H29: ='2. Back Up Beton'!J92 -> 0 | I29: ='2. Back Up Beton'!M92 -> 0 | J29: ='2. Back Up Beton'!P92 -> 0 | K29: ='2. Back Up Beton'!S92 -> 0 | L29: ='2. Back Up Beton'!V92 -> 0 | M29: ='2. Back Up Beton'!Y92 -> 0
C30: =D29 -> 900 | D30: =C30+100 -> 1000 | E30: 6 | F30: =(100/((D30-C30)*E30))*((H30*0.5)+(I30*1)+(J30*2)+(K30*20)+(L30*15)+(M30*1.5)) -> 0 | G30: =IF(F30<=25,"B",IF(F30<=75,"S",IF(F30<=100,"RR","RB"))) -> B | H30: ='2. Back Up Beton'!J100 -> 0 | I30: ='2. Back Up Beton'!M100 -> 0 | J30: ='2. Back Up Beton'!P100 -> 0 | K30: ='2. Back Up Beton'!S100 -> 0 | L30: ='2. Back Up Beton'!V100 -> 0 | M30: ='2. Back Up Beton'!Y100 -> 0
C31: =NOTE!J11 -> 3650 | D31: 3700 | E31: 5 | F31: =(100/((D31-C31)*E31))*((H31*0.5)+(I31*1)+(J31*2)+(K31*20)+(L31*15)+(M31*1.5)) -> 176 | G31: =IF(F31<=25,"B",IF(F31<=75,"S",IF(F31<=100,"RR","RB"))) -> RB | H31: ='2. Back Up Beton'!J108 -> 0 | I31: ='2. Back Up Beton'!M108 -> 40 | J31: ='2. Back Up Beton'!P108 -> 0 | K31: ='2. Back Up Beton'!S108 -> 20 | L31: ='2. Back Up Beton'!V108 -> 0 | M31: ='2. Back Up Beton'!Y108 -> 0
C32: =D31 -> 3700 | D32: =C32+100 -> 3800 | E32: 5 | F32: =(100/((D32-C32)*E32))*((H32*0.5)+(I32*1)+(J32*2)+(K32*20)+(L32*15)+(M32*1.5)) -> 10 | G32: =IF(F32<=25,"B",IF(F32<=75,"S",IF(F32<=100,"RR","RB"))) -> B | H32: ='2. Back Up Beton'!J116 -> 0 | I32: ='2. Back Up Beton'!M116 -> 50 | J32: ='2. Back Up Beton'!P116 -> 0 | K32: ='2. Back Up Beton'!S116 -> 0 | L32: ='2. Back Up Beton'!V116 -> 0 | M32: ='2. Back Up Beton'!Y116 -> 0
C33: =D32 -> 3800 | D33: 3900 | E33: 5 | F33: =(100/((D33-C33)*E33))*((H33*0.5)+(I33*1)+(J33*2)+(K33*20)+(L33*15)+(M33*1.5)) -> 0 | G33: =IF(F33<=25,"B",IF(F33<=75,"S",IF(F33<=100,"RR","RB"))) -> B | H33: ='2. Back Up Beton'!J124 -> 0 | I33: ='2. Back Up Beton'!M124 -> 0 | J33: ='2. Back Up Beton'!P124 -> 0 | K33: ='2. Back Up Beton'!S124 -> 0 | L33: ='2. Back Up Beton'!V124 -> 0 | M33: ='2. Back Up Beton'!Y124 -> 0
C34: =D33 -> 3900 | D34: =C34+100 -> 4000 | E34: 5 | F34: =(100/((D34-C34)*E34))*((H34*0.5)+(I34*1)+(J34*2)+(K34*20)+(L34*15)+(M34*1.5)) -> 0 | G34: =IF(F34<=25,"B",IF(F34<=75,"S",IF(F34<=100,"RR","RB"))) -> B | H34: ='2. Back Up Beton'!J132 -> 0 | I34: ='2. Back Up Beton'!M132 -> 0 | J34: ='2. Back Up Beton'!P132 -> 0 | K34: ='2. Back Up Beton'!S132 -> 0 | L34: ='2. Back Up Beton'!V132 -> 0 | M34: ='2. Back Up Beton'!Y132 -> 0
C35: =D34 -> 4000 | D35: =C35+100 -> 4100 | E35: 5 | F35: =(100/((D35-C35)*E35))*((H35*0.5)+(I35*1)+(J35*2)+(K35*20)+(L35*15)+(M35*1.5)) -> 0 | G35: =IF(F35<=25,"B",IF(F35<=75,"S",IF(F35<=100,"RR","RB"))) -> B | H35: ='2. Back Up Beton'!J140 -> 0 | I35: ='2. Back Up Beton'!M140 -> 0 | J35: ='2. Back Up Beton'!P140 -> 0 | K35: ='2. Back Up Beton'!S140 -> 0 | L35: ='2. Back Up Beton'!V140 -> 0 | M35: ='2. Back Up Beton'!Y140 -> 0
C36: =D35 -> 4100 | D36: =C36+100 -> 4200 | E36: 5 | F36: =(100/((D36-C36)*E36))*((H36*0.5)+(I36*1)+(J36*2)+(K36*20)+(L36*15)+(M36*1.5)) -> 3.3 | G36: =IF(F36<=25,"B",IF(F36<=75,"S",IF(F36<=100,"RR","RB"))) -> B | H36: ='2. Back Up Beton'!J148 -> 3 | I36: ='2. Back Up Beton'!M148 -> 15 | J36: ='2. Back Up Beton'!P148 -> 0 | K36: ='2. Back Up Beton'!S148 -> 0 | L36: ='2. Back Up Beton'!V148 -> 0 | M36: ='2. Back Up Beton'!Y148 -> 0
C37: =D36 -> 4200 | D37: =C37+100 -> 4300 | E37: 5 | F37: =(100/((D37-C37)*E37))*((H37*0.5)+(I37*1)+(J37*2)+(K37*20)+(L37*15)+(M37*1.5)) -> 9 | G37: =IF(F37<=25,"B",IF(F37<=75,"S",IF(F37<=100,"RR","RB"))) -> B | H37: ='2. Back Up Beton'!J156 -> 0 | I37: ='2. Back Up Beton'!M156 -> 45 | J37: ='2. Back Up Beton'!P156 -> 0 | K37: ='2. Back Up Beton'!S156 -> 0 | L37: ='2. Back Up Beton'!V156 -> 0 | M37: ='2. Back Up Beton'!Y156 -> 0
C38: =D37 -> 4300 | D38: =C38+100 -> 4400 | E38: 5 | F38: =(100/((D38-C38)*E38))*((H38*0.5)+(I38*1)+(J38*2)+(K38*20)+(L38*15)+(M38*1.5)) -> 6 | G38: =IF(F38<=25,"B",IF(F38<=75,"S",IF(F38<=100,"RR","RB"))) -> B | H38: ='2. Back Up Beton'!J164 -> 60 | I38: ='2. Back Up Beton'!M164 -> 0 | J38: ='2. Back Up Beton'!P164 -> 0 | K38: ='2. Back Up Beton'!S164 -> 0 | L38: ='2. Back Up Beton'!V164 -> 0 | M38: ='2. Back Up Beton'!Y164 -> 0
C39: =D38 -> 4400 | D39: =C39+100 -> 4500 | E39: 5 | F39: =(100/((D39-C39)*E39))*((H39*0.5)+(I39*1)+(J39*2)+(K39*20)+(L39*15)+(M39*1.5)) -> 64 | G39: =IF(F39<=25,"B",IF(F39<=75,"S",IF(F39<=100,"RR","RB"))) -> S | H39: ='2. Back Up Beton'!J172 -> 0 | I39: ='2. Back Up Beton'!M172 -> 0 | J39: ='2. Back Up Beton'!P172 -> 0 | K39: ='2. Back Up Beton'!S172 -> 16 | L39: ='2. Back Up Beton'!V172 -> 0 | M39: ='2. Back Up Beton'!Y172 -> 0
C40: =D39 -> 4500 | D40: =C40+100 -> 4600 | E40: 5 | F40: =(100/((D40-C40)*E40))*((H40*0.5)+(I40*1)+(J40*2)+(K40*20)+(L40*15)+(M40*1.5)) -> 1.5 | G40: =IF(F40<=25,"B",IF(F40<=75,"S",IF(F40<=100,"RR","RB"))) -> B | H40: ='2. Back Up Beton'!J180 -> 15 | I40: ='2. Back Up Beton'!M180 -> 0 | J40: ='2. Back Up Beton'!P180 -> 0 | K40: ='2. Back Up Beton'!S180 -> 0 | L40: ='2. Back Up Beton'!V180 -> 0 | M40: ='2. Back Up Beton'!Y180 -> 0
C41: =D40 -> 4600 | D41: =C41+100 -> 4700 | E41: 5 | F41: =(100/((D41-C41)*E41))*((H41*0.5)+(I41*1)+(J41*2)+(K41*20)+(L41*15)+(M41*1.5)) -> 2.1 | G41: =IF(F41<=25,"B",IF(F41<=75,"S",IF(F41<=100,"RR","RB"))) -> B | H41: ='2. Back Up Beton'!J188 -> 21 | I41: ='2. Back Up Beton'!M188 -> 0 | J41: ='2. Back Up Beton'!P188 -> 0 | K41: ='2. Back Up Beton'!S188 -> 0 | L41: ='2. Back Up Beton'!V188 -> 0 | M41: ='2. Back Up Beton'!Y188 -> 0
C42: =D41 -> 4700 | D42: =C42+100 -> 4800 | E42: 5 | F42: =(100/((D42-C42)*E42))*((H42*0.5)+(I42*1)+(J42*2)+(K42*20)+(L42*15)+(M42*1.5)) -> 4.5 | G42: =IF(F42<=25,"B",IF(F42<=75,"S",IF(F42<=100,"RR","RB"))) -> B | H42: ='2. Back Up Beton'!J196 -> 45 | I42: ='2. Back Up Beton'!M196 -> 0 | J42: ='2. Back Up Beton'!P196 -> 0 | K42: ='2. Back Up Beton'!S196 -> 0 | L42: ='2. Back Up Beton'!V196 -> 0 | M42: ='2. Back Up Beton'!Y196 -> 0
C43: =D42 -> 4800 | D43: =C43+100 -> 4900 | E43: 5 | F43: =(100/((D43-C43)*E43))*((H43*0.5)+(I43*1)+(J43*2)+(K43*20)+(L43*15)+(M43*1.5)) -> 6 | G43: =IF(F43<=25,"B",IF(F43<=75,"S",IF(F43<=100,"RR","RB"))) -> B | H43: ='2. Back Up Beton'!J204 -> 0 | I43: ='2. Back Up Beton'!M204 -> 30 | J43: ='2. Back Up Beton'!P204 -> 0 | K43: ='2. Back Up Beton'!S204 -> 0 | L43: ='2. Back Up Beton'!V204 -> 0 | M43: ='2. Back Up Beton'!Y204 -> 0
C44: =D43 -> 4900 | D44: =C44+100 -> 5000 | E44: 5 | F44: =(100/((D44-C44)*E44))*((H44*0.5)+(I44*1)+(J44*2)+(K44*20)+(L44*15)+(M44*1.5)) -> 2.7 | G44: =IF(F44<=25,"B",IF(F44<=75,"S",IF(F44<=100,"RR","RB"))) -> B | H44: ='2. Back Up Beton'!J212 -> 27 | I44: ='2. Back Up Beton'!M212 -> 0 | J44: ='2. Back Up Beton'!P212 -> 0 | K44: ='2. Back Up Beton'!S212 -> 0 | L44: ='2. Back Up Beton'!V212 -> 0 | M44: ='2. Back Up Beton'!Y212 -> 0
C45: =D44 -> 5000 | D45: =C45+100 -> 5100 | E45: 5 | F45: =(100/((D45-C45)*E45))*((H45*0.5)+(I45*1)+(J45*2)+(K45*20)+(L45*15)+(M45*1.5)) -> 9 | G45: =IF(F45<=25,"B",IF(F45<=75,"S",IF(F45<=100,"RR","RB"))) -> B | H45: ='2. Back Up Beton'!J220 -> 0 | I45: ='2. Back Up Beton'!M220 -> 45 | J45: ='2. Back Up Beton'!P220 -> 0 | K45: ='2. Back Up Beton'!S220 -> 0 | L45: ='2. Back Up Beton'!V220 -> 0 | M45: ='2. Back Up Beton'!Y220 -> 0
C46: =D45 -> 5100 | D46: =C46+100 -> 5200 | E46: 5 | F46: =(100/((D46-C46)*E46))*((H46*0.5)+(I46*1)+(J46*2)+(K46*20)+(L46*15)+(M46*1.5)) -> 70 | G46: =IF(F46<=25,"B",IF(F46<=75,"S",IF(F46<=100,"RR","RB"))) -> S | H46: ='2. Back Up Beton'!J228 -> 0 | I46: ='2. Back Up Beton'!M228 -> 350 | J46: ='2. Back Up Beton'!P228 -> 0 | K46: ='2. Back Up Beton'!S228 -> 0 | L46: ='2. Back Up Beton'!V228 -> 0 | M46: ='2. Back Up Beton'!Y228 -> 0
C47: =NOTE!J13 -> 8150 | D47: 8200 | E47: 5 | F47: =(100/((D47-C47)*E47))*((H47*0.5)+(I47*1)+(J47*2)+(K47*20)+(L47*15)+(M47*1.5)) -> 30 | G47: =IF(F47<=25,"B",IF(F47<=75,"S",IF(F47<=100,"RR","RB"))) -> S | H47: ='2. Back Up Beton'!J236 -> 150 | I47: ='2. Back Up Beton'!M236 -> 0 | J47: ='2. Back Up Beton'!P236 -> 0 | K47: ='2. Back Up Beton'!S236 -> 0 | L47: ='2. Back Up Beton'!V236 -> 0 | M47: ='2. Back Up Beton'!Y236 -> 0
C48: =D47 -> 8200 | D48: =C48+100 -> 8300 | E48: 5 | F48: =(100/((D48-C48)*E48))*((H48*0.5)+(I48*1)+(J48*2)+(K48*20)+(L48*15)+(M48*1.5)) -> 30 | G48: =IF(F48<=25,"B",IF(F48<=75,"S",IF(F48<=100,"RR","RB"))) -> S | H48: ='2. Back Up Beton'!J244 -> 300 | I48: ='2. Back Up Beton'!M244 -> 0 | J48: ='2. Back Up Beton'!P244 -> 0 | K48: ='2. Back Up Beton'!S244 -> 0 | L48: ='2. Back Up Beton'!V244 -> 0 | M48: ='2. Back Up Beton'!Y244 -> 0
C49: =D48 -> 8300 | D49: =C49+100 -> 8400 | E49: 5 | F49: =(100/((D49-C49)*E49))*((H49*0.5)+(I49*1)+(J49*2)+(K49*20)+(L49*15)+(M49*1.5)) -> 30 | G49: =IF(F49<=25,"B",IF(F49<=75,"S",IF(F49<=100,"RR","RB"))) -> S | H49: ='2. Back Up Beton'!J252 -> 300 | I49: ='2. Back Up Beton'!M252 -> 0 | J49: ='2. Back Up Beton'!P252 -> 0 | K49: ='2. Back Up Beton'!S252 -> 0 | L49: ='2. Back Up Beton'!V252 -> 0 | M49: ='2. Back Up Beton'!Y252 -> 0
C50: =D49 -> 8400 | D50: 8500 | E50: 5 | F50: =(100/((D50-C50)*E50))*((H50*0.5)+(I50*1)+(J50*2)+(K50*20)+(L50*15)+(M50*1.5)) -> 30 | G50: =IF(F50<=25,"B",IF(F50<=75,"S",IF(F50<=100,"RR","RB"))) -> S | H50: ='2. Back Up Beton'!J260 -> 300 | I50: ='2. Back Up Beton'!M260 -> 0 | J50: ='2. Back Up Beton'!P260 -> 0 | K50: ='2. Back Up Beton'!S260 -> 0 | L50: ='2. Back Up Beton'!V260 -> 0 | M50: ='2. Back Up Beton'!Y260 -> 0
C51: =D50 -> 8500 | D51: =C51+100 -> 8600 | E51: 5 | F51: =(100/((D51-C51)*E51))*((H51*0.5)+(I51*1)+(J51*2)+(K51*20)+(L51*15)+(M51*1.5)) -> 30 | G51: =IF(F51<=25,"B",IF(F51<=75,"S",IF(F51<=100,"RR","RB"))) -> S | H51: ='2. Back Up Beton'!J268 -> 300 | I51: ='2. Back Up Beton'!M268 -> 0 | J51: ='2. Back Up Beton'!P268 -> 0 | K51: ='2. Back Up Beton'!S268 -> 0 | L51: ='2. Back Up Beton'!V268 -> 0 | M51: ='2. Back Up Beton'!Y268 -> 0
...

Sheet 2. Back Up Beton
C2: PEMERINTAH PROVINSI LAMPUNG
C3: DINAS BINA MARGA DAN BINA KONSTRUKSI
B6: BACK - UP DATA SURVEY KONDISI JALAN (BETON)
B9: NO. RUAS | E9: : | F9: ='Link List'!D3 -> 044
B12: NAMA RUAS | E12: : | F12: ='Link List'!F3 -> SP TELUK KILUAN - SP. UMBAR
B15: PANJANG RUAS | E15: : | F15: ='Link List'!I3 -> 25.157
C18: STA | F18: NILAI TTI | G18: KONDISI | H18: TIPE KERUSAKAN KONDISI JALAN BETON | Z18: KET
C19: DARI (M) | D19: KE (M) | E19: LEBAR | H19: P | I19: L | J19: BETON RETAK | K19: P | L19: L | M19: PECAH/ GOMPAL | N19: P | O19: L | P19: STRUKTUR RETAK | Q19: P | R19: L | S19: PATAHAN/ PENURUNAN | T19: JUMLAH PUMPING | W19: JUMLAH PECAH SUDUT
B20: 1 | H20: 2 | K20: 3 | N20: 4 | Q20: 5 | W20: 7 | Z20: 8
C21: ='2. Rekap Back Up Beton'!C21 -> 0 | D21: ='2. Rekap Back Up Beton'!D21 -> 100 | E21: ='2. Rekap Back Up Beton'!E21 -> 5 | F21: =(100/((D21-C21)*E21))*((J28*0.5)+(M28*1)+(P28*2)+(S28*20)+(V28*15)+(Y28*1.5)) -> 0 | G21: =IF(F21<=25,"B",IF(F21<=75,"S",IF(F21<=100,"RR","RB"))) -> B | H21: 0 | I21: 0 | J21: =H21*I21 -> 0 | K21: 0 | L21: 0 | M21: =K21*L21 -> 0 | N21: 0 | O21: 0 | P21: =N21*O21 -> 0 | Q21: 0 | R21: 0 | S21: =Q21*R21 -> 0 | T21: 0 | U21: 0 | V21: =T21*U21 -> 0 | W21: 0 | X21: 0 | Y21: =W21*X21 -> 0
H22: 0 | I22: 0 | J22: =H22*I22 -> 0 | K22: 0 | L22: 0 | M22: =K22*L22 -> 0 | N22: 0 | O22: 0 | P22: =N22*O22 -> 0 | Q22: 0 | R22: 0 | S22: =Q22*R22 -> 0 | T22: 0 | U22: 0 | V22: =T22*U22 -> 0 | W22: 0 | X22: 0 | Y22: =W22*X22 -> 0
H23: 0 | I23: 0 | J23: =H23*I23 -> 0 | K23: 0 | L23: 0 | M23: =K23*L23 -> 0 | N23: 0 | O23: 0 | P23: =N23*O23 -> 0 | Q23: 0 | R23: 0 | S23: =Q23*R23 -> 0 | T23: 0 | U23: 0 | V23: =T23*U23 -> 0 | W23: 0 | X23: 0 | Y23: =W23*X23 -> 0
H24: 0 | I24: 0 | J24: =H24*I24 -> 0 | K24: 0 | L24: 0 | M24: =K24*L24 -> 0 | N24: 0 | O24: 0 | P24: =N24*O24 -> 0 | Q24: 0 | R24: 0 | S24: =Q24*R24 -> 0 | T24: 0 | U24: 0 | V24: =T24*U24 -> 0 | W24: 0 | X24: 0 | Y24: =W24*X24 -> 0
H25: 0 | I25: 0 | J25: =H25*I25 -> 0 | K25: 0 | L25: 0 | M25: =K25*L25 -> 0 | N25: 0 | O25: 0 | P25: =N25*O25 -> 0 | Q25: 0 | R25: 0 | S25: =Q25*R25 -> 0 | T25: 0 | U25: 0 | V25: =T25*U25 -> 0 | W25: 0 | X25: 0 | Y25: =W25*X25 -> 0
H26: 0 | I26: 0 | J26: =H26*I26 -> 0 | K26: 0 | L26: 0 | M26: =K26*L26 -> 0 | N26: 0 | O26: 0 | P26: =N26*O26 -> 0 | Q26: 0 | R26: 0 | S26: =Q26*R26 -> 0 | T26: 0 | U26: 0 | V26: =T26*U26 -> 0 | W26: 0 | X26: 0 | Y26: =W26*X26 -> 0
H27: 0 | I27: 0 | J27: =H27*I27 -> 0 | K27: 0 | L27: 0 | M27: =K27*L27 -> 0 | N27: 0 | O27: 0 | P27: =N27*O27 -> 0 | Q27: 0 | R27: 0 | S27: =Q27*R27 -> 0 | T27: 0 | U27: 0 | V27: =T27*U27 -> 0 | W27: 0 | X27: 0 | Y27: =W27*X27 -> 0
H28: Total | J28: =SUM(J21:J27) -> 0 | K28: Total | M28: =SUM(M21:M27) -> 0 | N28: Total | P28: =SUM(P21:P27) -> 0 | Q28: Total | S28: =SUM(S21:S27) -> 0 | T28: Total | V28: =SUM(V21:V27) -> 0 | W28: Total | Y28: =SUM(Y21:Y27) -> 0
C29: ='2. Rekap Back Up Beton'!C22 -> 100 | D29: ='2. Rekap Back Up Beton'!D22 -> 200 | E29: ='2. Rekap Back Up Beton'!E22 -> 5 | F29: =(100/((D29-C29)*E29))*((J36*0.5)+(M36*1)+(P36*2)+(S36*20)+(V36*15)+(Y36*1.5)) -> 0 | G29: =IF(F29<=25,"B",IF(F29<=75,"S",IF(F29<=100,"RR","RB"))) -> B | H29: 0 | I29: 0 | J29: =H29*I29 -> 0 | K29: 0 | L29: 0 | M29: =K29*L29 -> 0 | N29: 0 | O29: 4 | P29: =N29*O29 -> 0 | Q29: 0 | R29: 0 | S29: =Q29*R29 -> 0 | T29: 0 | U29: 0 | V29: =T29*U29 -> 0 | W29: 0 | X29: 0 | Y29: =W29*X29 -> 0
H30: 0 | I30: 0 | J30: =H30*I30 -> 0 | K30: 0 | L30: 0 | M30: =K30*L30 -> 0 | N30: 0 | O30: 0 | P30: =N30*O30 -> 0 | Q30: 0 | R30: 0 | S30: =Q30*R30 -> 0 | T30: 0 | U30: 0 | V30: =T30*U30 -> 0 | W30: 0 | X30: 0 | Y30: =W30*X30 -> 0
H31: 0 | I31: 0 | J31: =H31*I31 -> 0 | K31: 0 | L31: 0 | M31: =K31*L31 -> 0 | N31: 0 | O31: 0 | P31: =N31*O31 -> 0 | Q31: 0 | R31: 0 | S31: =Q31*R31 -> 0 | T31: 0 | U31: 0 | V31: =T31*U31 -> 0 | W31: 0 | X31: 0 | Y31: =W31*X31 -> 0
H32: 0 | I32: 0 | J32: =H32*I32 -> 0 | K32: 0 | L32: 0 | M32: =K32*L32 -> 0 | N32: 0 | O32: 0 | P32: =N32*O32 -> 0 | Q32: 0 | R32: 0 | S32: =Q32*R32 -> 0 | T32: 0 | U32: 0 | V32: =T32*U32 -> 0 | W32: 0 | X32: 0 | Y32: =W32*X32 -> 0
H33: 0 | I33: 0 | J33: =H33*I33 -> 0 | K33: 0 | L33: 0 | M33: =K33*L33 -> 0 | N33: 0 | O33: 0 | P33: =N33*O33 -> 0 | Q33: 0 | R33: 0 | S33: =Q33*R33 -> 0 | T33: 0 | U33: 0 | V33: =T33*U33 -> 0 | W33: 0 | X33: 0 | Y33: =W33*X33 -> 0
H34: 0 | I34: 0 | J34: =H34*I34 -> 0 | K34: 0 | L34: 0 | M34: =K34*L34 -> 0 | N34: 0 | O34: 0 | P34: =N34*O34 -> 0 | Q34: 0 | R34: 0 | S34: =Q34*R34 -> 0 | T34: 0 | U34: 0 | V34: =T34*U34 -> 0 | W34: 0 | X34: 0 | Y34: =W34*X34 -> 0
H35: 0 | I35: 0 | J35: =H35*I35 -> 0 | K35: 0 | L35: 0 | M35: =K35*L35 -> 0 | N35: 0 | O35: 0 | P35: =N35*O35 -> 0 | Q35: 0 | R35: 0 | S35: =Q35*R35 -> 0 | T35: 0 | U35: 0 | V35: =T35*U35 -> 0 | W35: 0 | X35: 0 | Y35: =W35*X35 -> 0
H36: Total | J36: =SUM(J29:J35) -> 0 | K36: Total | M36: =SUM(M29:M35) -> 0 | N36: Total | P36: =SUM(P29:P35) -> 0 | Q36: Total | S36: =SUM(S29:S35) -> 0 | T36: Total | V36: =SUM(V29:V35) -> 0 | W36: Total | Y36: =SUM(Y29:Y35) -> 0
C37: ='2. Rekap Back Up Beton'!C23 -> 200 | D37: ='2. Rekap Back Up Beton'!D23 -> 300 | E37: ='2. Rekap Back Up Beton'!E23 -> 5 | F37: =(100/((D37-C37)*E37))*((J44*0.5)+(M44*1)+(P44*2)+(S44*20)+(V44*15)+(Y44*1.5)) -> 4 | G37: =IF(F37<=25,"B",IF(F37<=75,"S",IF(F37<=100,"RR","RB"))) -> B | H37: 0 | I37: 0 | J37: =H37*I37 -> 0 | K37: 0 | L37: 0 | M37: =K37*L37 -> 0 | N37: 0 | O37: 4 | P37: =N37*O37 -> 0 | Q37: 1 | R37: 1 | S37: =Q37*R37 -> 1 | T37: 0 | U37: 0 | V37: =T37*U37 -> 0 | W37: 0 | X37: 0 | Y37: =W37*X37 -> 0
H38: 0 | I38: 0 | J38: =H38*I38 -> 0 | K38: 0 | L38: 0 | M38: =K38*L38 -> 0 | N38: 0 | O38: 0 | P38: =N38*O38 -> 0 | Q38: 0 | R38: 0 | S38: =Q38*R38 -> 0 | T38: 0 | U38: 0 | V38: =T38*U38 -> 0 | W38: 0 | X38: 0 | Y38: =W38*X38 -> 0
H39: 0 | I39: 0 | J39: =H39*I39 -> 0 | K39: 0 | L39: 0 | M39: =K39*L39 -> 0 | N39: 0 | O39: 0 | P39: =N39*O39 -> 0 | Q39: 0 | R39: 0 | S39: =Q39*R39 -> 0 | T39: 0 | U39: 0 | V39: =T39*U39 -> 0 | W39: 0 | X39: 0 | Y39: =W39*X39 -> 0
H40: 0 | I40: 0 | J40: =H40*I40 -> 0 | K40: 0 | L40: 0 | M40: =K40*L40 -> 0 | N40: 0 | O40: 0 | P40: =N40*O40 -> 0 | Q40: 0 | R40: 0 | S40: =Q40*R40 -> 0 | T40: 0 | U40: 0 | V40: =T40*U40 -> 0 | W40: 0 | X40: 0 | Y40: =W40*X40 -> 0
H41: 0 | I41: 0 | J41: =H41*I41 -> 0 | K41: 0 | L41: 0 | M41: =K41*L41 -> 0 | N41: 0 | O41: 0 | P41: =N41*O41 -> 0 | Q41: 0 | R41: 0 | S41: =Q41*R41 -> 0 | T41: 0 | U41: 0 | V41: =T41*U41 -> 0 | W41: 0 | X41: 0 | Y41: =W41*X41 -> 0
H42: 0 | I42: 0 | J42: =H42*I42 -> 0 | K42: 0 | L42: 0 | M42: =K42*L42 -> 0 | N42: 0 | O42: 0 | P42: =N42*O42 -> 0 | Q42: 0 | R42: 0 | S42: =Q42*R42 -> 0 | T42: 0 | U42: 0 | V42: =T42*U42 -> 0 | W42: 0 | X42: 0 | Y42: =W42*X42 -> 0
H43: 0 | I43: 0 | J43: =H43*I43 -> 0 | K43: 0 | L43: 0 | M43: =K43*L43 -> 0 | N43: 0 | O43: 0 | P43: =N43*O43 -> 0 | Q43: 0 | R43: 0 | S43: =Q43*R43 -> 0 | T43: 0 | U43: 0 | V43: =T43*U43 -> 0 | W43: 0 | X43: 0 | Y43: =W43*X43 -> 0
H44: Total | J44: =SUM(J37:J43) -> 0 | K44: Total | M44: =SUM(M37:M43) -> 0 | N44: Total | P44: =SUM(P37:P43) -> 0 | Q44: Total | S44: =SUM(S37:S43) -> 1 | T44: Total | V44: =SUM(V37:V43) -> 0 | W44: Total | Y44: =SUM(Y37:Y43) -> 0
C45: ='2. Rekap Back Up Beton'!C24 -> 300 | D45: ='2. Rekap Back Up Beton'!D24 -> 400 | E45: ='2. Rekap Back Up Beton'!E24 -> 5 | F45: =(100/((D45-C45)*E45))*((J52*0.5)+(M52*1)+(P52*2)+(S52*20)+(V52*15)+(Y52*1.5)) -> 0 | G45: =IF(F45<=25,"B",IF(F45<=75,"S",IF(F45<=100,"RR","RB"))) -> B | H45: 0 | I45: 0 | J45: =H45*I45 -> 0 | K45: 0 | L45: 0 | M45: =K45*L45 -> 0 | N45: 0 | O45: 4 | P45: =N45*O45 -> 0 | Q45: 0 | R45: 0 | S45: =Q45*R45 -> 0 | T45: 0 | U45: 0 | V45: =T45*U45 -> 0 | W45: 0 | X45: 0 | Y45: =W45*X45 -> 0
H46: 0 | I46: 0 | J46: =H46*I46 -> 0 | K46: 0 | L46: 0 | M46: =K46*L46 -> 0 | N46: 0 | O46: 0 | P46: =N46*O46 -> 0 | Q46: 0 | R46: 0 | S46: =Q46*R46 -> 0 | T46: 0 | U46: 0 | V46: =T46*U46 -> 0 | W46: 0 | X46: 0 | Y46: =W46*X46 -> 0
H47: 0 | I47: 0 | J47: =H47*I47 -> 0 | K47: 0 | L47: 0 | M47: =K47*L47 -> 0 | N47: 0 | O47: 0 | P47: =N47*O47 -> 0 | Q47: 0 | R47: 0 | S47: =Q47*R47 -> 0 | T47: 0 | U47: 0 | V47: =T47*U47 -> 0 | W47: 0 | X47: 0 | Y47: =W47*X47 -> 0
H48: 0 | I48: 0 | J48: =H48*I48 -> 0 | K48: 0 | L48: 0 | M48: =K48*L48 -> 0 | N48: 0 | O48: 0 | P48: =N48*O48 -> 0 | Q48: 0 | R48: 0 | S48: =Q48*R48 -> 0 | T48: 0 | U48: 0 | V48: =T48*U48 -> 0 | W48: 0 | X48: 0 | Y48: =W48*X48 -> 0
H49: 0 | I49: 0 | J49: =H49*I49 -> 0 | K49: 0 | L49: 0 | M49: =K49*L49 -> 0 | N49: 0 | O49: 0 | P49: =N49*O49 -> 0 | Q49: 0 | R49: 0 | S49: =Q49*R49 -> 0 | T49: 0 | U49: 0 | V49: =T49*U49 -> 0 | W49: 0 | X49: 0 | Y49: =W49*X49 -> 0
H50: 0 | I50: 0 | J50: =H50*I50 -> 0 | K50: 0 | L50: 0 | M50: =K50*L50 -> 0 | N50: 0 | O50: 0 | P50: =N50*O50 -> 0 | Q50: 0 | R50: 0 | S50: =Q50*R50 -> 0 | T50: 0 | U50: 0 | V50: =T50*U50 -> 0 | W50: 0 | X50: 0 | Y50: =W50*X50 -> 0
H51: 0 | I51: 0 | J51: =H51*I51 -> 0 | K51: 0 | L51: 0 | M51: =K51*L51 -> 0 | N51: 0 | O51: 0 | P51: =N51*O51 -> 0 | Q51: 0 | R51: 0 | S51: =Q51*R51 -> 0 | T51: 0 | U51: 0 | V51: =T51*U51 -> 0 | W51: 0 | X51: 0 | Y51: =W51*X51 -> 0
...

Sheet 3. Rekap Back Up Non Aspal 
C2: PEMERINTAH PROVINSI LAMPUNG
C3: DINAS BINA MARGA DAN BINA KONSTRUKSI
B6: BACK - UP DATA SURVEY KONDISI JALAN (NON-ASPAL)
B9: NO. RUAS | E9: : | F9: ='Link List'!D3 -> 044
B12: NAMA RUAS | E12: : | F12: ='Link List'!F3 -> SP TELUK KILUAN - SP. UMBAR
B15: PANJANG RUAS | E15: : | F15: ='Link List'!I3 -> 25.157
C18: STA | F18: NILAI TTI | G18: KONDISI | H18: TIPE KERUSAKAN KONDISI JALAN NON ASPAL | V18: KET
C19: DARI (M) | D19: KE (M) | E19: LEBAR | H19: BENTUK KEMIRINGAN | I19: KEMIRINGAN | J19: PENURUNAN | K19: EROSI | L19: GELOMBANG | M19: UKURAN KERIKIL | N19: TEBAL KERIKIL | O19: LUAS KERIKIL | P19: DISTRIBUSI | Q19: JUMLAH LUBANG | R19: UKURAN LUBANG | S19: LUAS LUBANG | T19: LUAS ALUR | U19: DALAM ALUR
B20: 1 | H20: 2 | J20: 3 | K20: 4 | L20: 5 | M20: 6 | P20: 7 | Q20: 8 | T20: 9 | V20: 10
