Workbook
Name QTemp: CHECKLIST!$B$2:$I$25
Name QTemp: 'Link List'!$B$1:$M$23

Sheet CHECKLIST
A1: CHECKLIST
A2: No | B2: Ruas | C2: Sffx | D2: Nama Ruas | E2: Panjang Ruas SK Gub (km) | F2: STA | G2: DATA INVEN | H2: DATA KONDISI | J2: KETERANGAN
H3: BACK UP LAMA | I3: BACK UP BARU
A4: 1 | B4: 036 | D4: SUKAMARA - KURIPAN | E4: 21.777 | F4: OK | I4: OK | J4: MAS FEBRI
A5: =+A4+1 -> 2 | B5: 044 | D5: SP TELUK KILUAN - SP. UMBAR | E5: 25.157 | F5: OK | J5: MAS FEBRI
A6: =+A5+1 -> 3 | B6: 045 | D6: SP. UMBAR - PUTIH DOH | E6: 23.83 | F6: OK | J6: MAS FEBRI
A7: =+A6+1 -> 4 | B7: 046 | D7: PUTIH DOH - KURIPAN | E7: 11.736 | F7: OK | J7: MAS FEBRI
A8: =+A7+1 -> 5 | B8: 047 | D8: KURIPAN - SP. KOTA AGUNG | E8: 21.468 | F8: OK | I8: OK | J8: MAS FEBRI
A9: =+A8+1 -> 6 | B9: 048 | D9: PEKON BALAK - SUOH | E9: 33.628 | F9: OK | J9: MAS ADI
A10: =+A9+1 -> 7 | B10: 049 | D10: SUOH - SP. BLOK 9 | E10: 30.447 | F10: OK | H10: OK | J10: MAS EKO
A11: =+A10+1 -> 8 | B11: 050 | D11: SP. BLOK 9 - SANGGI | E11: 20.873 | F11: OK | H11: OK | J11: MAS ADI
A12: =+A11+1 -> 9 | B12: 051 | C12: 11K | D12: JALAN RADEN INTAN (LIWA) | E12: 5.179 | G12: OK | H12: OK | J12: MAS FEBRI
A13: =+A12+1 -> 10 | B13: 052 | D13: LIWA - BTS. SUMATERA SELATAN | E13: 19.109 | G13: OK | H13: OK | J13: MAS FEBRI
A14: =+A13+1 -> 11 | B14: 053 | C14: 11K | D14: JALAN ADAM MALIK (KRUI) | E14: 1.812 | G14: OK | H14: OK | J14: NABIL
A15: =+A14+1 -> 12 | B15: 054 | D15: KRUI - PEKON SERAI | E15: 1.81 | G15: OK | H15: OK | J15: NABIL
A16: =+A15+1 -> 13 | B16: 055 | D16: KOTAJAWA - KAMPUNG BARU | E16: 8.374 | G16: OK | H16: OK | J16: MAS FEBRI
A17: =+A16+1 -> 14 | B17: 056 | D17: TALANG PADANG - NGARIP | E17: 35.862 | G17: OK | H17: OK | J17: MAS FEBRI
A18: =+A17+1 -> 15 | B18: 057 | D18: NGARIP - ULU SEMONG | E18: 21.5 | G18: OK | H18: OK | J18: MAS FEBRI
A19: =+A18+1 -> 16 | B19: 058 | D19: ULU SEMONG - SP. TRIMULYO | E19: 9.66 | G19: OK | H19: OK | J19: MAS FEBRI
A20: =+A19+1 -> 17 | B20: 059 | D20: SP. TRIMULYO - BUNGIN - SP. TUGU SARI | E20: 24.574 | G20: OK | H20: OK | J20: MAS FEBRI
A21: =+A20+1 -> 18 | B21: 060 | D21: TEKAD - BATUTEGI | E21: 4.8 | F21: OK | I21: OK | J21: MAS ADI
A22: =+A21+1 -> 19 | B22: 064 | D22: BANDAR SAKTI - SP. DAYA MURNI | E22: 10.099 | G22: OK | H22: OK | J22: NABIL
A23: =+A22+1 -> 20 | B23: 065 | D23: SP. DAYA MURNI - GUNUNG BATIN | E23: 12.389 | G23: OK | H23: OK | J23: MAS AGUS
A24: =+A23+1 -> 21 | B24: 068 | D24: SP. TUJOK - PANARAGAN JAYA | E24: 25.813 | F24: OK | J24: MAS EKO
A25: =+A24+1 -> 22 | B25: 069 | D25: PANARAGAN JAYA - SP. PANARAGAN | E25: 4.104 | G25: OK | H25: OK | J25: NABIL
A26: =+A25+1 -> 23 | B26: 085 | C26: 11K | D26: JALAN RAYA GUNUNG SAKTI (MENGGALA) | E26: 1.865 | G26: OK | H26: OK | J26: NABIL
A27: =+A26+1 -> 24 | B27: 086 | D27: BUJUNG TENUK - PENUMANGAN | E27: 12.432 | F27: OK | G27: OK | H27: OK | J27: NABIL
A28: =+A27+1 -> 25 | B28: 087 | D28: PENUMANGAN - TEGAL MUKTI | E28: 15.839 | G28: OK | H28: OK | J28: NABIL
A29: =+A28+1 -> 26 | B29: 090 | D29: ADIJAYA - TULUNG RANDU | E29: 38.13 | F29: OK | J29: MAS EKO
A30: =+A29+1 -> 27 | B30: 091 | D30: PENUMANGAN - UNIT VI | E30: 23.562 | F30: OK | J30: MAS EKO
A31: =+A30+1 -> 28 | B31: 092 | D31: SP. UNIT VIII - GEDONG AJI | E31: 22.05 | F31: OK | H31: OK | J31: MAS EKO
A32: =+A31+1 -> 29 | B32: 093 | D32: GEDONG AJI - UMBUL MESIR | E32: 31.5 | F32: OK | H32: OK | J32: MAS EKO
A33: =+A32+1 -> 30 | B33: 094 | D33: SP. PEMATANG - BRABASAN | E33: 11.602 | F33: OK | J33: MAS AGUS
A34: =+A33+1 -> 31 | B34: 095 | D34: BRABASAN - WIRALAGA | E34: 29.443 | F34: OK | J34: MAS EKO

Sheet Link List
A1: No | B1: Kode provinsi | C1: Kode Kabupaten | D1: Ruas | E1: Sffx | F1: Nama Ruas | G1: Status | H1: Fungsi | I1: Panjang Ruas SK Gub (km) | J1: Panjang Ruas Survei (km) | K1: Titik Awal Ruas - Patok KM | L1: Titik Awal Ruas - Offset (m) | M1: Link Access Status
A2: 1 | B2: 18 | C2: 00 | D2: 036 | F2: SUKAMARA - KURIPAN | G2: P | H2: K2 | I2: 21.777 | J2: 21.777 | K2: 0 | L2: 0 | M2: P
A3: =+A2+1 -> 2 | B3: 18 | C3: 00 | D3: 044 | F3: SP TELUK KILUAN - SP. UMBAR | G3: P | H3: K2 | I3: 25.157 | J3: 25.157 | K3: 0 | L3: 0 | M3: P
A4: =+A3+1 -> 3 | B4: 18 | C4: 00 | D4: 045 | F4: SP. UMBAR - PUTIH DOH | G4: P | H4: K2 | I4: 23.83 | J4: 23.83 | K4: 0 | L4: 0 | M4: P
A5: =+A4+1 -> 4 | B5: 18 | C5: 00 | D5: 046 | F5: PUTIH DOH - KURIPAN | G5: P | H5: K2 | I5: 11.736 | J5: 11.736 | K5: 0 | L5: 0 | M5: P
A6: =+A5+1 -> 5 | B6: 18 | C6: 00 | D6: 047 | F6: KURIPAN - SP. KOTA AGUNG | G6: P | H6: K2 | I6: 21.468 | J6: 21.468 | K6: 0 | L6: 0 | M6: N
A7: =+A6+1 -> 6 | B7: 18 | C7: 00 | D7: 048 | F7: PEKON BALAK - SUOH | G7: P | H7: K2 | I7: 33.628 | J7: 33.628 | K7: 0 | L7: 0 | M7: N
A8: =+A7+1 -> 7 | B8: 18 | C8: 00 | D8: 049 | F8: SUOH - SP. BLOK 9 | G8: P | H8: K2 | I8: 30.447 | J8: 30.447 | K8: 0 | L8: 0 | M8: P
A9: =+A8+1 -> 8 | B9: 18 | C9: 00 | D9: 050 | F9: SP. BLOK 9 - SANGGI | G9: P | H9: K2 | I9: 20.873 | J9: 20.873 | K9: 0 | L9: 0 | M9: N
A10: =+A9+1 -> 9 | B10: 18 | C10: 00 | D10: 051 | E10: 11K | F10: JALAN RADEN INTAN (LIWA) | G10: P | H10: K2 | I10: 5.179 | J10: 5.179 | K10: 0 | L10: 0 | M10: N
A11: =+A10+1 -> 10 | B11: 18 | C11: 00 | D11: 052 | F11: LIWA - BTS. SUMATERA SELATAN | G11: P | H11: K2 | I11: 19.109 | J11: 19.109 | K11: 0 | L11: 0 | M11: P
A12: =+A11+1 -> 11 | B12: 18 | C12: 00 | D12: 053 | E12: 11K | F12: JALAN ADAM MALIK (KRUI) | G12: P | H12: K2 | I12: 1.812 | J12: 1.812 | K12: 0 | L12: 0 | M12: N
A13: =+A12+1 -> 12 | B13: 18 | C13: 00 | D13: 054 | F13: KRUI - PEKON SERAI | G13: P | H13: K2 | I13: 1.81 | J13: 1.81 | K13: 0 | L13: 0 | M13: N
A14: =+A13+1 -> 13 | B14: 18 | C14: 00 | D14: 055 | F14: KOTAJAWA - KAMPUNG BARU | G14: P | H14: K2 | I14: 8.374 | J14: 8.374 | K14: 0 | L14: 0 | M14: N
A15: =+A14+1 -> 14 | B15: 18 | C15: 00 | D15: 056 | F15: TALANG PADANG - NGARIP | G15: P | H15: K2 | I15: 35.862 | J15: 35.862 | K15: 0 | L15: 0 | M15: N
A16: =+A15+1 -> 15 | B16: 18 | C16: 00 | D16: 057 | F16: NGARIP - ULU SEMONG | G16: P | H16: K2 | I16: 21.5 | J16: 21.5 | K16: 0 | L16: 0 | M16: P
A17: =+A16+1 -> 16 | B17: 18 | C17: 00 | D17: 058 | F17: ULU SEMONG - SP. TRIMULYO | G17: P | H17: K2 | I17: 9.66 | J17: 9.66 | K17: 0 | L17: 0 | M17: P
A18: =+A17+1 -> 17 | B18: 18 | C18: 00 | D18: 059 | F18: SP. TRIMULYO - BUNGIN - SP. TUGU SARI | G18: P | H18: K2 | I18: 24.574 | J18: 24.574 | K18: 0 | L18: 0 | M18: N
A19: =+A18+1 -> 18 | B19: 18 | C19: 00 | D19: 060 | F19: TEKAD - BATUTEGI | G19: P | H19: K2 | I19: 4.8 | J19: 4.8 | K19: 0 | L19: 0 | M19: P
A20: =+A19+1 -> 19 | B20: 18 | C20: 00 | D20: 064 | F20: BANDAR SAKTI - SP. DAYA MURNI | G20: P | H20: K2 | I20: 10.099 | J20: 10.099 | K20: 0 | L20: 0 | M20: P
A21: =+A20+1 -> 20 | B21: 18 | C21: 00 | D21: 065 | F21: SP. DAYA MURNI - GUNUNG BATIN | G21: P | H21: K2 | I21: 12.389 | J21: 12.389 | K21: 0 | L21: 0 | M21: N
A22: =+A21+1 -> 21 | B22: 18 | C22: 00 | D22: 068 | F22: SP. TUJOK - PANARAGAN JAYA | G22: P | H22: K2 | I22: 25.813 | J22: 25.813 | K22: 0 | L22: 0 | M22: P
A23: =+A22+1 -> 22 | B23: 18 | C23: 00 | D23: 069 | F23: PANARAGAN JAYA - SP. PANARAGAN | G23: P | H23: K2 | I23: 4.104 | J23: 4.104 | K23: 0 | L23: 0 | M23: P
A24: =+A23+1 -> 23 | B24: 18 | C24: 00 | D24: 085 | E24: 11K | F24: JALAN RAYA GUNUNG SAKTI (MENGGALA) | G24: P | H24: K2 | I24: 1.865 | J24: 1.865 | K24: 0 | L24: 0 | M24: N
A25: =+A24+1 -> 24 | B25: 18 | C25: 00 | D25: 086 | F25: BUJUNG TENUK - PENUMANGAN | G25: P | H25: K2 | I25: 12.432 | J25: 12.432 | K25: 0 | L25: 0 | M25: P
A26: =+A25+1 -> 25 | B26: 18 | C26: 00 | D26: 087 | F26: PENUMANGAN - TEGAL MUKTI | G26: P | H26: K2 | I26: 15.839 | J26: 15.839 | K26: 0 | L26: 0 | M26: P
A27: =+A26+1 -> 26 | B27: 18 | C27: 00 | D27: 090 | F27: ADIJAYA - TULUNG RANDU | G27: P | H27: K2 | I27: 38.13 | J27: 38.13 | K27: 0 | L27: 0 | M27: P
A28: =+A27+1 -> 27 | B28: 18 | C28: 00 | D28: 091 | F28: PENUMANGAN - UNIT VI | G28: P | H28: K2 | I28: 23.562 | J28: 23.562 | K28: 0 | L28: 0 | M28: P
A29: =+A28+1 -> 28 | B29: 18 | C29: 00 | D29: 092 | F29: SP. UNIT VIII - GEDONG AJI | G29: P | H29: K2 | I29: 22.05 | J29: 22.05 | K29: 0 | L29: 0 | M29: N
A30: =+A29+1 -> 29 | B30: 18 | C30: 00 | D30: 093 | F30: GEDONG AJI - UMBUL MESIR | G30: P | H30: K2 | I30: 31.5 | J30: 31.5 | K30: 0 | L30: 0 | M30: P
A31: =+A30+1 -> 30 | B31: 18 | C31: 00 | D31: 094 | F31: SP. PEMATANG - BRABASAN | G31: P | H31: K2 | I31: 11.602 | J31: 11.602 | K31: 0 | L31: 0 | M31: N
A32: =+A31+1 -> 31 | B32: 18 | C32: 00 | D32: 095 | F32: BRABASAN - WIRALAGA | G32: P | H32: K2 | I32: 29.443 | J32: 29.443 | K32: 0 | L32: 0 | M32: P

Sheet 1. Rekap Back Up Aspal
C2: PEMERINTAH PROVINSI LAMPUNG
C3: DINAS BINA MARGA DAN BINA KONSTRUKSI
B6: REKAPITULASI BACK - UP DATA SURVEY KONDISI JALAN (ASPAL)
B9: NO. RUAS | E9: : | F9: ='Link List'!D20 -> 064
B12: NAMA RUAS | E12: : | F12: ='Link List'!F20 -> BANDAR SAKTI - SP. DAYA MURNI
B15: PANJANG RUAS | E15: : | F15: ='Link List'!I20 -> 10.099
C18: STA | F18: NILAI TTI | G18: KONDISI 2024 | H18: KONDISI 2025 | I18: TIPE KERUSAKAN KONDISI JALAN ASPAL | U18: KET
C19: DARI (M) | D19: KE (M) | E19: LEBAR | I19: BLEEDING | J19: AGREGAT LEPAS | K19: DISINTEGRASI | L19: RETAK TURUN | M19: TAMBALAN | N19: RETAK LAIN | O19: JENIS RETAK | P19: LUBANG | Q19: TIPE LUBANG | R19: ALUR | S19: RUSAK TEPI (KIRI) | T19: RUSAK TEPI (KANAN)
B20: 1 | I20: 2 | J20: 3 | K20: 4 | L20: 5 | M20: 6 | N20: 7 | P20: 8 | R20: 9 | S20: 10 Ki | T20: 10 Ka | U20: 12
C21: 0 | D21: 100 | E21: 4.5 | F21: =(100/((D21-C21)*E21))*((I21*0.5)+(J21*0.5)+(K21*4)+(L21*4)+(M21*1)+(N21*2)+(P21*1.5)+(R21*1)+(S21*1)+(T21*1)) -> 27.361111 | G21: =IF(F21<=25,"B",IF(F21<=75,"S",IF(F21<=100,"RR","RB"))) -> S | I21: ='1. Back Up Aspal'!K28 -> 0 | J21: ='1. Back Up Aspal'!N28 -> 22.25 | K21: ='1. Back Up Aspal'!Q28 -> 18 | L21: ='1. Back Up Aspal'!T28 -> 10 | M21: ='1. Back Up Aspal'!W28 -> 0 | N21: ='1. Back Up Aspal'!Z28 -> 0 | O21: ='1. Back Up Aspal'!AA28 -> 1 | P21: ='1. Back Up Aspal'!AD28 -> 0 | Q21: ='1. Back Up Aspal'!AE28 -> 1 | R21: ='1. Back Up Aspal'!AH28 -> 0 | S21: ='1. Back Up Aspal'!AK28 -> 0 | T21: ='1. Back Up Aspal'!AN28 -> 0
C22: =D21 -> 100 | D22: =C22+100 -> 200 | E22: 4.5 | F22: =(100/((D22-C22)*E22))*((I22*0.5)+(J22*0.5)+(K22*4)+(L22*4)+(M22*1)+(N22*2)+(P22*1.5)+(R22*1)+(S22*1)+(T22*1)) -> 7.8333333 | G22: =IF(F22<=25,"B",IF(F22<=75,"S",IF(F22<=100,"RR","RB"))) -> B | I22: ='1. Back Up Aspal'!K36 -> 0 | J22: ='1. Back Up Aspal'!N36 -> 30.5 | K22: ='1. Back Up Aspal'!Q36 -> 0 | L22: ='1. Back Up Aspal'!T36 -> 5 | M22: ='1. Back Up Aspal'!W36 -> 0 | N22: ='1. Back Up Aspal'!Z36 -> 0 | O22: ='1. Back Up Aspal'!AA36 -> 1 | P22: ='1. Back Up Aspal'!AD36 -> 0 | Q22: ='1. Back Up Aspal'!AE36 -> 1 | R22: ='1. Back Up Aspal'!AH36 -> 0 | S22: ='1. Back Up Aspal'!AK36 -> 0 | T22: ='1. Back Up Aspal'!AN36 -> 0
C23: =D22 -> 200 | D23: =C23+100 -> 300 | E23: 4.5 | F23: =(100/((D23-C23)*E23))*((I23*0.5)+(J23*0.5)+(K23*4)+(L23*4)+(M23*1)+(N23*2)+(P23*1.5)+(R23*1)+(S23*1)+(T23*1)) -> 0.95138889 | G23: =IF(F23<=25,"B",IF(F23<=75,"S",IF(F23<=100,"RR","RB"))) -> B | I23: ='1. Back Up Aspal'!K44 -> 0 | J23: ='1. Back Up Aspal'!N44 -> 0.5625 | K23: ='1. Back Up Aspal'!Q44 -> 0 | L23: ='1. Back Up Aspal'!T44 -> 1 | M23: ='1. Back Up Aspal'!W44 -> 0 | N23: ='1. Back Up Aspal'!Z44 -> 0 | O23: ='1. Back Up Aspal'!AA44 -> 1 | P23: ='1. Back Up Aspal'!AD44 -> 0 | Q23: ='1. Back Up Aspal'!AE44 -> 1 | R23: ='1. Back Up Aspal'!AH44 -> 0 | S23: ='1. Back Up Aspal'!AK44 -> 0 | T23: ='1. Back Up Aspal'!AN44 -> 0
C24: =D23 -> 300 | D24: =C24+100 -> 400 | E24: 4.5 | F24: =(100/((D24-C24)*E24))*((I24*0.5)+(J24*0.5)+(K24*4)+(L24*4)+(M24*1)+(N24*2)+(P24*1.5)+(R24*1)+(S24*1)+(T24*1)) -> 21.888889 | G24: =IF(F24<=25,"B",IF(F24<=75,"S",IF(F24<=100,"RR","RB"))) -> B | I24: ='1. Back Up Aspal'!K52 -> 0 | J24: ='1. Back Up Aspal'!N52 -> 5 | K24: ='1. Back Up Aspal'!Q52 -> 9 | L24: ='1. Back Up Aspal'!T52 -> 11 | M24: ='1. Back Up Aspal'!W52 -> 0 | N24: ='1. Back Up Aspal'!Z52 -> 8 | O24: ='1. Back Up Aspal'!AA52 -> 2 | P24: ='1. Back Up Aspal'!AD52 -> 0 | Q24: ='1. Back Up Aspal'!AE52 -> 1 | R24: ='1. Back Up Aspal'!AH52 -> 0 | S24: ='1. Back Up Aspal'!AK52 -> 0 | T24: ='1. Back Up Aspal'!AN52 -> 0
C25: =D24 -> 400 | D25: =C25+100 -> 500 | E25: 4.5 | F25: =(100/((D25-C25)*E25))*((I25*0.5)+(J25*0.5)+(K25*4)+(L25*4)+(M25*1)+(N25*2)+(P25*1.5)+(R25*1)+(S25*1)+(T25*1)) -> 15.333333 | G25: =IF(F25<=25,"B",IF(F25<=75,"S",IF(F25<=100,"RR","RB"))) -> B | I25: ='1. Back Up Aspal'!K60 -> 0 | J25: ='1. Back Up Aspal'!N60 -> 8 | K25: ='1. Back Up Aspal'!Q60 -> 0 | L25: ='1. Back Up Aspal'!T60 -> 16 | M25: ='1. Back Up Aspal'!W60 -> 1 | N25: ='1. Back Up Aspal'!Z60 -> 0 | O25: ='1. Back Up Aspal'!AA60 -> 1 | P25: ='1. Back Up Aspal'!AD60 -> 0 | Q25: ='1. Back Up Aspal'!AE60 -> 1 | R25: ='1. Back Up Aspal'!AH60 -> 0 | S25: ='1. Back Up Aspal'!AK60 -> 0 | T25: ='1. Back Up Aspal'!AN60 -> 0
C26: =D25 -> 500 | D26: =C26+100 -> 600 | E26: 4.5 | F26: =(100/((D26-C26)*E26))*((I26*0.5)+(J26*0.5)+(K26*4)+(L26*4)+(M26*1)+(N26*2)+(P26*1.5)+(R26*1)+(S26*1)+(T26*1)) -> 2.2222222 | G26: =IF(F26<=25,"B",IF(F26<=75,"S",IF(F26<=100,"RR","RB"))) -> B | I26: ='1. Back Up Aspal'!K68 -> 0 | J26: ='1. Back Up Aspal'!N68 -> 20 | K26: ='1. Back Up Aspal'!Q68 -> 0 | L26: ='1. Back Up Aspal'!T68 -> 0 | M26: ='1. Back Up Aspal'!W68 -> 0 | N26: ='1. Back Up Aspal'!Z68 -> 0 | O26: ='1. Back Up Aspal'!AA68 -> 1 | P26: ='1. Back Up Aspal'!AD68 -> 0 | Q26: ='1. Back Up Aspal'!AE68 -> 1 | R26: ='1. Back Up Aspal'!AH68 -> 0 | S26: ='1. Back Up Aspal'!AK68 -> 0 | T26: ='1. Back Up Aspal'!AN68 -> 0
C27: =D26 -> 600 | D27: =C27+100 -> 700 | E27: 4.5 | F27: =(100/((D27-C27)*E27))*((I27*0.5)+(J27*0.5)+(K27*4)+(L27*4)+(M27*1)+(N27*2)+(P27*1.5)+(R27*1)+(S27*1)+(T27*1)) -> 0.027777778 | G27: =IF(F27<=25,"B",IF(F27<=75,"S",IF(F27<=100,"RR","RB"))) -> B | I27: ='1. Back Up Aspal'!K76 -> 0 | J27: ='1. Back Up Aspal'!N76 -> 0.25 | K27: ='1. Back Up Aspal'!Q76 -> 0 | L27: ='1. Back Up Aspal'!T76 -> 0 | M27: ='1. Back Up Aspal'!W76 -> 0 | N27: ='1. Back Up Aspal'!Z76 -> 0 | O27: ='1. Back Up Aspal'!AA76 -> 1 | P27: ='1. Back Up Aspal'!AD76 -> 0 | Q27: ='1. Back Up Aspal'!AE76 -> 1 | R27: ='1. Back Up Aspal'!AH76 -> 0 | S27: ='1. Back Up Aspal'!AK76 -> 0 | T27: ='1. Back Up Aspal'!AN76 -> 0
C28: =D27 -> 700 | D28: =C28+100 -> 800 | E28: 4.5 | F28: =(100/((D28-C28)*E28))*((I28*0.5)+(J28*0.5)+(K28*4)+(L28*4)+(M28*1)+(N28*2)+(P28*1.5)+(R28*1)+(S28*1)+(T28*1)) -> 0 | G28: =IF(F28<=25,"B",IF(F28<=75,"S",IF(F28<=100,"RR","RB"))) -> B | I28: ='1. Back Up Aspal'!K84 -> 0 | J28: ='1. Back Up Aspal'!N84 -> 0 | K28: ='1. Back Up Aspal'!Q84 -> 0 | L28: ='1. Back Up Aspal'!T84 -> 0 | M28: ='1. Back Up Aspal'!W84 -> 0 | N28: ='1. Back Up Aspal'!Z84 -> 0 | O28: ='1. Back Up Aspal'!AA84 -> 1 | P28: ='1. Back Up Aspal'!AD84 -> 0 | Q28: ='1. Back Up Aspal'!AE84 -> 1 | R28: ='1. Back Up Aspal'!AH84 -> 0 | S28: ='1. Back Up Aspal'!AK84 -> 0 | T28: ='1. Back Up Aspal'!AN84 -> 0
C29: =D28 -> 800 | D29: =C29+100 -> 900 | E29: 4.5 | F29: =(100/((D29-C29)*E29))*((I29*0.5)+(J29*0.5)+(K29*4)+(L29*4)+(M29*1)+(N29*2)+(P29*1.5)+(R29*1)+(S29*1)+(T29*1)) -> 0 | G29: =IF(F29<=25,"B",IF(F29<=75,"S",IF(F29<=100,"RR","RB"))) -> B | I29: ='1. Back Up Aspal'!K92 -> 0 | J29: ='1. Back Up Aspal'!N92 -> 0 | K29: ='1. Back Up Aspal'!Q92 -> 0 | L29: ='1. Back Up Aspal'!T92 -> 0 | M29: ='1. Back Up Aspal'!W92 -> 0 | N29: ='1. Back Up Aspal'!Z92 -> 0 | O29: ='1. Back Up Aspal'!AA92 -> 1 | P29: ='1. Back Up Aspal'!AD92 -> 0 | Q29: ='1. Back Up Aspal'!AE92 -> 1 | R29: ='1. Back Up Aspal'!AH92 -> 0 | S29: ='1. Back Up Aspal'!AK92 -> 0 | T29: ='1. Back Up Aspal'!AN92 -> 0
C30: =D29 -> 900 | D30: =C30+100 -> 1000 | E30: 4.5 | F30: =(100/((D30-C30)*E30))*((I30*0.5)+(J30*0.5)+(K30*4)+(L30*4)+(M30*1)+(N30*2)+(P30*1.5)+(R30*1)+(S30*1)+(T30*1)) -> 0 | G30: =IF(F30<=25,"B",IF(F30<=75,"S",IF(F30<=100,"RR","RB"))) -> B | I30: ='1. Back Up Aspal'!K100 -> 0 | J30: ='1. Back Up Aspal'!N100 -> 0 | K30: ='1. Back Up Aspal'!Q100 -> 0 | L30: ='1. Back Up Aspal'!T100 -> 0 | M30: ='1. Back Up Aspal'!W100 -> 0 | N30: ='1. Back Up Aspal'!Z100 -> 0 | O30: ='1. Back Up Aspal'!AA100 -> 1 | P30: ='1. Back Up Aspal'!AD100 -> 0 | Q30: ='1. Back Up Aspal'!AE100 -> 1 | R30: ='1. Back Up Aspal'!AH100 -> 0 | S30: ='1. Back Up Aspal'!AK100 -> 0 | T30: ='1. Back Up Aspal'!AN100 -> 0
C31: =D30 -> 1000 | D31: =C31+100 -> 1100 | E31: 4.5 | F31: =(100/((D31-C31)*E31))*((I31*0.5)+(J31*0.5)+(K31*4)+(L31*4)+(M31*1)+(N31*2)+(P31*1.5)+(R31*1)+(S31*1)+(T31*1)) -> 0 | G31: =IF(F31<=25,"B",IF(F31<=75,"S",IF(F31<=100,"RR","RB"))) -> B | I31: ='1. Back Up Aspal'!K108 -> 0 | J31: ='1. Back Up Aspal'!N108 -> 0 | K31: ='1. Back Up Aspal'!Q108 -> 0 | L31: ='1. Back Up Aspal'!T108 -> 0 | M31: ='1. Back Up Aspal'!W108 -> 0 | N31: ='1. Back Up Aspal'!Z108 -> 0 | O31: ='1. Back Up Aspal'!AA108 -> 1 | P31: ='1. Back Up Aspal'!AD108 -> 0 | Q31: ='1. Back Up Aspal'!AE108 -> 1 | R31: ='1. Back Up Aspal'!AH108 -> 0 | S31: ='1. Back Up Aspal'!AK108 -> 0 | T31: ='1. Back Up Aspal'!AN108 -> 0
C32: =D31 -> 1100 | D32: =C32+100 -> 1200 | E32: 4.5 | F32: =(100/((D32-C32)*E32))*((I32*0.5)+(J32*0.5)+(K32*4)+(L32*4)+(M32*1)+(N32*2)+(P32*1.5)+(R32*1)+(S32*1)+(T32*1)) -> 0 | G32: =IF(F32<=25,"B",IF(F32<=75,"S",IF(F32<=100,"RR","RB"))) -> B | I32: ='1. Back Up Aspal'!K116 -> 0 | J32: ='1. Back Up Aspal'!N116 -> 0 | K32: ='1. Back Up Aspal'!Q116 -> 0 | L32: ='1. Back Up Aspal'!T116 -> 0 | M32: ='1. Back Up Aspal'!W116 -> 0 | N32: ='1. Back Up Aspal'!Z116 -> 0 | O32: ='1. Back Up Aspal'!AA116 -> 1 | P32: ='1. Back Up Aspal'!AD116 -> 0 | Q32: ='1. Back Up Aspal'!AE116 -> 1 | R32: ='1. Back Up Aspal'!AH116 -> 0 | S32: ='1. Back Up Aspal'!AK116 -> 0 | T32: ='1. Back Up Aspal'!AN116 -> 0
C33: =D32 -> 1200 | D33: =C33+100 -> 1300 | E33: 4.5 | F33: =(100/((D33-C33)*E33))*((I33*0.5)+(J33*0.5)+(K33*4)+(L33*4)+(M33*1)+(N33*2)+(P33*1.5)+(R33*1)+(S33*1)+(T33*1)) -> 0 | G33: =IF(F33<=25,"B",IF(F33<=75,"S",IF(F33<=100,"RR","RB"))) -> B | I33: ='1. Back Up Aspal'!K124 -> 0 | J33: ='1. Back Up Aspal'!N124 -> 0 | K33: ='1. Back Up Aspal'!Q124 -> 0 | L33: ='1. Back Up Aspal'!T124 -> 0 | M33: ='1. Back Up Aspal'!W124 -> 0 | N33: ='1. Back Up Aspal'!Z124 -> 0 | O33: ='1. Back Up Aspal'!AA124 -> 1 | P33: ='1. Back Up Aspal'!AD124 -> 0 | Q33: ='1. Back Up Aspal'!AE124 -> 1 | R33: ='1. Back Up Aspal'!AH124 -> 0 | S33: ='1. Back Up Aspal'!AK124 -> 0 | T33: ='1. Back Up Aspal'!AN124 -> 0
C34: =D33 -> 1300 | D34: =C34+100 -> 1400 | E34: 4.5 | F34: =(100/((D34-C34)*E34))*((I34*0.5)+(J34*0.5)+(K34*4)+(L34*4)+(M34*1)+(N34*2)+(P34*1.5)+(R34*1)+(S34*1)+(T34*1)) -> 0 | G34: =IF(F34<=25,"B",IF(F34<=75,"S",IF(F34<=100,"RR","RB"))) -> B | I34: ='1. Back Up Aspal'!K132 -> 0 | J34: ='1. Back Up Aspal'!N132 -> 0 | K34: ='1. Back Up Aspal'!Q132 -> 0 | L34: ='1. Back Up Aspal'!T132 -> 0 | M34: ='1. Back Up Aspal'!W132 -> 0 | N34: ='1. Back Up Aspal'!Z132 -> 0 | O34: ='1. Back Up Aspal'!AA132 -> 1 | P34: ='1. Back Up Aspal'!AD132 -> 0 | Q34: ='1. Back Up Aspal'!AE132 -> 1 | R34: ='1. Back Up Aspal'!AH132 -> 0 | S34: ='1. Back Up Aspal'!AK132 -> 0 | T34: ='1. Back Up Aspal'!AN132 -> 0
C35: =D34 -> 1400 | D35: =C35+100 -> 1500 | E35: 4.5 | F35: =(100/((D35-C35)*E35))*((I35*0.5)+(J35*0.5)+(K35*4)+(L35*4)+(M35*1)+(N35*2)+(P35*1.5)+(R35*1)+(S35*1)+(T35*1)) -> 0 | G35: =IF(F35<=25,"B",IF(F35<=75,"S",IF(F35<=100,"RR","RB"))) -> B | I35: ='1. Back Up Aspal'!K140 -> 0 | J35: ='1. Back Up Aspal'!N140 -> 0 | K35: ='1. Back Up Aspal'!Q140 -> 0 | L35: ='1. Back Up Aspal'!T140 -> 0 | M35: ='1. Back Up Aspal'!W140 -> 0 | N35: ='1. Back Up Aspal'!Z140 -> 0 | O35: ='1. Back Up Aspal'!AA140 -> 1 | P35: ='1. Back Up Aspal'!AD140 -> 0 | Q35: ='1. Back Up Aspal'!AE140 -> 1 | R35: ='1. Back Up Aspal'!AH140 -> 0 | S35: ='1. Back Up Aspal'!AK140 -> 0 | T35: ='1. Back Up Aspal'!AN140 -> 0
C36: =D35 -> 1500 | D36: =C36+100 -> 1600 | E36: 4.5 | F36: =(100/((D36-C36)*E36))*((I36*0.5)+(J36*0.5)+(K36*4)+(L36*4)+(M36*1)+(N36*2)+(P36*1.5)+(R36*1)+(S36*1)+(T36*1)) -> 0 | G36: =IF(F36<=25,"B",IF(F36<=75,"S",IF(F36<=100,"RR","RB"))) -> B | I36: ='1. Back Up Aspal'!K148 -> 0 | J36: ='1. Back Up Aspal'!N148 -> 0 | K36: ='1. Back Up Aspal'!Q148 -> 0 | L36: ='1. Back Up Aspal'!T148 -> 0 | M36: ='1. Back Up Aspal'!W148 -> 0 | N36: ='1. Back Up Aspal'!Z148 -> 0 | O36: ='1. Back Up Aspal'!AA148 -> 1 | P36: ='1. Back Up Aspal'!AD148 -> 0 | Q36: ='1. Back Up Aspal'!AE148 -> 1 | R36: ='1. Back Up Aspal'!AH148 -> 0 | S36: ='1. Back Up Aspal'!AK148 -> 0 | T36: ='1. Back Up Aspal'!AN148 -> 0
C37: =D36 -> 1600 | D37: =C37+100 -> 1700 | E37: 4.5 | F37: =(100/((D37-C37)*E37))*((I37*0.5)+(J37*0.5)+(K37*4)+(L37*4)+(M37*1)+(N37*2)+(P37*1.5)+(R37*1)+(S37*1)+(T37*1)) -> 0 | G37: =IF(F37<=25,"B",IF(F37<=75,"S",IF(F37<=100,"RR","RB"))) -> B | I37: ='1. Back Up Aspal'!K156 -> 0 | J37: ='1. Back Up Aspal'!N156 -> 0 | K37: ='1. Back Up Aspal'!Q156 -> 0 | L37: ='1. Back Up Aspal'!T156 -> 0 | M37: ='1. Back Up Aspal'!W156 -> 0 | N37: ='1. Back Up Aspal'!Z156 -> 0 | O37: ='1. Back Up Aspal'!AA156 -> 1 | P37: ='1. Back Up Aspal'!AD156 -> 0 | Q37: ='1. Back Up Aspal'!AE156 -> 1 | R37: ='1. Back Up Aspal'!AH156 -> 0 | S37: ='1. Back Up Aspal'!AK156 -> 0 | T37: ='1. Back Up Aspal'!AN156 -> 0
C38: =D37 -> 1700 | D38: =C38+100 -> 1800 | E38: 4.5 | F38: =(100/((D38-C38)*E38))*((I38*0.5)+(J38*0.5)+(K38*4)+(L38*4)+(M38*1)+(N38*2)+(P38*1.5)+(R38*1)+(S38*1)+(T38*1)) -> 0 | G38: =IF(F38<=25,"B",IF(F38<=75,"S",IF(F38<=100,"RR","RB"))) -> B | I38: ='1. Back Up Aspal'!K164 -> 0 | J38: ='1. Back Up Aspal'!N164 -> 0 | K38: ='1. Back Up Aspal'!Q164 -> 0 | L38: ='1. Back Up Aspal'!T164 -> 0 | M38: ='1. Back Up Aspal'!W164 -> 0 | N38: ='1. Back Up Aspal'!Z164 -> 0 | O38: ='1. Back Up Aspal'!AA164 -> 1 | P38: ='1. Back Up Aspal'!AD164 -> 0 | Q38: ='1. Back Up Aspal'!AE164 -> 1 | R38: ='1. Back Up Aspal'!AH164 -> 0 | S38: ='1. Back Up Aspal'!AK164 -> 0 | T38: ='1. Back Up Aspal'!AN164 -> 0
C39: =D38 -> 1800 | D39: =C39+100 -> 1900 | E39: 6 | F39: =(100/((D39-C39)*E39))*((I39*0.5)+(J39*0.5)+(K39*4)+(L39*4)+(M39*1)+(N39*2)+(P39*1.5)+(R39*1)+(S39*1)+(T39*1)) -> 0 | G39: =IF(F39<=25,"B",IF(F39<=75,"S",IF(F39<=100,"RR","RB"))) -> B | I39: ='1. Back Up Aspal'!K172 -> 0 | J39: ='1. Back Up Aspal'!N172 -> 0 | K39: ='1. Back Up Aspal'!Q172 -> 0 | L39: ='1. Back Up Aspal'!T172 -> 0 | M39: ='1. Back Up Aspal'!W172 -> 0 | N39: ='1. Back Up Aspal'!Z172 -> 0 | O39: ='1. Back Up Aspal'!AA172 -> 1 | P39: ='1. Back Up Aspal'!AD172 -> 0 | Q39: ='1. Back Up Aspal'!AE172 -> 1 | R39: ='1. Back Up Aspal'!AH172 -> 0 | S39: ='1. Back Up Aspal'!AK172 -> 0 | T39: ='1. Back Up Aspal'!AN172 -> 0
C40: =D39 -> 1900 | D40: =C40+100 -> 2000 | E40: 6 | F40: =(100/((D40-C40)*E40))*((I40*0.5)+(J40*0.5)+(K40*4)+(L40*4)+(M40*1)+(N40*2)+(P40*1.5)+(R40*1)+(S40*1)+(T40*1)) -> 0 | G40: =IF(F40<=25,"B",IF(F40<=75,"S",IF(F40<=100,"RR","RB"))) -> B | I40: ='1. Back Up Aspal'!K180 -> 0 | J40: ='1. Back Up Aspal'!N180 -> 0 | K40: ='1. Back Up Aspal'!Q180 -> 0 | L40: ='1. Back Up Aspal'!T180 -> 0 | M40: ='1. Back Up Aspal'!W180 -> 0 | N40: ='1. Back Up Aspal'!Z180 -> 0 | O40: ='1. Back Up Aspal'!AA180 -> 1 | P40: ='1. Back Up Aspal'!AD180 -> 0 | Q40: ='1. Back Up Aspal'!AE180 -> 1 | R40: ='1. Back Up Aspal'!AH180 -> 0 | S40: ='1. Back Up Aspal'!AK180 -> 0 | T40: ='1. Back Up Aspal'!AN180 -> 0
C41: =D40 -> 2000 | D41: =C41+100 -> 2100 | E41: 6 | F41: =(100/((D41-C41)*E41))*((I41*0.5)+(J41*0.5)+(K41*4)+(L41*4)+(M41*1)+(N41*2)+(P41*1.5)+(R41*1)+(S41*1)+(T41*1)) -> 0 | G41: =IF(F41<=25,"B",IF(F41<=75,"S",IF(F41<=100,"RR","RB"))) -> B | I41: ='1. Back Up Aspal'!K188 -> 0 | J41: ='1. Back Up Aspal'!N188 -> 0 | K41: ='1. Back Up Aspal'!Q188 -> 0 | L41: ='1. Back Up Aspal'!T188 -> 0 | M41: ='1. Back Up Aspal'!W188 -> 0 | N41: ='1. Back Up Aspal'!Z188 -> 0 | O41: ='1. Back Up Aspal'!AA188 -> 1 | P41: ='1. Back Up Aspal'!AD188 -> 0 | Q41: ='1. Back Up Aspal'!AE188 -> 1 | R41: ='1. Back Up Aspal'!AH188 -> 0 | S41: ='1. Back Up Aspal'!AK188 -> 0 | T41: ='1. Back Up Aspal'!AN188 -> 0
C42: =D41 -> 2100 | D42: =C42+100 -> 2200 | E42: 6 | F42: =(100/((D42-C42)*E42))*((I42*0.5)+(J42*0.5)+(K42*4)+(L42*4)+(M42*1)+(N42*2)+(P42*1.5)+(R42*1)+(S42*1)+(T42*1)) -> 1.6666667 | G42: =IF(F42<=25,"B",IF(F42<=75,"S",IF(F42<=100,"RR","RB"))) -> B | I42: ='1. Back Up Aspal'!K196 -> 0 | J42: ='1. Back Up Aspal'!N196 -> 0 | K42: ='1. Back Up Aspal'!Q196 -> 0 | L42: ='1. Back Up Aspal'!T196 -> 0 | M42: ='1. Back Up Aspal'!W196 -> 10 | N42: ='1. Back Up Aspal'!Z196 -> 0 | O42: ='1. Back Up Aspal'!AA196 -> 1 | P42: ='1. Back Up Aspal'!AD196 -> 0 | Q42: ='1. Back Up Aspal'!AE196 -> 1 | R42: ='1. Back Up Aspal'!AH196 -> 0 | S42: ='1. Back Up Aspal'!AK196 -> 0 | T42: ='1. Back Up Aspal'!AN196 -> 0
C43: =D42 -> 2200 | D43: =C43+100 -> 2300 | E43: 6 | F43: =(100/((D43-C43)*E43))*((I43*0.5)+(J43*0.5)+(K43*4)+(L43*4)+(M43*1)+(N43*2)+(P43*1.5)+(R43*1)+(S43*1)+(T43*1)) -> 0 | G43: =IF(F43<=25,"B",IF(F43<=75,"S",IF(F43<=100,"RR","RB"))) -> B | I43: ='1. Back Up Aspal'!K204 -> 0 | J43: ='1. Back Up Aspal'!N204 -> 0 | K43: ='1. Back Up Aspal'!Q204 -> 0 | L43: ='1. Back Up Aspal'!T204 -> 0 | M43: ='1. Back Up Aspal'!W204 -> 0 | N43: ='1. Back Up Aspal'!Z204 -> 0 | O43: ='1. Back Up Aspal'!AA204 -> 1 | P43: ='1. Back Up Aspal'!AD204 -> 0 | Q43: ='1. Back Up Aspal'!AE204 -> 1 | R43: ='1. Back Up Aspal'!AH204 -> 0 | S43: ='1. Back Up Aspal'!AK204 -> 0 | T43: ='1. Back Up Aspal'!AN204 -> 0
C44: =D43 -> 2300 | D44: =C44+100 -> 2400 | E44: 6 | F44: =(100/((D44-C44)*E44))*((I44*0.5)+(J44*0.5)+(K44*4)+(L44*4)+(M44*1)+(N44*2)+(P44*1.5)+(R44*1)+(S44*1)+(T44*1)) -> 0 | G44: =IF(F44<=25,"B",IF(F44<=75,"S",IF(F44<=100,"RR","RB"))) -> B | I44: ='1. Back Up Aspal'!K212 -> 0 | J44: ='1. Back Up Aspal'!N212 -> 0 | K44: ='1. Back Up Aspal'!Q212 -> 0 | L44: ='1. Back Up Aspal'!T212 -> 0 | M44: ='1. Back Up Aspal'!W212 -> 0 | N44: ='1. Back Up Aspal'!Z212 -> 0 | O44: ='1. Back Up Aspal'!AA212 -> 1 | P44: ='1. Back Up Aspal'!AD212 -> 0 | Q44: ='1. Back Up Aspal'!AE212 -> 1 | R44: ='1. Back Up Aspal'!AH212 -> 0 | S44: ='1. Back Up Aspal'!AK212 -> 0 | T44: ='1. Back Up Aspal'!AN212 -> 0
C45: =D44 -> 2400 | D45: =C45+100 -> 2500 | E45: 6 | F45: =(100/((D45-C45)*E45))*((I45*0.5)+(J45*0.5)+(K45*4)+(L45*4)+(M45*1)+(N45*2)+(P45*1.5)+(R45*1)+(S45*1)+(T45*1)) -> 0 | G45: =IF(F45<=25,"B",IF(F45<=75,"S",IF(F45<=100,"RR","RB"))) -> B | I45: ='1. Back Up Aspal'!K220 -> 0 | J45: ='1. Back Up Aspal'!N220 -> 0 | K45: ='1. Back Up Aspal'!Q220 -> 0 | L45: ='1. Back Up Aspal'!T220 -> 0 | M45: ='1. Back Up Aspal'!W220 -> 0 | N45: ='1. Back Up Aspal'!Z220 -> 0 | O45: ='1. Back Up Aspal'!AA220 -> 1 | P45: ='1. Back Up Aspal'!AD220 -> 0 | Q45: ='1. Back Up Aspal'!AE220 -> 1 | R45: ='1. Back Up Aspal'!AH220 -> 0 | S45: ='1. Back Up Aspal'!AK220 -> 0 | T45: ='1. Back Up Aspal'!AN220 -> 0
C46: =D45 -> 2500 | D46: =C46+100 -> 2600 | E46: 6 | F46: =(100/((D46-C46)*E46))*((I46*0.5)+(J46*0.5)+(K46*4)+(L46*4)+(M46*1)+(N46*2)+(P46*1.5)+(R46*1)+(S46*1)+(T46*1)) -> 0.66666667 | G46: =IF(F46<=25,"B",IF(F46<=75,"S",IF(F46<=100,"RR","RB"))) -> B | I46: ='1. Back Up Aspal'!K228 -> 0 | J46: ='1. Back Up Aspal'!N228 -> 0 | K46: ='1. Back Up Aspal'!Q228 -> 0 | L46: ='1. Back Up Aspal'!T228 -> 0 | M46: ='1. Back Up Aspal'!W228 -> 4 | N46: ='1. Back Up Aspal'!Z228 -> 0 | O46: ='1. Back Up Aspal'!AA228 -> 1 | P46: ='1. Back Up Aspal'!AD228 -> 0 | Q46: ='1. Back Up Aspal'!AE228 -> 1 | R46: ='1. Back Up Aspal'!AH228 -> 0 | S46: ='1. Back Up Aspal'!AK228 -> 0 | T46: ='1. Back Up Aspal'!AN228 -> 0
C47: =D46 -> 2600 | D47: =C47+100 -> 2700 | E47: 6 | F47: =(100/((D47-C47)*E47))*((I47*0.5)+(J47*0.5)+(K47*4)+(L47*4)+(M47*1)+(N47*2)+(P47*1.5)+(R47*1)+(S47*1)+(T47*1)) -> 1.6666667 | G47: =IF(F47<=25,"B",IF(F47<=75,"S",IF(F47<=100,"RR","RB"))) -> B | I47: ='1. Back Up Aspal'!K236 -> 0 | J47: ='1. Back Up Aspal'!N236 -> 0 | K47: ='1. Back Up Aspal'!Q236 -> 0 | L47: ='1. Back Up Aspal'!T236 -> 0 | M47: ='1. Back Up Aspal'!W236 -> 10 | N47: ='1. Back Up Aspal'!Z236 -> 0 | O47: ='1. Back Up Aspal'!AA236 -> 1 | P47: ='1. Back Up Aspal'!AD236 -> 0 | Q47: ='1. Back Up Aspal'!AE236 -> 1 | R47: ='1. Back Up Aspal'!AH236 -> 0 | S47: ='1. Back Up Aspal'!AK236 -> 0 | T47: ='1. Back Up Aspal'!AN236 -> 0
C48: =D47 -> 2700 | D48: =C48+100 -> 2800 | E48: 6 | F48: =(100/((D48-C48)*E48))*((I48*0.5)+(J48*0.5)+(K48*4)+(L48*4)+(M48*1)+(N48*2)+(P48*1.5)+(R48*1)+(S48*1)+(T48*1)) -> 2.5 | G48: =IF(F48<=25,"B",IF(F48<=75,"S",IF(F48<=100,"RR","RB"))) -> B | I48: ='1. Back Up Aspal'!K244 -> 0 | J48: ='1. Back Up Aspal'!N244 -> 0 | K48: ='1. Back Up Aspal'!Q244 -> 0 | L48: ='1. Back Up Aspal'!T244 -> 0 | M48: ='1. Back Up Aspal'!W244 -> 15 | N48: ='1. Back Up Aspal'!Z244 -> 0 | O48: ='1. Back Up Aspal'!AA244 -> 1 | P48: ='1. Back Up Aspal'!AD244 -> 0 | Q48: ='1. Back Up Aspal'!AE244 -> 1 | R48: ='1. Back Up Aspal'!AH244 -> 0 | S48: ='1. Back Up Aspal'!AK244 -> 0 | T48: ='1. Back Up Aspal'!AN244 -> 0
C49: =D48 -> 2800 | D49: =C49+100 -> 2900 | E49: 6 | F49: =(100/((D49-C49)*E49))*((I49*0.5)+(J49*0.5)+(K49*4)+(L49*4)+(M49*1)+(N49*2)+(P49*1.5)+(R49*1)+(S49*1)+(T49*1)) -> 0.010416667 | G49: =IF(F49<=25,"B",IF(F49<=75,"S",IF(F49<=100,"RR","RB"))) -> B | I49: ='1. Back Up Aspal'!K252 -> 0 | J49: ='1. Back Up Aspal'!N252 -> 0 | K49: ='1. Back Up Aspal'!Q252 -> 0 | L49: ='1. Back Up Aspal'!T252 -> 0 | M49: ='1. Back Up Aspal'!W252 -> 0.0625 | N49: ='1. Back Up Aspal'!Z252 -> 0 | O49: ='1. Back Up Aspal'!AA252 -> 1 | P49: ='1. Back Up Aspal'!AD252 -> 0 | Q49: ='1. Back Up Aspal'!AE252 -> 1 | R49: ='1. Back Up Aspal'!AH252 -> 0 | S49: ='1. Back Up Aspal'!AK252 -> 0 | T49: ='1. Back Up Aspal'!AN252 -> 0
C50: =D49 -> 2900 | D50: =C50+100 -> 3000 | E50: 6 | F50: =(100/((D50-C50)*E50))*((I50*0.5)+(J50*0.5)+(K50*4)+(L50*4)+(M50*1)+(N50*2)+(P50*1.5)+(R50*1)+(S50*1)+(T50*1)) -> 0 | G50: =IF(F50<=25,"B",IF(F50<=75,"S",IF(F50<=100,"RR","RB"))) -> B | I50: ='1. Back Up Aspal'!K260 -> 0 | J50: ='1. Back Up Aspal'!N260 -> 0 | K50: ='1. Back Up Aspal'!Q260 -> 0 | L50: ='1. Back Up Aspal'!T260 -> 0 | M50: ='1. Back Up Aspal'!W260 -> 0 | N50: ='1. Back Up Aspal'!Z260 -> 0 | O50: ='1. Back Up Aspal'!AA260 -> 1 | P50: ='1. Back Up Aspal'!AD260 -> 0 | Q50: ='1. Back Up Aspal'!AE260 -> 1 | R50: ='1. Back Up Aspal'!AH260 -> 0 | S50: ='1. Back Up Aspal'!AK260 -> 0 | T50: ='1. Back Up Aspal'!AN260 -> 0
C51: =D50 -> 3000 | D51: =C51+100 -> 3100 | E51: 4.5 | F51: =(100/((D51-C51)*E51))*((I51*0.5)+(J51*0.5)+(K51*4)+(L51*4)+(M51*1)+(N51*2)+(P51*1.5)+(R51*1)+(S51*1)+(T51*1)) -> 9.7777778 | G51: =IF(F51<=25,"B",IF(F51<=75,"S",IF(F51<=100,"RR","RB"))) -> B | I51: ='1. Back Up Aspal'!K268 -> 0 | J51: ='1. Back Up Aspal'!N268 -> 0 | K51: ='1. Back Up Aspal'!Q268 -> 0 | L51: ='1. Back Up Aspal'!T268 -> 11 | M51: ='1. Back Up Aspal'!W268 -> 0 | N51: ='1. Back Up Aspal'!Z268 -> 0 | O51: ='1. Back Up Aspal'!AA268 -> 1 | P51: ='1. Back Up Aspal'!AD268 -> 0 | Q51: ='1. Back Up Aspal'!AE268 -> 1 | R51: ='1. Back Up Aspal'!AH268 -> 0 | S51: ='1. Back Up Aspal'!AK268 -> 0 | T51: ='1. Back Up Aspal'!AN268 -> 0
...

Sheet 1. Back Up Aspal
C2: PEMERINTAH PROVINSI LAMPUNG
C3: DINAS BINA MARGA DAN BINA KONSTRUKSI
B6: BACK - UP DATA SURVEY KONDISI JALAN (ASPAL)
B9: NO. RUAS | E9: : | F9: ='1. Rekap Back Up Aspal'!F9 -> 064
B12: NAMA RUAS | E12: : | F12: ='1. Rekap Back Up Aspal'!F12 -> BANDAR SAKTI - SP. DAYA MURNI
B15: PANJANG RUAS | E15: : | F15: ='1. Rekap Back Up Aspal'!F15 -> 10.099
C18: STA | F18: NILAI TTI | G18: KONDISI 2024 | H18: KONDISI 2025 | I18: TIPE KERUSAKAN KONDISI JALAN ASPAL | AO18: KET
C19: DARI (M) | D19: KE (M) | E19: LEBAR | I19: P | J19: L | K19: BLEEDING | L19: P | M19: L | N19: AGREGAT LEPAS | O19: P | P19: L | Q19: DISINTEGRASI | R19: P | S19: L | T19: RETAK TURUN | U19: P | V19: L | W19: TAMBALAN | X19: P | Y19: L | Z19: RETAK LAIN | AA19: JENIS RETAK | AB19: P | AC19: L | AD19: LUBANG | AE19: TIPE LUBANG | AF19: P | AG19: L | AH19: ALUR | AI19: P | AJ19: L | AK19: RUSAK TEPI (KIRI) | AL19: P | AM19: L | AN19: RUSAK TEPI (KANAN)
B20: 1 | I20: 2 | L20: 3 | O20: 4 | R20: 5 | X20: 7 | AB20: 8 | AF20: 9 | AI20: 10 | AL20: 11 | AO20: 12
C21: ='1. Rekap Back Up Aspal'!C21 -> 0 | D21: ='1. Rekap Back Up Aspal'!D21 -> 100 | E21: ='1. Rekap Back Up Aspal'!E21 -> 4.5 | F21: =(100/((D21-C21)*E21))*((K28*0.5)+(N28*0.5)+(Q28*4)+(T28*4)+(W28*1)+(Z28*2)+(AD28*1.5)+(AH28*1)+(AK28*1)+(AN28*1)) -> 27.361111 | G21: S | H21: =IF(F21<=25,"B",IF(F21<=75,"S",IF(F21<=100,"RR","RB"))) -> S | I21: 0 | J21: 0 | K21: =I21*J21 -> 0 | L21: 0.5 | M21: 0.5 | N21: =L21*M21 -> 0.25 | O21: 2 | P21: 1 | Q21: =O21*P21 -> 2 | R21: 5 | S21: 2 | T21: =R21*S21 -> 10 | U21: 0 | V21: 0 | W21: =U21*V21 -> 0 | X21: 0 | Y21: 0 | Z21: =X21*Y21 -> 0 | AA21: 1 | AB21: 0 | AC21: 0 | AD21: =AB21*AC21 -> 0 | AE21: 1 | AF21: 0 | AG21: 0 | AH21: =AF21*AG21 -> 0 | AI21: 0 | AJ21: 0 | AK21: =AI21*AJ21 -> 0 | AL21: 0 | AM21: 0 | AN21: =AL21*AM21 -> 0
I22: 0 | J22: 0 | K22: =I22*J22 -> 0 | L22: 15 | M22: 1 | N22: =L22*M22 -> 15 | O22: 8 | P22: 2 | Q22: =O22*P22 -> 16 | R22: 0 | S22: 0 | T22: =R22*S22 -> 0 | U22: 0 | V22: 0 | W22: =U22*V22 -> 0 | X22: 0 | Y22: 0 | Z22: =X22*Y22 -> 0 | AA22: 1 | AB22: 0 | AC22: 0 | AD22: =AB22*AC22 -> 0 | AE22: 1 | AF22: 0 | AG22: 0 | AH22: =AF22*AG22 -> 0 | AI22: 0 | AJ22: 0 | AK22: =AI22*AJ22 -> 0 | AL22: 0 | AM22: 0 | AN22: =AL22*AM22 -> 0
I23: 0 | J23: 0 | K23: =I23*J23 -> 0 | L23: 2 | M23: 1 | N23: =L23*M23 -> 2 | O23: 0 | P23: 0 | Q23: =O23*P23 -> 0 | R23: 0 | S23: 0 | T23: =R23*S23 -> 0 | U23: 0 | V23: 0 | W23: =U23*V23 -> 0 | X23: 0 | Y23: 0 | Z23: =X23*Y23 -> 0 | AA23: 1 | AB23: 0 | AC23: 0 | AD23: =AB23*AC23 -> 0 | AE23: 1 | AF23: 0 | AG23: 0 | AH23: =AF23*AG23 -> 0 | AI23: 0 | AJ23: 0 | AK23: =AI23*AJ23 -> 0 | AL23: 0 | AM23: 0 | AN23: =AL23*AM23 -> 0
I24: 0 | J24: 0 | K24: =I24*J24 -> 0 | L24: 4 | M24: 1 | N24: =L24*M24 -> 4 | O24: 0 | P24: 0 | Q24: =O24*P24 -> 0 | R24: 0 | S24: 0 | T24: =R24*S24 -> 0 | U24: 0 | V24: 0 | W24: =U24*V24 -> 0 | X24: 0 | Y24: 0 | Z24: =X24*Y24 -> 0 | AA24: 1 | AB24: 0 | AC24: 0 | AD24: =AB24*AC24 -> 0 | AE24: 1 | AF24: 0 | AG24: 0 | AH24: =AF24*AG24 -> 0 | AI24: 0 | AJ24: 0 | AK24: =AI24*AJ24 -> 0 | AL24: 0 | AM24: 0 | AN24: =AL24*AM24 -> 0
I25: 0 | J25: 0 | K25: =I25*J25 -> 0 | L25: 1 | M25: 1 | N25: =L25*M25 -> 1 | O25: 0 | P25: 0 | Q25: =O25*P25 -> 0 | R25: 0 | S25: 0 | T25: =R25*S25 -> 0 | U25: 0 | V25: 0 | W25: =U25*V25 -> 0 | X25: 0 | Y25: 0 | Z25: =X25*Y25 -> 0 | AA25: 1 | AB25: 0 | AC25: 0 | AD25: =AB25*AC25 -> 0 | AE25: 1 | AF25: 0 | AG25: 0 | AH25: =AF25*AG25 -> 0 | AI25: 0 | AJ25: 0 | AK25: =AI25*AJ25 -> 0 | AL25: 0 | AM25: 0 | AN25: =AL25*AM25 -> 0
I26: 0 | J26: 0 | K26: =I26*J26 -> 0 | L26: 0 | M26: 0 | N26: =L26*M26 -> 0 | O26: 0 | P26: 0 | Q26: =O26*P26 -> 0 | R26: 0 | S26: 0 | T26: =R26*S26 -> 0 | U26: 0 | V26: 0 | W26: =U26*V26 -> 0 | X26: 0 | Y26: 0 | Z26: =X26*Y26 -> 0 | AA26: 1 | AB26: 0 | AC26: 0 | AD26: =AB26*AC26 -> 0 | AE26: 1 | AF26: 0 | AG26: 0 | AH26: =AF26*AG26 -> 0 | AI26: 0 | AJ26: 0 | AK26: =AI26*AJ26 -> 0 | AL26: 0 | AM26: 0 | AN26: =AL26*AM26 -> 0
I27: 0 | J27: 0 | K27: =I27*J27 -> 0 | L27: 0 | M27: 0 | N27: =L27*M27 -> 0 | O27: 0 | P27: 0 | Q27: =O27*P27 -> 0 | R27: 0 | S27: 0 | T27: =R27*S27 -> 0 | U27: 0 | V27: 0 | W27: =U27*V27 -> 0 | X27: 0 | Y27: 0 | Z27: =X27*Y27 -> 0 | AA27: 1 | AB27: 0 | AC27: 0 | AD27: =AB27*AC27 -> 0 | AE27: 1 | AF27: 0 | AG27: 0 | AH27: =AF27*AG27 -> 0 | AI27: 0 | AJ27: 0 | AK27: =AI27*AJ27 -> 0 | AL27: 0 | AM27: 0 | AN27: =AL27*AM27 -> 0
I28: Total | K28: =SUM(K21:K27) -> 0 | L28: Total | N28: =SUM(N21:N27) -> 22.25 | O28: Total | Q28: =SUM(Q21:Q27) -> 18 | R28: Total | T28: =SUM(T21:T27) -> 10 | U28: Total | W28: =SUM(W21:W27) -> 0 | X28: Total | Z28: =SUM(Z21:Z27) -> 0 | AA28: 1 | AB28: Total | AD28: =SUM(AD21:AD27) -> 0 | AE28: 1 | AF28: Total | AH28: =SUM(AH21:AH27) -> 0 | AI28: Total | AK28: =SUM(AK21:AK27) -> 0 | AL28: Total | AN28: =SUM(AN21:AN27) -> 0
C29: ='1. Rekap Back Up Aspal'!C22 -> 100 | D29: ='1. Rekap Back Up Aspal'!D22 -> 200 | E29: ='1. Rekap Back Up Aspal'!E22 -> 4.5 | F29: =(100/((D29-C29)*E29))*((K36*0.5)+(N36*0.5)+(Q36*4)+(T36*4)+(W36*1)+(Z36*2)+(AD36*1.5)+(AH36*1)+(AK36*1)+(AN36*1)) -> 7.8333333 | G29: B | H29: =IF(F29<=25,"B",IF(F29<=75,"S",IF(F29<=100,"RR","RB"))) -> B | I29: 0 | J29: 0 | K29: =I29*J29 -> 0 | L29: 15 | M29: 2 | N29: =L29*M29 -> 30 | O29: 0 | P29: 0 | Q29: =O29*P29 -> 0 | R29: 5 | S29: 1 | T29: =R29*S29 -> 5 | U29: 0 | V29: 0 | W29: =U29*V29 -> 0 | X29: 0 | Y29: 0 | Z29: =X29*Y29 -> 0 | AA29: 1 | AB29: 0 | AC29: 0 | AD29: =AB29*AC29 -> 0 | AE29: 1 | AF29: 0 | AG29: 0 | AH29: =AF29*AG29 -> 0 | AI29: 0 | AJ29: 0 | AK29: =AI29*AJ29 -> 0 | AL29: 0 | AM29: 0 | AN29: =AL29*AM29 -> 0
I30: 0 | J30: 0 | K30: =I30*J30 -> 0 | L30: 1 | M30: 0.5 | N30: =L30*M30 -> 0.5 | O30: 0 | P30: 0 | Q30: =O30*P30 -> 0 | R30: 0 | S30: 0 | T30: =R30*S30 -> 0 | U30: 0 | V30: 0 | W30: =U30*V30 -> 0 | X30: 0 | Y30: 0 | Z30: =X30*Y30 -> 0 | AA30: 1 | AB30: 0 | AC30: 0 | AD30: =AB30*AC30 -> 0 | AE30: 1 | AF30: 0 | AG30: 0 | AH30: =AF30*AG30 -> 0 | AI30: 0 | AJ30: 0 | AK30: =AI30*AJ30 -> 0 | AL30: 0 | AM30: 0 | AN30: =AL30*AM30 -> 0
I31: 0 | J31: 0 | K31: =I31*J31 -> 0 | L31: 0 | M31: 0 | N31: =L31*M31 -> 0 | O31: 0 | P31: 0 | Q31: =O31*P31 -> 0 | R31: 0 | S31: 0 | T31: =R31*S31 -> 0 | U31: 0 | V31: 0 | W31: =U31*V31 -> 0 | X31: 0 | Y31: 0 | Z31: =X31*Y31 -> 0 | AA31: 1 | AB31: 0 | AC31: 0 | AD31: =AB31*AC31 -> 0 | AE31: 1 | AF31: 0 | AG31: 0 | AH31: =AF31*AG31 -> 0 | AI31: 0 | AJ31: 0 | AK31: =AI31*AJ31 -> 0 | AL31: 0 | AM31: 0 | AN31: =AL31*AM31 -> 0
I32: 0 | J32: 0 | K32: =I32*J32 -> 0 | L32: 0 | M32: 0 | N32: =L32*M32 -> 0 | O32: 0 | P32: 0 | Q32: =O32*P32 -> 0 | R32: 0 | S32: 0 | T32: =R32*S32 -> 0 | U32: 0 | V32: 0 | W32: =U32*V32 -> 0 | X32: 0 | Y32: 0 | Z32: =X32*Y32 -> 0 | AA32: 1 | AB32: 0 | AC32: 0 | AD32: =AB32*AC32 -> 0 | AE32: 1 | AF32: 0 | AG32: 0 | AH32: =AF32*AG32 -> 0 | AI32: 0 | AJ32: 0 | AK32: =AI32*AJ32 -> 0 | AL32: 0 | AM32: 0 | AN32: =AL32*AM32 -> 0
I33: 0 | J33: 0 | K33: =I33*J33 -> 0 | L33: 0 | M33: 0 | N33: =L33*M33 -> 0 | O33: 0 | P33: 0 | Q33: =O33*P33 -> 0 | R33: 0 | S33: 0 | T33: =R33*S33 -> 0 | U33: 0 | V33: 0 | W33: =U33*V33 -> 0 | X33: 0 | Y33: 0 | Z33: =X33*Y33 -> 0 | AA33: 1 | AB33: 0 | AC33: 0 | AD33: =AB33*AC33 -> 0 | AE33: 1 | AF33: 0 | AG33: 0 | AH33: =AF33*AG33 -> 0 | AI33: 0 | AJ33: 0 | AK33: =AI33*AJ33 -> 0 | AL33: 0 | AM33: 0 | AN33: =AL33*AM33 -> 0
I34: 0 | J34: 0 | K34: =I34*J34 -> 0 | L34: 0 | M34: 0 | N34: =L34*M34 -> 0 | O34: 0 | P34: 0 | Q34: =O34*P34 -> 0 | R34: 0 | S34: 0 | T34: =R34*S34 -> 0 | U34: 0 | V34: 0 | W34: =U34*V34 -> 0 | X34: 0 | Y34: 0 | Z34: =X34*Y34 -> 0 | AA34: 1 | AB34: 0 | AC34: 0 | AD34: =AB34*AC34 -> 0 | AE34: 1 | AF34: 0 | AG34: 0 | AH34: =AF34*AG34 -> 0 | AI34: 0 | AJ34: 0 | AK34: =AI34*AJ34 -> 0 | AL34: 0 | AM34: 0 | AN34: =AL34*AM34 -> 0
I35: 0 | J35: 0 | K35: =I35*J35 -> 0 | L35: 0 | M35: 0 | N35: =L35*M35 -> 0 | O35: 0 | P35: 0 | Q35: =O35*P35 -> 0 | R35: 0 | S35: 0 | T35: =R35*S35 -> 0 | U35: 0 | V35: 0 | W35: =U35*V35 -> 0 | X35: 0 | Y35: 0 | Z35: =X35*Y35 -> 0 | AA35: 1 | AB35: 0 | AC35: 0 | AD35: =AB35*AC35 -> 0 | AE35: 1 | AF35: 0 | AG35: 0 | AH35: =AF35*AG35 -> 0 | AI35: 0 | AJ35: 0 | AK35: =AI35*AJ35 -> 0 | AL35: 0 | AM35: 0 | AN35: =AL35*AM35 -> 0
I36: Total | K36: =SUM(K29:K35) -> 0 | L36: Total | N36: =SUM(N29:N35) -> 30.5 | O36: Total | Q36: =SUM(Q29:Q35) -> 0 | R36: Total | T36: =SUM(T29:T35) -> 5 | U36: Total | W36: =SUM(W29:W35) -> 0 | X36: Total | Z36: =SUM(Z29:Z35) -> 0 | AA36: 1 | AB36: Total | AD36: =SUM(AD29:AD35) -> 0 | AE36: 1 | AF36: Total | AH36: =SUM(AH29:AH35) -> 0 | AI36: Total | AK36: =SUM(AK29:AK35) -> 0 | AL36: Total | AN36: =SUM(AN29:AN35) -> 0
C37: ='1. Rekap Back Up Aspal'!C23 -> 200 | D37: ='1. Rekap Back Up Aspal'!D23 -> 300 | E37: ='1. Rekap Back Up Aspal'!E23 -> 4.5 | F37: =(100/((D37-C37)*E37))*((K44*0.5)+(N44*0.5)+(Q44*4)+(T44*4)+(W44*1)+(Z44*2)+(AD44*1.5)+(AH44*1)+(AK44*1)+(AN44*1)) -> 0.95138889 | G37: B | H37: =IF(F37<=25,"B",IF(F37<=75,"S",IF(F37<=100,"RR","RB"))) -> B | I37: 0 | J37: 0 | K37: =I37*J37 -> 0 | L37: 1 | M37: 0.5 | N37: =L37*M37 -> 0.5 | O37: 0 | P37: 0 | Q37: =O37*P37 -> 0 | R37: 1 | S37: 1 | T37: =R37*S37 -> 1 | U37: 0 | V37: 0 | W37: =U37*V37 -> 0 | X37: 0 | Y37: 0 | Z37: =X37*Y37 -> 0 | AA37: 1 | AB37: 0 | AC37: 0 | AD37: =AB37*AC37 -> 0 | AE37: 1 | AF37: 0 | AG37: 0 | AH37: =AF37*AG37 -> 0 | AI37: 0 | AJ37: 0 | AK37: =AI37*AJ37 -> 0 | AL37: 0 | AM37: 0 | AN37: =AL37*AM37 -> 0
I38: 0 | J38: 0 | K38: =I38*J38 -> 0 | L38: 0.25 | M38: 0.25 | N38: =L38*M38 -> 0.0625 | O38: 0 | P38: 0 | Q38: =O38*P38 -> 0 | R38: 0 | S38: 0 | T38: =R38*S38 -> 0 | U38: 0 | V38: 0 | W38: =U38*V38 -> 0 | X38: 0 | Y38: 0 | Z38: =X38*Y38 -> 0 | AA38: 1 | AB38: 0 | AC38: 0 | AD38: =AB38*AC38 -> 0 | AE38: 1 | AF38: 0 | AG38: 0 | AH38: =AF38*AG38 -> 0 | AI38: 0 | AJ38: 0 | AK38: =AI38*AJ38 -> 0 | AL38: 0 | AM38: 0 | AN38: =AL38*AM38 -> 0
I39: 0 | J39: 0 | K39: =I39*J39 -> 0 | L39: 0 | M39: 0 | N39: =L39*M39 -> 0 | O39: 0 | P39: 0 | Q39: =O39*P39 -> 0 | R39: 0 | S39: 0 | T39: =R39*S39 -> 0 | U39: 0 | V39: 0 | W39: =U39*V39 -> 0 | X39: 0 | Y39: 0 | Z39: =X39*Y39 -> 0 | AA39: 1 | AB39: 0 | AC39: 0 | AD39: =AB39*AC39 -> 0 | AE39: 1 | AF39: 0 | AG39: 0 | AH39: =AF39*AG39 -> 0 | AI39: 0 | AJ39: 0 | AK39: =AI39*AJ39 -> 0 | AL39: 0 | AM39: 0 | AN39: =AL39*AM39 -> 0
I40: 0 | J40: 0 | K40: =I40*J40 -> 0 | L40: 0 | M40: 0 | N40: =L40*M40 -> 0 | O40: 0 | P40: 0 | Q40: =O40*P40 -> 0 | R40: 0 | S40: 0 | T40: =R40*S40 -> 0 | U40: 0 | V40: 0 | W40: =U40*V40 -> 0 | X40: 0 | Y40: 0 | Z40: =X40*Y40 -> 0 | AA40: 1 | AB40: 0 | AC40: 0 | AD40: =AB40*AC40 -> 0 | AE40: 1 | AF40: 0 | AG40: 0 | AH40: =AF40*AG40 -> 0 | AI40: 0 | AJ40: 0 | AK40: =AI40*AJ40 -> 0 | AL40: 0 | AM40: 0 | AN40: =AL40*AM40 -> 0
I41: 0 | J41: 0 | K41: =I41*J41 -> 0 | L41: 0 | M41: 0 | N41: =L41*M41 -> 0 | O41: 0 | P41: 0 | Q41: =O41*P41 -> 0 | R41: 0 | S41: 0 | T41: =R41*S41 -> 0 | U41: 0 | V41: 0 | W41: =U41*V41 -> 0 | X41: 0 | Y41: 0 | Z41: =X41*Y41 -> 0 | AA41: 1 | AB41: 0 | AC41: 0 | AD41: =AB41*AC41 -> 0 | AE41: 1 | AF41: 0 | AG41: 0 | AH41: =AF41*AG41 -> 0 | AI41: 0 | AJ41: 0 | AK41: =AI41*AJ41 -> 0 | AL41: 0 | AM41: 0 | AN41: =AL41*AM41 -> 0
I42: 0 | J42: 0 | K42: =I42*J42 -> 0 | L42: 0 | M42: 0 | N42: =L42*M42 -> 0 | O42: 0 | P42: 0 | Q42: =O42*P42 -> 0 | R42: 0 | S42: 0 | T42: =R42*S42 -> 0 | U42: 0 | V42: 0 | W42: =U42*V42 -> 0 | X42: 0 | Y42: 0 | Z42: =X42*Y42 -> 0 | AA42: 1 | AB42: 0 | AC42: 0 | AD42: =AB42*AC42 -> 0 | AE42: 1 | AF42: 0 | AG42: 0 | AH42: =AF42*AG42 -> 0 | AI42: 0 | AJ42: 0 | AK42: =AI42*AJ42 -> 0 | AL42: 0 | AM42: 0 | AN42: =AL42*AM42 -> 0
I43: 0 | J43: 0 | K43: =I43*J43 -> 0 | L43: 0 | M43: 0 | N43: =L43*M43 -> 0 | O43: 0 | P43: 0 | Q43: =O43*P43 -> 0 | R43: 0 | S43: 0 | T43: =R43*S43 -> 0 | U43: 0 | V43: 0 | W43: =U43*V43 -> 0 | X43: 0 | Y43: 0 | Z43: =X43*Y43 -> 0 | AA43: 1 | AB43: 0 | AC43: 0 | AD43: =AB43*AC43 -> 0 | AE43: 1 | AF43: 0 | AG43: 0 | AH43: =AF43*AG43 -> 0 | AI43: 0 | AJ43: 0 | AK43: =AI43*AJ43 -> 0 | AL43: 0 | AM43: 0 | AN43: =AL43*AM43 -> 0
I44: Total | K44: =SUM(K37:K43) -> 0 | L44: Total | N44: =SUM(N37:N43) -> 0.5625 | O44: Total | Q44: =SUM(Q37:Q43) -> 0 | R44: Total | T44: =SUM(T37:T43) -> 1 | U44: Total | W44: =SUM(W37:W43) -> 0 | X44: Total | Z44: =SUM(Z37:Z43) -> 0 | AA44: 1 | AB44: Total | AD44: =SUM(AD37:AD43) -> 0 | AE44: 1 | AF44: Total | AH44: =SUM(AH37:AH43) -> 0 | AI44: Total | AK44: =SUM(AK37:AK43) -> 0 | AL44: Total | AN44: =SUM(AN37:AN43) -> 0
C45: ='1. Rekap Back Up Aspal'!C24 -> 300 | D45: ='1. Rekap Back Up Aspal'!D24 -> 400 | E45: ='1. Rekap Back Up Aspal'!E24 -> 4.5 | F45: =(100/((D45-C45)*E45))*((K52*0.5)+(N52*0.5)+(Q52*4)+(T52*4)+(W52*1)+(Z52*2)+(AD52*1.5)+(AH52*1)+(AK52*1)+(AN52*1)) -> 21.888889 | G45: B | H45: =IF(F45<=25,"B",IF(F45<=75,"S",IF(F45<=100,"RR","RB"))) -> B | I45: 0 | J45: 0 | K45: =I45*J45 -> 0 | L45: 1 | M45: 1 | N45: =L45*M45 -> 1 | O45: 3 | P45: 3 | Q45: =O45*P45 -> 9 | R45: 3 | S45: 3 | T45: =R45*S45 -> 9 | U45: 0 | V45: 0 | W45: =U45*V45 -> 0 | X45: 3 | Y45: 1 | Z45: =X45*Y45 -> 3 | AA45: 2 | AB45: 0 | AC45: 0 | AD45: =AB45*AC45 -> 0 | AE45: 1 | AF45: 0 | AG45: 0 | AH45: =AF45*AG45 -> 0 | AI45: 0 | AJ45: 0 | AK45: =AI45*AJ45 -> 0 | AL45: 0 | AM45: 0 | AN45: =AL45*AM45 -> 0
I46: 0 | J46: 0 | K46: =I46*J46 -> 0 | L46: 4 | M46: 1 | N46: =L46*M46 -> 4 | O46: 0 | P46: 0 | Q46: =O46*P46 -> 0 | R46: 1 | S46: 2 | T46: =R46*S46 -> 2 | U46: 0 | V46: 0 | W46: =U46*V46 -> 0 | X46: 5 | Y46: 1 | Z46: =X46*Y46 -> 5 | AA46: 2 | AB46: 0 | AC46: 0 | AD46: =AB46*AC46 -> 0 | AE46: 1 | AF46: 0 | AG46: 0 | AH46: =AF46*AG46 -> 0 | AI46: 0 | AJ46: 0 | AK46: =AI46*AJ46 -> 0 | AL46: 0 | AM46: 0 | AN46: =AL46*AM46 -> 0
I47: 0 | J47: 0 | K47: =I47*J47 -> 0 | L47: 0 | M47: 0 | N47: =L47*M47 -> 0 | O47: 0 | P47: 0 | Q47: =O47*P47 -> 0 | R47: 0 | S47: 0 | T47: =R47*S47 -> 0 | U47: 0 | V47: 0 | W47: =U47*V47 -> 0 | X47: 0 | Y47: 0 | Z47: =X47*Y47 -> 0 | AA47: 1 | AB47: 0 | AC47: 0 | AD47: =AB47*AC47 -> 0 | AE47: 1 | AF47: 0 | AG47: 0 | AH47: =AF47*AG47 -> 0 | AI47: 0 | AJ47: 0 | AK47: =AI47*AJ47 -> 0 | AL47: 0 | AM47: 0 | AN47: =AL47*AM47 -> 0
I48: 0 | J48: 0 | K48: =I48*J48 -> 0 | L48: 0 | M48: 0 | N48: =L48*M48 -> 0 | O48: 0 | P48: 0 | Q48: =O48*P48 -> 0 | R48: 0 | S48: 0 | T48: =R48*S48 -> 0 | U48: 0 | V48: 0 | W48: =U48*V48 -> 0 | X48: 0 | Y48: 0 | Z48: =X48*Y48 -> 0 | AA48: 1 | AB48: 0 | AC48: 0 | AD48: =AB48*AC48 -> 0 | AE48: 1 | AF48: 0 | AG48: 0 | AH48: =AF48*AG48 -> 0 | AI48: 0 | AJ48: 0 | AK48: =AI48*AJ48 -> 0 | AL48: 0 | AM48: 0 | AN48: =AL48*AM48 -> 0
I49: 0 | J49: 0 | K49: =I49*J49 -> 0 | L49: 0 | M49: 0 | N49: =L49*M49 -> 0 | O49: 0 | P49: 0 | Q49: =O49*P49 -> 0 | R49: 0 | S49: 0 | T49: =R49*S49 -> 0 | U49: 0 | V49: 0 | W49: =U49*V49 -> 0 | X49: 0 | Y49: 0 | Z49: =X49*Y49 -> 0 | AA49: 1 | AB49: 0 | AC49: 0 | AD49: =AB49*AC49 -> 0 | AE49: 1 | AF49: 0 | AG49: 0 | AH49: =AF49*AG49 -> 0 | AI49: 0 | AJ49: 0 | AK49: =AI49*AJ49 -> 0 | AL49: 0 | AM49: 0 | AN49: =AL49*AM49 -> 0
I50: 0 | J50: 0 | K50: =I50*J50 -> 0 | L50: 0 | M50: 0 | N50: =L50*M50 -> 0 | O50: 0 | P50: 0 | Q50: =O50*P50 -> 0 | R50: 0 | S50: 0 | T50: =R50*S50 -> 0 | U50: 0 | V50: 0 | W50: =U50*V50 -> 0 | X50: 0 | Y50: 0 | Z50: =X50*Y50 -> 0 | AA50: 1 | AB50: 0 | AC50: 0 | AD50: =AB50*AC50 -> 0 | AE50: 1 | AF50: 0 | AG50: 0 | AH50: =AF50*AG50 -> 0 | AI50: 0 | AJ50: 0 | AK50: =AI50*AJ50 -> 0 | AL50: 0 | AM50: 0 | AN50: =AL50*AM50 -> 0
I51: 0 | J51: 0 | K51: =I51*J51 -> 0 | L51: 0 | M51: 0 | N51: =L51*M51 -> 0 | O51: 0 | P51: 0 | Q51: =O51*P51 -> 0 | R51: 0 | S51: 0 | T51: =R51*S51 -> 0 | U51: 0 | V51: 0 | W51: =U51*V51 -> 0 | X51: 0 | Y51: 0 | Z51: =X51*Y51 -> 0 | AA51: 1 | AB51: 0 | AC51: 0 | AD51: =AB51*AC51 -> 0 | AE51: 1 | AF51: 0 | AG51: 0 | AH51: =AF51*AG51 -> 0 | AI51: 0 | AJ51: 0 | AK51: =AI51*AJ51 -> 0 | AL51: 0 | AM51: 0 | AN51: =AL51*AM51 -> 0
...

Sheet 1. Back Up Aspal L
C2: PEMERINTAH PROVINSI LAMPUNG
C3: DINAS BINA MARGA DAN BINA KONSTRUKSI
B6: BACK - UP DATA SURVEY KONDISI JALAN (ASPAL)
B9: NO. RUAS | E9: : | F9: =+'[1]Link List'!D20 -> 064
B12: NAMA RUAS | E12: : | F12: =+'[1]Link List'!F20 -> BANDAR SAKTI - SP. DAYA MURNI
B15: PANJANG RUAS | E15: : | F15: =+'[1]Link List'!I20 -> 10.099
B18: STA | G18: ASPAL | AQ18: KET
B19: AWAL | E19: AKHIR | G19: TIPE KERUSAKAN | H19: P | I19: L | J19: JML | K19: TIPE KERUSAKAN | L19: P | M19: L | N19: JML | O19: =+K19 -> TIPE KERUSAKAN | P19: P | Q19: L | R19: JML | S19: TIPE KERUSAKAN | T19: P | U19: L | V19: JML | W19: =+S19 -> TIPE KERUSAKAN | X19: P | Y19: L | Z19: JML | AA19: TIPE KERUSAKAN | AB19: P | AC19: L | AD19: JML | AE19: =+AA19 -> TIPE KERUSAKAN | AF19: P | AG19: L | AH19: JML | AI19: TIPE KERUSAKAN | AJ19: P | AK19: L | AL19: JML | AM19: =+AI19 -> TIPE KERUSAKAN | AN19: P | AO19: L | AP19: JML
C21: 0 | D21: s/d | E21: =+C21+100 -> 100 | G21: Kegemukan | H21: 0 | I21: 0 | J21: =+H21*I21 -> 0 | K21: Agregat Lepas | L21: 20 | M21: 2.5 | N21: =+L21*M21 -> 50 | O21: Disintegrasi | P21: 15 | Q21: 3.5 | R21: =+P21*Q21 -> 52.5 | S21: Retak Lain | T21: 0 | U21: 0 | V21: =+T21*U21 -> 0 | W21: Retak Turun | X21: 5 | Y21: 2 | Z21: =+X21*Y21 -> 10 | AA21: Tambalan | AB21: 0 | AC21: 0 | AD21: =+AB21*AC21 -> 0 | AE21: Lubang | AF21: 0 | AG21: 0 | AH21: =+AF21*AG21 -> 0 | AI21: Alur | AJ21: 0 | AK21: 0 | AL21: =+AJ21*AK21 -> 0 | AM21: Rusak Tepi | AN21: 0 | AO21: 0 | AP21: =+AN21*AO21 -> 0
C29: =+E21 -> 100 | D29: s/d | E29: =+C29+100 -> 200 | G29: Kegemukan | H29: 0 | I29: 0 | J29: =+H29*I29 -> 0 | K29: Agregat Lepas | L29: 10 | M29: 2.5 | N29: =+L29*M29 -> 25 | O29: Disintegrasi | P29: 0 | Q29: 0 | R29: =+P29*Q29 -> 0 | S29: Retak Lain | T29: 0 | U29: 0 | V29: =+T29*U29 -> 0 | W29: Retak Turun | X29: 0 | Y29: 0 | Z29: =+X29*Y29 -> 0 | AA29: Tambalan | AB29: 0 | AC29: 0 | AD29: =+AB29*AC29 -> 0 | AE29: Lubang | AF29: 0 | AG29: 0 | AH29: =+AF29*AG29 -> 0 | AI29: Alur | AJ29: 0 | AK29: 0 | AL29: =+AJ29*AK29 -> 0 | AM29: Rusak Tepi | AN29: 0 | AO29: 0 | AP29: =+AN29*AO29 -> 0
C37: =+E29 -> 200 | D37: s/d | E37: =+C37+100 -> 300 | G37: Kegemukan | H37: 0 | I37: 0 | J37: =+H37*I37 -> 0 | K37: Agregat Lepas | L37: 0 | M37: 0 | N37: =+L37*M37 -> 0 | O37: Disintegrasi | P37: 0 | Q37: 0 | R37: =+P37*Q37 -> 0 | S37: Retak Lain | T37: 0 | U37: 0 | V37: =+T37*U37 -> 0 | W37: Retak Turun | X37: 0 | Y37: 0 | Z37: =+X37*Y37 -> 0 | AA37: Tambalan | AB37: 0 | AC37: 0 | AD37: =+AB37*AC37 -> 0 | AE37: Lubang | AF37: 0 | AG37: 0 | AH37: =+AF37*AG37 -> 0 | AI37: Alur | AJ37: 0 | AK37: 0 | AL37: =+AJ37*AK37 -> 0 | AM37: Rusak Tepi | AN37: 0 | AO37: 0 | AP37: =+AN37*AO37 -> 0
C45: =+E37 -> 300 | D45: s/d | E45: =+C45+100 -> 400 | G45: Kegemukan | H45: 0 | I45: 0 | J45: =+H45*I45 -> 0 | K45: Agregat Lepas | L45: 4 | M45: 2 | N45: =+L45*M45 -> 8 | O45: Disintegrasi | P45: 0 | Q45: 0 | R45: =+P45*Q45 -> 0 | S45: Retak Lain | T45: 0 | U45: 0 | V45: =+T45*U45 -> 0 | W45: Retak Turun | X45: 7 | Y45: 3 | Z45: =+X45*Y45 -> 21 | AA45: Tambalan | AB45: 7 | AC45: 2.5 | AD45: =+AB45*AC45 -> 17.5 | AE45: Lubang | AF45: 0 | AG45: 0 | AH45: =+AF45*AG45 -> 0 | AI45: Alur | AJ45: 0 | AK45: 0 | AL45: =+AJ45*AK45 -> 0 | AM45: Rusak Tepi | AN45: 0 | AO45: 0 | AP45: =+AN45*AO45 -> 0
C53: =+E45 -> 400 | D53: s/d | E53: =+C53+100 -> 500 | G53: Kegemukan | H53: 0 | I53: 0 | J53: =+H53*I53 -> 0 | K53: Agregat Lepas | L53: 4 | M53: 2 | N53: =+L53*M53 -> 8 | O53: Disintegrasi | P53: 0 | Q53: 0 | R53: =+P53*Q53 -> 0 | S53: Retak Lain | T53: 0 | U53: 0 | V53: =+T53*U53 -> 0 | W53: Retak Turun | X53: 0 | Y53: 0 | Z53: =+X53*Y53 -> 0 | AA53: Tambalan | AB53: 0 | AC53: 0 | AD53: =+AB53*AC53 -> 0 | AE53: Lubang | AF53: 0 | AG53: 0 | AH53: =+AF53*AG53 -> 0 | AI53: Alur | AJ53: 0 | AK53: 0 | AL53: =+AJ53*AK53 -> 0 | AM53: Rusak Tepi | AN53: 0 | AO53: 0 | AP53: =+AN53*AO53 -> 0
C61: =+E53 -> 500 | D61: s/d | E61: =+C61+100 -> 600 | G61: Kegemukan | H61: 0 | I61: 0 | J61: =+H61*I61 -> 0 | K61: Agregat Lepas | L61: 0 | M61: 0 | N61: =+L61*M61 -> 0 | O61: Disintegrasi | P61: 0 | Q61: 0 | R61: =+P61*Q61 -> 0 | S61: Retak Lain | T61: 0 | U61: 0 | V61: =+T61*U61 -> 0 | W61: Retak Turun | X61: 0 | Y61: 0 | Z61: =+X61*Y61 -> 0 | AA61: Tambalan | AB61: 0 | AC61: 0 | AD61: =+AB61*AC61 -> 0 | AE61: Lubang | AF61: 0 | AG61: 0 | AH61: =+AF61*AG61 -> 0 | AI61: Alur | AJ61: 0 | AK61: 0 | AL61: =+AJ61*AK61 -> 0 | AM61: Rusak Tepi | AN61: 0 | AO61: 0 | AP61: =+AN61*AO61 -> 0
C69: =+E61 -> 600 | D69: s/d | E69: =+C69+100 -> 700 | G69: Kegemukan | H69: 0 | I69: 0 | J69: =+H69*I69 -> 0 | K69: Agregat Lepas | L69: 0 | M69: 0 | N69: =+L69*M69 -> 0 | O69: Disintegrasi | P69: 0 | Q69: 0 | R69: =+P69*Q69 -> 0 | S69: Retak Lain | T69: 0 | U69: 0 | V69: =+T69*U69 -> 0 | W69: Retak Turun | X69: 0 | Y69: 0 | Z69: =+X69*Y69 -> 0 | AA69: Tambalan | AB69: 0 | AC69: 0 | AD69: =+AB69*AC69 -> 0 | AE69: Lubang | AF69: 0 | AG69: 0 | AH69: =+AF69*AG69 -> 0 | AI69: Alur | AJ69: 0 | AK69: 0 | AL69: =+AJ69*AK69 -> 0 | AM69: Rusak Tepi | AN69: 0 | AO69: 0 | AP69: =+AN69*AO69 -> 0
C77: =+E69 -> 700 | D77: s/d | E77: =+C77+100 -> 800 | G77: Kegemukan | H77: 0 | I77: 0 | J77: =+H77*I77 -> 0 | K77: Agregat Lepas | L77: 0 | M77: 0 | N77: =+L77*M77 -> 0 | O77: Disintegrasi | P77: 0 | Q77: 0 | R77: =+P77*Q77 -> 0 | S77: Retak Lain | T77: 0 | U77: 0 | V77: =+T77*U77 -> 0 | W77: Retak Turun | X77: 0 | Y77: 0 | Z77: =+X77*Y77 -> 0 | AA77: Tambalan | AB77: 0 | AC77: 0 | AD77: =+AB77*AC77 -> 0 | AE77: Lubang | AF77: 0 | AG77: 0 | AH77: =+AF77*AG77 -> 0 | AI77: Alur | AJ77: 0 | AK77: 0 | AL77: =+AJ77*AK77 -> 0 | AM77: Rusak Tepi | AN77: 0 | AO77: 0 | AP77: =+AN77*AO77 -> 0
C85: =+E77 -> 800 | D85: s/d | E85: =+C85+100 -> 900 | G85: Kegemukan | H85: 0 | I85: 0 | J85: =+H85*I85 -> 0 | K85: Agregat Lepas | L85: 0 | M85: 0 | N85: =+L85*M85 -> 0 | O85: Disintegrasi | P85: 0 | Q85: 0 | R85: =+P85*Q85 -> 0 | S85: Retak Lain | T85: 0 | U85: 0 | V85: =+T85*U85 -> 0 | W85: Retak Turun | X85: 0 | Y85: 0 | Z85: =+X85*Y85 -> 0 | AA85: Tambalan | AB85: 0 | AC85: 0 | AD85: =+AB85*AC85 -> 0 | AE85: Lubang | AF85: 0 | AG85: 0 | AH85: =+AF85*AG85 -> 0 | AI85: Alur | AJ85: 0 | AK85: 0 | AL85: =+AJ85*AK85 -> 0 | AM85: Rusak Tepi | AN85: 0 | AO85: 0 | AP85: =+AN85*AO85 -> 0
C93: =+E85 -> 900 | D93: s/d | E93: =+C93+100 -> 1000 | G93: Kegemukan | H93: 0 | I93: 0 | J93: =+H93*I93 -> 0 | K93: Agregat Lepas | L93: 0 | M93: 0 | N93: =+L93*M93 -> 0 | O93: Disintegrasi | P93: 0 | Q93: 0 | R93: =+P93*Q93 -> 0 | S93: Retak Lain | T93: 0 | U93: 0 | V93: =+T93*U93 -> 0 | W93: Retak Turun | X93: 0 | Y93: 0 | Z93: =+X93*Y93 -> 0 | AA93: Tambalan | AB93: 0 | AC93: 0 | AD93: =+AB93*AC93 -> 0 | AE93: Lubang | AF93: 0 | AG93: 0 | AH93: =+AF93*AG93 -> 0 | AI93: Alur | AJ93: 0 | AK93: 0 | AL93: =+AJ93*AK93 -> 0 | AM93: Rusak Tepi | AN93: 0 | AO93: 0 | AP93: =+AN93*AO93 -> 0
C101: =+E93 -> 1000 | D101: s/d | E101: =+C101+100 -> 1100 | G101: Kegemukan | H101: 0 | I101: 0 | J101: =+H101*I101 -> 0 | K101: Agregat Lepas | L101: 0 | M101: 0 | N101: =+L101*M101 -> 0 | O101: Disintegrasi | P101: 0 | Q101: 0 | R101: =+P101*Q101 -> 0 | S101: Retak Lain | T101: 0 | U101: 0 | V101: =+T101*U101 -> 0 | W101: Retak Turun | X101: 0 | Y101: 0 | Z101: =+X101*Y101 -> 0 | AA101: Tambalan | AB101: 0 | AC101: 0 | AD101: =+AB101*AC101 -> 0 | AE101: Lubang | AF101: 0 | AG101: 0 | AH101: =+AF101*AG101 -> 0 | AI101: Alur | AJ101: 0 | AK101: 0 | AL101: =+AJ101*AK101 -> 0 | AM101: Rusak Tepi | AN101: 0 | AO101: 0 | AP101: =+AN101*AO101 -> 0
C109: =+E101 -> 1100 | D109: s/d | E109: =+C109+100 -> 1200 | G109: Kegemukan | H109: 0 | I109: 0 | J109: =+H109*I109 -> 0 | K109: Agregat Lepas | L109: 0 | M109: 0 | N109: =+L109*M109 -> 0 | O109: Disintegrasi | P109: 0 | Q109: 0 | R109: =+P109*Q109 -> 0 | S109: Retak Lain | T109: 0 | U109: 0 | V109: =+T109*U109 -> 0 | W109: Retak Turun | X109: 0 | Y109: 0 | Z109: =+X109*Y109 -> 0 | AA109: Tambalan | AB109: 0 | AC109: 0 | AD109: =+AB109*AC109 -> 0 | AE109: Lubang | AF109: 0 | AG109: 0 | AH109: =+AF109*AG109 -> 0 | AI109: Alur | AJ109: 0 | AK109: 0 | AL109: =+AJ109*AK109 -> 0 | AM109: Rusak Tepi | AN109: 0 | AO109: 0 | AP109: =+AN109*AO109 -> 0
C117: =+E109 -> 1200 | D117: s/d | E117: =+C117+100 -> 1300 | G117: Kegemukan | H117: 0 | I117: 0 | J117: =+H117*I117 -> 0 | K117: Agregat Lepas | L117: 0 | M117: 0 | N117: =+L117*M117 -> 0 | O117: Disintegrasi | P117: 0 | Q117: 0 | R117: =+P117*Q117 -> 0 | S117: Retak Lain | T117: 0 | U117: 0 | V117: =+T117*U117 -> 0 | W117: Retak Turun | X117: 0 | Y117: 0 | Z117: =+X117*Y117 -> 0 | AA117: Tambalan | AB117: 0 | AC117: 0 | AD117: =+AB117*AC117 -> 0 | AE117: Lubang | AF117: 0 | AG117: 0 | AH117: =+AF117*AG117 -> 0 | AI117: Alur | AJ117: 0 | AK117: 0 | AL117: =+AJ117*AK117 -> 0 | AM117: Rusak Tepi | AN117: 0 | AO117: 0 | AP117: =+AN117*AO117 -> 0
... C813: =+E805 -> 9900 | D813: s/d | E813: =+C813+100 -> 10000 | G813: Kegemukan | H813: 0 | I813: 0 | J813: =+H813*I813 -> 0 | K813: Agregat Lepas | L813: 0 | M813: 0 | N813: =+L813*M813 -> 0 | O813: Disintegrasi | P813: 70 | Q813: 8 | R813: =+P813*Q813 -> 560 | S813: Retak Lain | T813: 0 | U813: 0 | V813: =+T813*U813 -> 0 | W813: Retak Turun | X813: 0 | Y813: 0 | Z813: =+X813*Y813 -> 0 | AA813: Tambalan | AB813: 0 | AC813: 0 | AD813: =+AB813*AC813 -> 0 | AE813: Lubang | AF813: 2 | AG813: 2 | AH813: =+AF813*AG813 -> 4 | AI813: Alur | AJ813: 0 | AK813: 0 | AL813: =+AJ813*AK813 -> 0 | AM813: Rusak Tepi | AN813: 0 | AO813: 0 | AP813: =+AN813*AO813 -> 0
C821: =+E813 -> 10000 | D821: s/d | E821: =+C821+99 -> 10099 | G821: Kegemukan | H821: 0 | I821: 0 | J821: =+H821*I821 -> 0 | K821: Agregat Lepas | L821: 0 | M821: 0 | N821: =+L821*M821 -> 0 | O821: Disintegrasi | P821: 50 | Q821: 8 | R821: =+P821*Q821 -> 400 | S821: Retak Lain | T821: 0 | U821: 0 | V821: =+T821*U821 -> 0 | W821: Retak Turun | X821: 0 | Y821: 0 | Z821: =+X821*Y821 -> 0 | AA821: Tambalan | AB821: 0 | AC821: 0 | AD821: =+AB821*AC821 -> 0 | AE821: Lubang | AF821: 16 | AG821: 3 | AH821: =+AF821*AG821 -> 48 | AI821: Alur | AJ821: 0 | AK821: 0 | AL821: =+AJ821*AK821 -> 0 | AM821: Rusak Tepi | AN821: 0 | AO821: 0 | AP821: =+AN821*AO821 -> 0
B830: LEGENDA : | J830: TABLET
B832: I. PERKERASAN ASPAL
B833: 1. | C833: Ketidakrataan atau IRI (m/km) | J833: Kegemukan | N833: 1
B834: 2. | C834: Kegemukan / Blending (m2) | J834: Agregat Lepas | N834: 2
B835: 3. | C835: Agregat Lepas / Ravelling (m2) | J835: Disintegrasi | N835: 3
B836: 4. | C836: Disintegrasi (m2) | J836: Retak Lain | N836: 4
B837: 5. | C837: Retak turun dan Penurunan (m2) | J837: Retak Turun | N837: 5
B838: 6. | C838: Tambalan / Patching (m2) | J838: Tambalan | N838: 6
B839: 7. | C839: Retak Lain / (Melintang, Bercabang n Buaya) (m2) | J839: Lubang | N839: 7
B840: 8. | C840: Lubang / Potholes (m2) | J840: Alur | N840: 8
B841: 9. | C841: Alur / Jejak Roda / Rutting (m2) | J841: Rusak Tepi | N841: 9
B842: 10. | C842: Rusak Tepi (m2)
B844: II. PERKERASAN BETON
B845: 1. | C845: Retak (m2) | J845: Retak | N845: 1
B846: 2. | C846: Gompal / Pecah (m2) | J846: Gompal | N846: 2
B847: 3. | C847: Retak Struktur (m2) | J847: Retak Struktur | N847: 3
B848: 4. | C848: Patahan/ Penurunan (m2) | J848: Patahan/ Penurunan | N848: 4
...

Sheet 2. Rekap Back Up Beton X
C2: PEMERINTAH PROVINSI LAMPUNG
C3: DINAS BINA MARGA DAN BINA KONSTRUKSI
B6: BACK - UP DATA SURVEY KONDISI JALAN (BETON)
B9: NO. RUAS | E9: : | F9: ='1. Back Up Aspal'!F9 -> 064
B12: NAMA RUAS | E12: : | F12: ='1. Back Up Aspal'!F12 -> BANDAR SAKTI - SP. DAYA MURNI
B15: PANJANG RUAS | E15: : | F15: ='1. Back Up Aspal'!F15 -> 10.099
C18: STA | F18: NILAI TTI | G18: KONDISI | H18: TIPE KERUSAKAN KONDISI JALAN BETON | N18: KET
C19: DARI (M) | D19: KE (M) | E19: LEBAR | H19: BETON RETAK | I19: PECAH/ GOMPAL | J19: STRUKTUR RETAK | K19: PATAHAN/ PENURUNAN | L19: JUMLAH PUMPING | M19: JUMLAH PECAH SUDUT
B20: 1 | N20: 8
C21: 0 | D21: 100 | E21: 3 | F21: =(100/((D21-C21)*E21))*((H21*0.5)+(I21*1)+(J21*2)+(K21*20)+(L21*15)+(M21*1.5)) -> 0 | G21: =IF(F21<=25,"B",IF(F21<=75,"S",IF(F21<=100,"RR","RB"))) -> B | H21: ='2. Back Up Beton X'!J28 -> 0 | I21: ='2. Back Up Beton X'!M28 -> 0 | J21: ='2. Back Up Beton X'!P28 -> 0 | K21: ='2. Back Up Beton X'!S28 -> 0 | L21: ='2. Back Up Beton X'!V28 -> 0 | M21: ='2. Back Up Beton X'!Y28 -> 0
C22: =D21 -> 100 | D22: =C22+100 -> 200 | E22: 3 | F22: =(100/((D22-C22)*E22))*((H22*0.5)+(I22*1)+(J22*2)+(K22*20)+(L22*15)+(M22*1.5)) -> 0 | G22: =IF(F22<=25,"B",IF(F22<=75,"S",IF(F22<=100,"RR","RB"))) -> B | H22: ='2. Back Up Beton X'!J36 -> 0 | I22: ='2. Back Up Beton X'!M36 -> 0 | J22: ='2. Back Up Beton X'!P36 -> 0 | K22: ='2. Back Up Beton X'!S36 -> 0 | L22: ='2. Back Up Beton X'!V36 -> 0 | M22: ='2. Back Up Beton X'!Y36 -> 0
C23: =D22 -> 200 | D23: =C23+100 -> 300 | E23: 3 | F23: =(100/((D23-C23)*E23))*((H23*0.5)+(I23*1)+(J23*2)+(K23*20)+(L23*15)+(M23*1.5)) -> 0 | G23: =IF(F23<=25,"B",IF(F23<=75,"S",IF(F23<=100,"RR","RB"))) -> B | H23: ='2. Back Up Beton X'!J44 -> 0 | I23: ='2. Back Up Beton X'!M44 -> 0 | J23: ='2. Back Up Beton X'!P44 -> 0 | K23: ='2. Back Up Beton X'!S44 -> 0 | L23: ='2. Back Up Beton X'!V44 -> 0 | M23: ='2. Back Up Beton X'!Y44 -> 0
